2024-03-13 21:04:53,931 INFO    StreamThr :11564 [internal.py:wandb_internal():86] W&B internal server running at pid: 11564, started at: 2024-03-13 21:04:53.930696
2024-03-13 21:04:53,932 DEBUG   HandlerThread:11564 [handler.py:handle_request():144] handle_request: status
2024-03-13 21:04:53,937 INFO    WriterThread:11564 [datastore.py:open_for_write():85] open: E:\自动驾驶\车位检测\parking-space-Identification-in-different-weather-main\wandb\run-20240313_210453-3oq1hjiv\run-3oq1hjiv.wandb
2024-03-13 21:04:53,939 DEBUG   SenderThread:11564 [sender.py:send():380] send: header
2024-03-13 21:04:53,939 DEBUG   SenderThread:11564 [sender.py:send():380] send: run
2024-03-13 21:04:54,962 INFO    SenderThread:11564 [dir_watcher.py:__init__():211] watching files in: E:\自动驾驶\车位检测\parking-space-Identification-in-different-weather-main\wandb\run-20240313_210453-3oq1hjiv\files
2024-03-13 21:04:54,962 INFO    SenderThread:11564 [sender.py:_start_run_threads():1122] run started: 3oq1hjiv with start time 1710335093.931697
2024-03-13 21:04:54,981 DEBUG   HandlerThread:11564 [handler.py:handle_request():144] handle_request: check_version
2024-03-13 21:04:54,981 DEBUG   SenderThread:11564 [sender.py:send_request():407] send_request: check_version
2024-03-13 21:04:59,110 DEBUG   HandlerThread:11564 [handler.py:handle_request():144] handle_request: status_report
2024-03-13 21:04:59,125 DEBUG   HandlerThread:11564 [handler.py:handle_request():144] handle_request: run_start
2024-03-13 21:04:59,166 DEBUG   HandlerThread:11564 [system_info.py:__init__():32] System info init
2024-03-13 21:04:59,167 DEBUG   HandlerThread:11564 [system_info.py:__init__():47] System info init done
2024-03-13 21:04:59,167 INFO    HandlerThread:11564 [system_monitor.py:start():181] Starting system monitor
2024-03-13 21:04:59,167 INFO    SystemMonitor:11564 [system_monitor.py:_start():145] Starting system asset monitoring threads
2024-03-13 21:04:59,167 INFO    HandlerThread:11564 [system_monitor.py:probe():201] Collecting system info
2024-03-13 21:04:59,172 INFO    SystemMonitor:11564 [interfaces.py:start():190] Started cpu monitoring
2024-03-13 21:04:59,173 INFO    SystemMonitor:11564 [interfaces.py:start():190] Started disk monitoring
2024-03-13 21:04:59,174 INFO    SystemMonitor:11564 [interfaces.py:start():190] Started gpu monitoring
2024-03-13 21:04:59,174 INFO    SystemMonitor:11564 [interfaces.py:start():190] Started memory monitoring
2024-03-13 21:04:59,202 INFO    SystemMonitor:11564 [interfaces.py:start():190] Started network monitoring
2024-03-13 21:04:59,211 DEBUG   HandlerThread:11564 [system_info.py:probe():196] Probing system
2024-03-13 21:04:59,212 DEBUG   HandlerThread:11564 [system_info.py:probe():244] Probing system done
2024-03-13 21:04:59,212 DEBUG   HandlerThread:11564 [system_monitor.py:probe():210] {'os': 'Windows-10-10.0.22000-SP0', 'python': '3.10.9', 'heartbeatAt': '2024-03-13T13:04:59.212091', 'startedAt': '2024-03-13T13:04:53.916702', 'docker': None, 'cuda': None, 'args': ('--task=P', '--weather=rainy'), 'state': 'running', 'program': 'E:\\自动驾驶\\车位检测\\parking-space-Identification-in-different-weather-main\\train.py', 'codePathLocal': 'train.py', 'codePath': 'train.py', 'host': 'LAPTOP-QIVT4NMT', 'username': 'lenovo', 'executable': 'E:\\anaconda\\python.exe', 'cpu_count': 8, 'cpu_count_logical': 16, 'cpu_freq': {'current': 3201.0, 'min': 0.0, 'max': 3201.0}, 'cpu_freq_per_core': [{'current': 3201.0, 'min': 0.0, 'max': 3201.0}], 'disk': {'/': {'total': 465.74511337280273, 'used': 179.69673919677734}}, 'gpu': 'NVIDIA GeForce RTX 3060 Laptop GPU', 'gpu_count': 1, 'gpu_devices': [{'name': 'NVIDIA GeForce RTX 3060 Laptop GPU', 'memory_total': 6442450944}], 'memory': {'total': 15.855525970458984}}
2024-03-13 21:04:59,212 INFO    HandlerThread:11564 [system_monitor.py:probe():211] Finished collecting system info
2024-03-13 21:04:59,212 INFO    HandlerThread:11564 [system_monitor.py:probe():214] Publishing system info
2024-03-13 21:04:59,212 DEBUG   HandlerThread:11564 [system_info.py:_save_pip():52] Saving list of pip packages installed into the current environment
2024-03-13 21:04:59,213 DEBUG   HandlerThread:11564 [system_info.py:_save_pip():68] Saving pip packages done
2024-03-13 21:04:59,213 DEBUG   HandlerThread:11564 [system_info.py:_save_conda():75] Saving list of conda packages installed into the current environment
2024-03-13 21:04:59,222 ERROR   gpu       :11564 [interfaces.py:monitor():144] Failed to sample metric: Not Supported
2024-03-13 21:05:00,001 INFO    Thread-12 :11564 [dir_watcher.py:_on_file_created():271] file/dir created: E:\自动驾驶\车位检测\parking-space-Identification-in-different-weather-main\wandb\run-20240313_210453-3oq1hjiv\files\conda-environment.yaml
2024-03-13 21:05:00,002 INFO    Thread-12 :11564 [dir_watcher.py:_on_file_created():271] file/dir created: E:\自动驾驶\车位检测\parking-space-Identification-in-different-weather-main\wandb\run-20240313_210453-3oq1hjiv\files\requirements.txt
2024-03-13 21:05:01,262 ERROR   gpu       :11564 [interfaces.py:monitor():144] Failed to sample metric: Not Supported
2024-03-13 21:05:03,306 ERROR   gpu       :11564 [interfaces.py:monitor():144] Failed to sample metric: Not Supported
2024-03-13 21:05:05,343 ERROR   gpu       :11564 [interfaces.py:monitor():144] Failed to sample metric: Not Supported
2024-03-13 21:05:06,029 INFO    Thread-12 :11564 [dir_watcher.py:_on_file_modified():288] file/dir modified: E:\自动驾驶\车位检测\parking-space-Identification-in-different-weather-main\wandb\run-20240313_210453-3oq1hjiv\files\conda-environment.yaml
2024-03-13 21:05:06,166 DEBUG   HandlerThread:11564 [system_info.py:_save_conda():87] Saving conda packages done
2024-03-13 21:05:06,167 INFO    HandlerThread:11564 [system_monitor.py:probe():216] Finished publishing system info
2024-03-13 21:05:06,186 DEBUG   HandlerThread:11564 [handler.py:handle_request():144] handle_request: status_report
2024-03-13 21:05:06,187 DEBUG   HandlerThread:11564 [handler.py:handle_request():144] handle_request: keepalive
2024-03-13 21:05:06,187 DEBUG   SenderThread:11564 [sender.py:send():380] send: files
2024-03-13 21:05:06,187 INFO    SenderThread:11564 [sender.py:_save_file():1378] saving file wandb-metadata.json with policy now
2024-03-13 21:05:06,198 DEBUG   HandlerThread:11564 [handler.py:handle_request():144] handle_request: stop_status
2024-03-13 21:05:06,199 DEBUG   SenderThread:11564 [sender.py:send_request():407] send_request: stop_status
2024-03-13 21:05:06,200 DEBUG   HandlerThread:11564 [handler.py:handle_request():144] handle_request: internal_messages
2024-03-13 21:05:07,044 INFO    Thread-12 :11564 [dir_watcher.py:_on_file_modified():288] file/dir modified: E:\自动驾驶\车位检测\parking-space-Identification-in-different-weather-main\wandb\run-20240313_210453-3oq1hjiv\files\conda-environment.yaml
2024-03-13 21:05:07,045 INFO    Thread-12 :11564 [dir_watcher.py:_on_file_created():271] file/dir created: E:\自动驾驶\车位检测\parking-space-Identification-in-different-weather-main\wandb\run-20240313_210453-3oq1hjiv\files\wandb-metadata.json
2024-03-13 21:05:07,375 ERROR   gpu       :11564 [interfaces.py:monitor():144] Failed to sample metric: Not Supported
2024-03-13 21:05:08,168 DEBUG   SenderThread:11564 [sender.py:send():380] send: telemetry
2024-03-13 21:05:09,064 INFO    Thread-12 :11564 [dir_watcher.py:_on_file_created():271] file/dir created: E:\自动驾驶\车位检测\parking-space-Identification-in-different-weather-main\wandb\run-20240313_210453-3oq1hjiv\files\output.log
2024-03-13 21:05:09,172 DEBUG   HandlerThread:11564 [handler.py:handle_request():144] handle_request: status_report
2024-03-13 21:05:09,409 ERROR   gpu       :11564 [interfaces.py:monitor():144] Failed to sample metric: Not Supported
2024-03-13 21:05:11,083 INFO    Thread-12 :11564 [dir_watcher.py:_on_file_modified():288] file/dir modified: E:\自动驾驶\车位检测\parking-space-Identification-in-different-weather-main\wandb\run-20240313_210453-3oq1hjiv\files\output.log
2024-03-13 21:05:11,446 ERROR   gpu       :11564 [interfaces.py:monitor():144] Failed to sample metric: Not Supported
2024-03-13 21:05:11,958 DEBUG   HandlerThread:11564 [handler.py:handle_request():144] handle_request: partial_history
2024-03-13 21:05:11,959 DEBUG   SenderThread:11564 [sender.py:send():380] send: history
2024-03-13 21:05:11,959 DEBUG   SenderThread:11564 [sender.py:send_request():407] send_request: summary_record
2024-03-13 21:05:11,960 INFO    SenderThread:11564 [sender.py:_save_file():1378] saving file wandb-summary.json with policy end
2024-03-13 21:05:12,087 INFO    Thread-12 :11564 [dir_watcher.py:_on_file_created():271] file/dir created: E:\自动驾驶\车位检测\parking-space-Identification-in-different-weather-main\wandb\run-20240313_210453-3oq1hjiv\files\wandb-summary.json
2024-03-13 21:05:13,483 ERROR   gpu       :11564 [interfaces.py:monitor():144] Failed to sample metric: Not Supported
2024-03-13 21:05:13,909 DEBUG   HandlerThread:11564 [handler.py:handle_request():144] handle_request: partial_history
2024-03-13 21:05:13,910 DEBUG   HandlerThread:11564 [handler.py:handle_request():144] handle_request: partial_history
2024-03-13 21:05:13,911 DEBUG   SenderThread:11564 [sender.py:send():380] send: history
2024-03-13 21:05:13,911 DEBUG   SenderThread:11564 [sender.py:send_request():407] send_request: summary_record
2024-03-13 21:05:13,912 INFO    SenderThread:11564 [sender.py:_save_file():1378] saving file wandb-summary.json with policy end
2024-03-13 21:05:13,913 DEBUG   SenderThread:11564 [sender.py:send():380] send: history
2024-03-13 21:05:13,913 DEBUG   SenderThread:11564 [sender.py:send_request():407] send_request: summary_record
2024-03-13 21:05:13,914 INFO    SenderThread:11564 [sender.py:_save_file():1378] saving file wandb-summary.json with policy end
2024-03-13 21:05:14,103 INFO    Thread-12 :11564 [dir_watcher.py:_on_file_modified():288] file/dir modified: E:\自动驾驶\车位检测\parking-space-Identification-in-different-weather-main\wandb\run-20240313_210453-3oq1hjiv\files\wandb-summary.json
2024-03-13 21:05:14,918 DEBUG   HandlerThread:11564 [handler.py:handle_request():144] handle_request: status_report
2024-03-13 21:05:15,109 INFO    Thread-12 :11564 [dir_watcher.py:_on_file_modified():288] file/dir modified: E:\自动驾驶\车位检测\parking-space-Identification-in-different-weather-main\wandb\run-20240313_210453-3oq1hjiv\files\output.log
2024-03-13 21:05:15,528 ERROR   gpu       :11564 [interfaces.py:monitor():144] Failed to sample metric: Not Supported
2024-03-13 21:05:16,753 DEBUG   HandlerThread:11564 [handler.py:handle_request():144] handle_request: partial_history
2024-03-13 21:05:16,754 DEBUG   SenderThread:11564 [sender.py:send():380] send: history
2024-03-13 21:05:16,754 DEBUG   SenderThread:11564 [sender.py:send_request():407] send_request: summary_record
2024-03-13 21:05:16,755 INFO    SenderThread:11564 [sender.py:_save_file():1378] saving file wandb-summary.json with policy end
2024-03-13 21:05:17,122 INFO    Thread-12 :11564 [dir_watcher.py:_on_file_modified():288] file/dir modified: E:\自动驾驶\车位检测\parking-space-Identification-in-different-weather-main\wandb\run-20240313_210453-3oq1hjiv\files\wandb-summary.json
2024-03-13 21:05:17,123 INFO    Thread-12 :11564 [dir_watcher.py:_on_file_modified():288] file/dir modified: E:\自动驾驶\车位检测\parking-space-Identification-in-different-weather-main\wandb\run-20240313_210453-3oq1hjiv\files\output.log
2024-03-13 21:05:17,554 ERROR   gpu       :11564 [interfaces.py:monitor():144] Failed to sample metric: Not Supported
2024-03-13 21:05:18,773 DEBUG   HandlerThread:11564 [handler.py:handle_request():144] handle_request: partial_history
2024-03-13 21:05:18,774 DEBUG   HandlerThread:11564 [handler.py:handle_request():144] handle_request: partial_history
2024-03-13 21:05:18,774 DEBUG   SenderThread:11564 [sender.py:send():380] send: history
2024-03-13 21:05:18,775 DEBUG   SenderThread:11564 [sender.py:send_request():407] send_request: summary_record
2024-03-13 21:05:18,776 INFO    SenderThread:11564 [sender.py:_save_file():1378] saving file wandb-summary.json with policy end
2024-03-13 21:05:18,776 DEBUG   SenderThread:11564 [sender.py:send():380] send: history
2024-03-13 21:05:18,776 DEBUG   SenderThread:11564 [sender.py:send_request():407] send_request: summary_record
2024-03-13 21:05:18,777 INFO    SenderThread:11564 [sender.py:_save_file():1378] saving file wandb-summary.json with policy end
2024-03-13 21:05:19,141 INFO    Thread-12 :11564 [dir_watcher.py:_on_file_modified():288] file/dir modified: E:\自动驾驶\车位检测\parking-space-Identification-in-different-weather-main\wandb\run-20240313_210453-3oq1hjiv\files\wandb-summary.json
2024-03-13 21:05:19,142 INFO    Thread-12 :11564 [dir_watcher.py:_on_file_modified():288] file/dir modified: E:\自动驾驶\车位检测\parking-space-Identification-in-different-weather-main\wandb\run-20240313_210453-3oq1hjiv\files\output.log
2024-03-13 21:05:19,571 ERROR   wandb-upload_0:11564 [internal_api.py:upload_file():2556] upload_file exception https://storage.googleapis.com/wandb-production.appspot.com/princeporch/uncategorized/3oq1hjiv/wandb-metadata.json?Expires=1710421510&GoogleAccessId=gorilla-files-url-signer-man%40wandb-production.iam.gserviceaccount.com&Signature=eOp1F3K0OOM3nLDkP8XGnJ3vXn9pxmhpqBLHGF70JePq4N7T%2B4hDEXHcmhltlUQ4NQc9xeuf4L9NTUU%2BemKL1XjMPGZBND6%2FSrv8%2FeIjMQZGrjidNIcRFBDVeo8CmuxZxdJ8Gptyw1wtIbncOOpIPzc8V5H7JupruC5U8TClVinntCLXpAqXzilii5v6LTDWYxZOX6GKmUhaJ871cyuuHvd2XejOlPzybq50U7LJHzWK4pdv0BWmuuhQEqsLpnTIkJ8IIeqMvtDgkxzpt5Y%2Fctx%2BBpalC7l25wD67YQWlfLN78ndHS0nNNKhuSR2F6PrWYtKn5tRxqmu3wALLCLFJg%3D%3D: HTTPSConnectionPool(host='storage.googleapis.com', port=443): Max retries exceeded with url: /wandb-production.appspot.com/princeporch/uncategorized/3oq1hjiv/wandb-metadata.json?Expires=1710421510&GoogleAccessId=gorilla-files-url-signer-man%40wandb-production.iam.gserviceaccount.com&Signature=eOp1F3K0OOM3nLDkP8XGnJ3vXn9pxmhpqBLHGF70JePq4N7T%2B4hDEXHcmhltlUQ4NQc9xeuf4L9NTUU%2BemKL1XjMPGZBND6%2FSrv8%2FeIjMQZGrjidNIcRFBDVeo8CmuxZxdJ8Gptyw1wtIbncOOpIPzc8V5H7JupruC5U8TClVinntCLXpAqXzilii5v6LTDWYxZOX6GKmUhaJ871cyuuHvd2XejOlPzybq50U7LJHzWK4pdv0BWmuuhQEqsLpnTIkJ8IIeqMvtDgkxzpt5Y%2Fctx%2BBpalC7l25wD67YQWlfLN78ndHS0nNNKhuSR2F6PrWYtKn5tRxqmu3wALLCLFJg%3D%3D (Caused by NewConnectionError('<urllib3.connection.HTTPSConnection object at 0x000001E23381F460>: Failed to establish a new connection: [WinError 10061] 由于目标计算机积极拒绝，无法连接。'))
2024-03-13 21:05:19,571 ERROR   wandb-upload_0:11564 [internal_api.py:upload_file():2558] upload_file request headers: {'User-Agent': 'python-requests/2.29.0', 'Accept-Encoding': 'gzip, deflate, br', 'Accept': '*/*', 'Connection': 'keep-alive', 'Content-Length': '1321'}
2024-03-13 21:05:19,571 ERROR   wandb-upload_0:11564 [internal_api.py:upload_file():2560] upload_file response body: 
2024-03-13 21:05:19,586 ERROR   gpu       :11564 [interfaces.py:monitor():144] Failed to sample metric: Not Supported
2024-03-13 21:05:20,798 DEBUG   HandlerThread:11564 [handler.py:handle_request():144] handle_request: status_report
2024-03-13 21:05:21,146 INFO    Thread-12 :11564 [dir_watcher.py:_on_file_modified():288] file/dir modified: E:\自动驾驶\车位检测\parking-space-Identification-in-different-weather-main\wandb\run-20240313_210453-3oq1hjiv\files\output.log
2024-03-13 21:05:21,206 DEBUG   HandlerThread:11564 [handler.py:handle_request():144] handle_request: internal_messages
2024-03-13 21:05:21,206 DEBUG   HandlerThread:11564 [handler.py:handle_request():144] handle_request: stop_status
2024-03-13 21:05:21,206 DEBUG   SenderThread:11564 [sender.py:send_request():407] send_request: stop_status
2024-03-13 21:05:21,514 DEBUG   HandlerThread:11564 [handler.py:handle_request():144] handle_request: partial_history
2024-03-13 21:05:21,599 DEBUG   SenderThread:11564 [sender.py:send():380] send: history
2024-03-13 21:05:21,599 DEBUG   SenderThread:11564 [sender.py:send_request():407] send_request: summary_record
2024-03-13 21:05:21,600 INFO    SenderThread:11564 [sender.py:_save_file():1378] saving file wandb-summary.json with policy end
2024-03-13 21:05:21,623 ERROR   gpu       :11564 [interfaces.py:monitor():144] Failed to sample metric: Not Supported
2024-03-13 21:05:22,159 INFO    Thread-12 :11564 [dir_watcher.py:_on_file_modified():288] file/dir modified: E:\自动驾驶\车位检测\parking-space-Identification-in-different-weather-main\wandb\run-20240313_210453-3oq1hjiv\files\wandb-summary.json
2024-03-13 21:05:23,172 INFO    Thread-12 :11564 [dir_watcher.py:_on_file_modified():288] file/dir modified: E:\自动驾驶\车位检测\parking-space-Identification-in-different-weather-main\wandb\run-20240313_210453-3oq1hjiv\files\output.log
2024-03-13 21:05:23,484 DEBUG   HandlerThread:11564 [handler.py:handle_request():144] handle_request: partial_history
2024-03-13 21:05:23,485 DEBUG   HandlerThread:11564 [handler.py:handle_request():144] handle_request: partial_history
2024-03-13 21:05:23,486 DEBUG   SenderThread:11564 [sender.py:send():380] send: history
2024-03-13 21:05:23,486 DEBUG   SenderThread:11564 [sender.py:send_request():407] send_request: summary_record
2024-03-13 21:05:23,487 INFO    SenderThread:11564 [sender.py:_save_file():1378] saving file wandb-summary.json with policy end
2024-03-13 21:05:23,487 DEBUG   SenderThread:11564 [sender.py:send():380] send: history
2024-03-13 21:05:23,487 DEBUG   SenderThread:11564 [sender.py:send_request():407] send_request: summary_record
2024-03-13 21:05:23,488 INFO    SenderThread:11564 [sender.py:_save_file():1378] saving file wandb-summary.json with policy end
2024-03-13 21:05:23,663 ERROR   gpu       :11564 [interfaces.py:monitor():144] Failed to sample metric: Not Supported
2024-03-13 21:05:24,174 INFO    Thread-12 :11564 [dir_watcher.py:_on_file_modified():288] file/dir modified: E:\自动驾驶\车位检测\parking-space-Identification-in-different-weather-main\wandb\run-20240313_210453-3oq1hjiv\files\wandb-summary.json
2024-03-13 21:05:25,190 INFO    Thread-12 :11564 [dir_watcher.py:_on_file_modified():288] file/dir modified: E:\自动驾驶\车位检测\parking-space-Identification-in-different-weather-main\wandb\run-20240313_210453-3oq1hjiv\files\output.log
2024-03-13 21:05:25,685 ERROR   gpu       :11564 [interfaces.py:monitor():144] Failed to sample metric: Not Supported
2024-03-13 21:05:26,188 DEBUG   HandlerThread:11564 [handler.py:handle_request():144] handle_request: status_report
2024-03-13 21:05:26,188 DEBUG   HandlerThread:11564 [handler.py:handle_request():144] handle_request: partial_history
2024-03-13 21:05:27,589 DEBUG   SenderThread:11564 [sender.py:send():380] send: history
2024-03-13 21:05:27,589 DEBUG   SenderThread:11564 [sender.py:send_request():407] send_request: summary_record
2024-03-13 21:05:27,590 INFO    SenderThread:11564 [sender.py:_save_file():1378] saving file wandb-summary.json with policy end
2024-03-13 21:05:27,722 ERROR   gpu       :11564 [interfaces.py:monitor():144] Failed to sample metric: Not Supported
2024-03-13 21:05:28,104 DEBUG   HandlerThread:11564 [handler.py:handle_request():144] handle_request: partial_history
2024-03-13 21:05:28,105 DEBUG   HandlerThread:11564 [handler.py:handle_request():144] handle_request: partial_history
2024-03-13 21:05:28,106 DEBUG   SenderThread:11564 [sender.py:send():380] send: history
2024-03-13 21:05:28,106 DEBUG   SenderThread:11564 [sender.py:send_request():407] send_request: summary_record
2024-03-13 21:05:28,107 INFO    SenderThread:11564 [sender.py:_save_file():1378] saving file wandb-summary.json with policy end
2024-03-13 21:05:28,107 DEBUG   SenderThread:11564 [sender.py:send():380] send: history
2024-03-13 21:05:28,107 DEBUG   SenderThread:11564 [sender.py:send_request():407] send_request: summary_record
2024-03-13 21:05:28,108 INFO    SenderThread:11564 [sender.py:_save_file():1378] saving file wandb-summary.json with policy end
2024-03-13 21:05:28,205 INFO    Thread-12 :11564 [dir_watcher.py:_on_file_modified():288] file/dir modified: E:\自动驾驶\车位检测\parking-space-Identification-in-different-weather-main\wandb\run-20240313_210453-3oq1hjiv\files\config.yaml
2024-03-13 21:05:28,206 INFO    Thread-12 :11564 [dir_watcher.py:_on_file_modified():288] file/dir modified: E:\自动驾驶\车位检测\parking-space-Identification-in-different-weather-main\wandb\run-20240313_210453-3oq1hjiv\files\wandb-summary.json
2024-03-13 21:05:29,208 INFO    Thread-12 :11564 [dir_watcher.py:_on_file_modified():288] file/dir modified: E:\自动驾驶\车位检测\parking-space-Identification-in-different-weather-main\wandb\run-20240313_210453-3oq1hjiv\files\output.log
2024-03-13 21:05:29,819 ERROR   gpu       :11564 [interfaces.py:monitor():144] Failed to sample metric: Not Supported
2024-03-13 21:05:30,829 DEBUG   HandlerThread:11564 [handler.py:handle_request():144] handle_request: partial_history
2024-03-13 21:05:30,830 DEBUG   SenderThread:11564 [sender.py:send():380] send: history
2024-03-13 21:05:30,830 DEBUG   SenderThread:11564 [sender.py:send_request():407] send_request: summary_record
2024-03-13 21:05:30,831 INFO    SenderThread:11564 [sender.py:_save_file():1378] saving file wandb-summary.json with policy end
2024-03-13 21:05:31,217 INFO    Thread-12 :11564 [dir_watcher.py:_on_file_modified():288] file/dir modified: E:\自动驾驶\车位检测\parking-space-Identification-in-different-weather-main\wandb\run-20240313_210453-3oq1hjiv\files\wandb-summary.json
2024-03-13 21:05:31,218 INFO    Thread-12 :11564 [dir_watcher.py:_on_file_modified():288] file/dir modified: E:\自动驾驶\车位检测\parking-space-Identification-in-different-weather-main\wandb\run-20240313_210453-3oq1hjiv\files\output.log
2024-03-13 21:05:31,842 ERROR   gpu       :11564 [interfaces.py:monitor():144] Failed to sample metric: Not Supported
2024-03-13 21:05:32,818 DEBUG   HandlerThread:11564 [handler.py:handle_request():144] handle_request: status_report
2024-03-13 21:05:32,818 DEBUG   HandlerThread:11564 [handler.py:handle_request():144] handle_request: partial_history
2024-03-13 21:05:32,819 DEBUG   HandlerThread:11564 [handler.py:handle_request():144] handle_request: partial_history
2024-03-13 21:05:32,819 DEBUG   SenderThread:11564 [sender.py:send():380] send: history
2024-03-13 21:05:32,820 DEBUG   SenderThread:11564 [sender.py:send_request():407] send_request: summary_record
2024-03-13 21:05:32,821 INFO    SenderThread:11564 [sender.py:_save_file():1378] saving file wandb-summary.json with policy end
2024-03-13 21:05:32,821 DEBUG   SenderThread:11564 [sender.py:send():380] send: history
2024-03-13 21:05:32,821 DEBUG   SenderThread:11564 [sender.py:send_request():407] send_request: summary_record
2024-03-13 21:05:32,822 INFO    SenderThread:11564 [sender.py:_save_file():1378] saving file wandb-summary.json with policy end
2024-03-13 21:05:33,229 INFO    Thread-12 :11564 [dir_watcher.py:_on_file_modified():288] file/dir modified: E:\自动驾驶\车位检测\parking-space-Identification-in-different-weather-main\wandb\run-20240313_210453-3oq1hjiv\files\wandb-summary.json
2024-03-13 21:05:33,230 INFO    Thread-12 :11564 [dir_watcher.py:_on_file_modified():288] file/dir modified: E:\自动驾驶\车位检测\parking-space-Identification-in-different-weather-main\wandb\run-20240313_210453-3oq1hjiv\files\output.log
2024-03-13 21:05:33,256 ERROR   wandb-upload_0:11564 [internal_api.py:upload_file():2556] upload_file exception https://storage.googleapis.com/wandb-production.appspot.com/princeporch/uncategorized/3oq1hjiv/wandb-metadata.json?Expires=1710421510&GoogleAccessId=gorilla-files-url-signer-man%40wandb-production.iam.gserviceaccount.com&Signature=eOp1F3K0OOM3nLDkP8XGnJ3vXn9pxmhpqBLHGF70JePq4N7T%2B4hDEXHcmhltlUQ4NQc9xeuf4L9NTUU%2BemKL1XjMPGZBND6%2FSrv8%2FeIjMQZGrjidNIcRFBDVeo8CmuxZxdJ8Gptyw1wtIbncOOpIPzc8V5H7JupruC5U8TClVinntCLXpAqXzilii5v6LTDWYxZOX6GKmUhaJ871cyuuHvd2XejOlPzybq50U7LJHzWK4pdv0BWmuuhQEqsLpnTIkJ8IIeqMvtDgkxzpt5Y%2Fctx%2BBpalC7l25wD67YQWlfLN78ndHS0nNNKhuSR2F6PrWYtKn5tRxqmu3wALLCLFJg%3D%3D: HTTPSConnectionPool(host='storage.googleapis.com', port=443): Max retries exceeded with url: /wandb-production.appspot.com/princeporch/uncategorized/3oq1hjiv/wandb-metadata.json?Expires=1710421510&GoogleAccessId=gorilla-files-url-signer-man%40wandb-production.iam.gserviceaccount.com&Signature=eOp1F3K0OOM3nLDkP8XGnJ3vXn9pxmhpqBLHGF70JePq4N7T%2B4hDEXHcmhltlUQ4NQc9xeuf4L9NTUU%2BemKL1XjMPGZBND6%2FSrv8%2FeIjMQZGrjidNIcRFBDVeo8CmuxZxdJ8Gptyw1wtIbncOOpIPzc8V5H7JupruC5U8TClVinntCLXpAqXzilii5v6LTDWYxZOX6GKmUhaJ871cyuuHvd2XejOlPzybq50U7LJHzWK4pdv0BWmuuhQEqsLpnTIkJ8IIeqMvtDgkxzpt5Y%2Fctx%2BBpalC7l25wD67YQWlfLN78ndHS0nNNKhuSR2F6PrWYtKn5tRxqmu3wALLCLFJg%3D%3D (Caused by NewConnectionError('<urllib3.connection.HTTPSConnection object at 0x000001E233A76A70>: Failed to establish a new connection: [WinError 10061] 由于目标计算机积极拒绝，无法连接。'))
2024-03-13 21:05:33,257 ERROR   wandb-upload_0:11564 [internal_api.py:upload_file():2558] upload_file request headers: {'User-Agent': 'python-requests/2.29.0', 'Accept-Encoding': 'gzip, deflate, br', 'Accept': '*/*', 'Connection': 'keep-alive', 'Content-Length': '1321'}
2024-03-13 21:05:33,257 ERROR   wandb-upload_0:11564 [internal_api.py:upload_file():2560] upload_file response body: 
2024-03-13 21:05:33,866 ERROR   gpu       :11564 [interfaces.py:monitor():144] Failed to sample metric: Not Supported
2024-03-13 21:05:35,243 INFO    Thread-12 :11564 [dir_watcher.py:_on_file_modified():288] file/dir modified: E:\自动驾驶\车位检测\parking-space-Identification-in-different-weather-main\wandb\run-20240313_210453-3oq1hjiv\files\output.log
2024-03-13 21:05:35,542 DEBUG   HandlerThread:11564 [handler.py:handle_request():144] handle_request: partial_history
2024-03-13 21:05:35,543 DEBUG   SenderThread:11564 [sender.py:send():380] send: history
2024-03-13 21:05:35,543 DEBUG   SenderThread:11564 [sender.py:send_request():407] send_request: summary_record
2024-03-13 21:05:35,544 INFO    SenderThread:11564 [sender.py:_save_file():1378] saving file wandb-summary.json with policy end
2024-03-13 21:05:35,899 ERROR   gpu       :11564 [interfaces.py:monitor():144] Failed to sample metric: Not Supported
2024-03-13 21:05:36,213 DEBUG   HandlerThread:11564 [handler.py:handle_request():144] handle_request: internal_messages
2024-03-13 21:05:36,214 DEBUG   HandlerThread:11564 [handler.py:handle_request():144] handle_request: stop_status
2024-03-13 21:05:36,214 DEBUG   SenderThread:11564 [sender.py:send_request():407] send_request: stop_status
2024-03-13 21:05:36,245 INFO    Thread-12 :11564 [dir_watcher.py:_on_file_modified():288] file/dir modified: E:\自动驾驶\车位检测\parking-space-Identification-in-different-weather-main\wandb\run-20240313_210453-3oq1hjiv\files\wandb-summary.json
2024-03-13 21:05:37,257 INFO    Thread-12 :11564 [dir_watcher.py:_on_file_modified():288] file/dir modified: E:\自动驾驶\车位检测\parking-space-Identification-in-different-weather-main\wandb\run-20240313_210453-3oq1hjiv\files\output.log
2024-03-13 21:05:37,532 DEBUG   HandlerThread:11564 [handler.py:handle_request():144] handle_request: partial_history
2024-03-13 21:05:37,533 DEBUG   HandlerThread:11564 [handler.py:handle_request():144] handle_request: partial_history
2024-03-13 21:05:37,533 DEBUG   SenderThread:11564 [sender.py:send():380] send: history
2024-03-13 21:05:37,534 DEBUG   SenderThread:11564 [sender.py:send_request():407] send_request: summary_record
2024-03-13 21:05:37,535 INFO    SenderThread:11564 [sender.py:_save_file():1378] saving file wandb-summary.json with policy end
2024-03-13 21:05:37,535 DEBUG   SenderThread:11564 [sender.py:send():380] send: history
2024-03-13 21:05:37,535 DEBUG   SenderThread:11564 [sender.py:send_request():407] send_request: summary_record
2024-03-13 21:05:37,536 INFO    SenderThread:11564 [sender.py:_save_file():1378] saving file wandb-summary.json with policy end
2024-03-13 21:05:37,926 ERROR   gpu       :11564 [interfaces.py:monitor():144] Failed to sample metric: Not Supported
2024-03-13 21:05:38,261 INFO    Thread-12 :11564 [dir_watcher.py:_on_file_modified():288] file/dir modified: E:\自动驾驶\车位检测\parking-space-Identification-in-different-weather-main\wandb\run-20240313_210453-3oq1hjiv\files\wandb-summary.json
2024-03-13 21:05:38,548 DEBUG   HandlerThread:11564 [handler.py:handle_request():144] handle_request: status_report
2024-03-13 21:05:39,264 INFO    Thread-12 :11564 [dir_watcher.py:_on_file_modified():288] file/dir modified: E:\自动驾驶\车位检测\parking-space-Identification-in-different-weather-main\wandb\run-20240313_210453-3oq1hjiv\files\output.log
2024-03-13 21:05:39,959 ERROR   gpu       :11564 [interfaces.py:monitor():144] Failed to sample metric: Not Supported
2024-03-13 21:05:40,224 DEBUG   HandlerThread:11564 [handler.py:handle_request():144] handle_request: partial_history
2024-03-13 21:05:40,225 DEBUG   SenderThread:11564 [sender.py:send():380] send: history
2024-03-13 21:05:40,225 DEBUG   SenderThread:11564 [sender.py:send_request():407] send_request: summary_record
2024-03-13 21:05:40,226 INFO    SenderThread:11564 [sender.py:_save_file():1378] saving file wandb-summary.json with policy end
2024-03-13 21:05:40,266 INFO    Thread-12 :11564 [dir_watcher.py:_on_file_modified():288] file/dir modified: E:\自动驾驶\车位检测\parking-space-Identification-in-different-weather-main\wandb\run-20240313_210453-3oq1hjiv\files\wandb-summary.json
2024-03-13 21:05:41,271 INFO    Thread-12 :11564 [dir_watcher.py:_on_file_modified():288] file/dir modified: E:\自动驾驶\车位检测\parking-space-Identification-in-different-weather-main\wandb\run-20240313_210453-3oq1hjiv\files\output.log
2024-03-13 21:05:42,002 ERROR   gpu       :11564 [interfaces.py:monitor():144] Failed to sample metric: Not Supported
2024-03-13 21:05:42,167 DEBUG   HandlerThread:11564 [handler.py:handle_request():144] handle_request: partial_history
2024-03-13 21:05:42,167 DEBUG   HandlerThread:11564 [handler.py:handle_request():144] handle_request: partial_history
2024-03-13 21:05:42,168 DEBUG   SenderThread:11564 [sender.py:send():380] send: history
2024-03-13 21:05:42,169 DEBUG   SenderThread:11564 [sender.py:send_request():407] send_request: summary_record
2024-03-13 21:05:42,169 INFO    SenderThread:11564 [sender.py:_save_file():1378] saving file wandb-summary.json with policy end
2024-03-13 21:05:42,170 DEBUG   SenderThread:11564 [sender.py:send():380] send: history
2024-03-13 21:05:42,170 DEBUG   SenderThread:11564 [sender.py:send_request():407] send_request: summary_record
2024-03-13 21:05:42,171 INFO    SenderThread:11564 [sender.py:_save_file():1378] saving file wandb-summary.json with policy end
2024-03-13 21:05:42,273 INFO    Thread-12 :11564 [dir_watcher.py:_on_file_modified():288] file/dir modified: E:\自动驾驶\车位检测\parking-space-Identification-in-different-weather-main\wandb\run-20240313_210453-3oq1hjiv\files\wandb-summary.json
2024-03-13 21:05:43,276 INFO    Thread-12 :11564 [dir_watcher.py:_on_file_modified():288] file/dir modified: E:\自动驾驶\车位检测\parking-space-Identification-in-different-weather-main\wandb\run-20240313_210453-3oq1hjiv\files\output.log
2024-03-13 21:05:44,039 ERROR   gpu       :11564 [interfaces.py:monitor():144] Failed to sample metric: Not Supported
2024-03-13 21:05:44,191 DEBUG   HandlerThread:11564 [handler.py:handle_request():144] handle_request: status_report
2024-03-13 21:05:44,892 DEBUG   HandlerThread:11564 [handler.py:handle_request():144] handle_request: partial_history
2024-03-13 21:05:44,892 DEBUG   SenderThread:11564 [sender.py:send():380] send: history
2024-03-13 21:05:44,893 DEBUG   SenderThread:11564 [sender.py:send_request():407] send_request: summary_record
2024-03-13 21:05:44,894 INFO    SenderThread:11564 [sender.py:_save_file():1378] saving file wandb-summary.json with policy end
2024-03-13 21:05:45,305 INFO    Thread-12 :11564 [dir_watcher.py:_on_file_modified():288] file/dir modified: E:\自动驾驶\车位检测\parking-space-Identification-in-different-weather-main\wandb\run-20240313_210453-3oq1hjiv\files\wandb-summary.json
2024-03-13 21:05:46,067 ERROR   gpu       :11564 [interfaces.py:monitor():144] Failed to sample metric: Not Supported
2024-03-13 21:05:46,900 DEBUG   HandlerThread:11564 [handler.py:handle_request():144] handle_request: partial_history
2024-03-13 21:05:46,901 DEBUG   HandlerThread:11564 [handler.py:handle_request():144] handle_request: partial_history
2024-03-13 21:05:46,902 DEBUG   SenderThread:11564 [sender.py:send():380] send: history
2024-03-13 21:05:46,902 DEBUG   SenderThread:11564 [sender.py:send_request():407] send_request: summary_record
2024-03-13 21:05:46,903 INFO    SenderThread:11564 [sender.py:_save_file():1378] saving file wandb-summary.json with policy end
2024-03-13 21:05:46,904 DEBUG   SenderThread:11564 [sender.py:send():380] send: history
2024-03-13 21:05:46,904 DEBUG   SenderThread:11564 [sender.py:send_request():407] send_request: summary_record
2024-03-13 21:05:46,905 INFO    SenderThread:11564 [sender.py:_save_file():1378] saving file wandb-summary.json with policy end
2024-03-13 21:05:47,322 INFO    Thread-12 :11564 [dir_watcher.py:_on_file_modified():288] file/dir modified: E:\自动驾驶\车位检测\parking-space-Identification-in-different-weather-main\wandb\run-20240313_210453-3oq1hjiv\files\wandb-summary.json
2024-03-13 21:05:47,322 INFO    Thread-12 :11564 [dir_watcher.py:_on_file_modified():288] file/dir modified: E:\自动驾驶\车位检测\parking-space-Identification-in-different-weather-main\wandb\run-20240313_210453-3oq1hjiv\files\output.log
2024-03-13 21:05:48,100 ERROR   gpu       :11564 [interfaces.py:monitor():144] Failed to sample metric: Not Supported
2024-03-13 21:05:48,264 ERROR   wandb-upload_0:11564 [internal_api.py:upload_file():2556] upload_file exception https://storage.googleapis.com/wandb-production.appspot.com/princeporch/uncategorized/3oq1hjiv/wandb-metadata.json?Expires=1710421510&GoogleAccessId=gorilla-files-url-signer-man%40wandb-production.iam.gserviceaccount.com&Signature=eOp1F3K0OOM3nLDkP8XGnJ3vXn9pxmhpqBLHGF70JePq4N7T%2B4hDEXHcmhltlUQ4NQc9xeuf4L9NTUU%2BemKL1XjMPGZBND6%2FSrv8%2FeIjMQZGrjidNIcRFBDVeo8CmuxZxdJ8Gptyw1wtIbncOOpIPzc8V5H7JupruC5U8TClVinntCLXpAqXzilii5v6LTDWYxZOX6GKmUhaJ871cyuuHvd2XejOlPzybq50U7LJHzWK4pdv0BWmuuhQEqsLpnTIkJ8IIeqMvtDgkxzpt5Y%2Fctx%2BBpalC7l25wD67YQWlfLN78ndHS0nNNKhuSR2F6PrWYtKn5tRxqmu3wALLCLFJg%3D%3D: HTTPSConnectionPool(host='storage.googleapis.com', port=443): Max retries exceeded with url: /wandb-production.appspot.com/princeporch/uncategorized/3oq1hjiv/wandb-metadata.json?Expires=1710421510&GoogleAccessId=gorilla-files-url-signer-man%40wandb-production.iam.gserviceaccount.com&Signature=eOp1F3K0OOM3nLDkP8XGnJ3vXn9pxmhpqBLHGF70JePq4N7T%2B4hDEXHcmhltlUQ4NQc9xeuf4L9NTUU%2BemKL1XjMPGZBND6%2FSrv8%2FeIjMQZGrjidNIcRFBDVeo8CmuxZxdJ8Gptyw1wtIbncOOpIPzc8V5H7JupruC5U8TClVinntCLXpAqXzilii5v6LTDWYxZOX6GKmUhaJ871cyuuHvd2XejOlPzybq50U7LJHzWK4pdv0BWmuuhQEqsLpnTIkJ8IIeqMvtDgkxzpt5Y%2Fctx%2BBpalC7l25wD67YQWlfLN78ndHS0nNNKhuSR2F6PrWYtKn5tRxqmu3wALLCLFJg%3D%3D (Caused by NewConnectionError('<urllib3.connection.HTTPSConnection object at 0x000001E233A76470>: Failed to establish a new connection: [WinError 10061] 由于目标计算机积极拒绝，无法连接。'))
2024-03-13 21:05:48,265 ERROR   wandb-upload_0:11564 [internal_api.py:upload_file():2558] upload_file request headers: {'User-Agent': 'python-requests/2.29.0', 'Accept-Encoding': 'gzip, deflate, br', 'Accept': '*/*', 'Connection': 'keep-alive', 'Content-Length': '1321'}
2024-03-13 21:05:48,265 ERROR   wandb-upload_0:11564 [internal_api.py:upload_file():2560] upload_file response body: 
2024-03-13 21:05:48,265 INFO    wandb-upload_0:11564 [retry.py:__call__():172] Retry attempt failed:
Traceback (most recent call last):
  File "E:\anaconda\lib\site-packages\urllib3\connection.py", line 174, in _new_conn
    conn = connection.create_connection(
  File "E:\anaconda\lib\site-packages\urllib3\util\connection.py", line 95, in create_connection
    raise err
  File "E:\anaconda\lib\site-packages\urllib3\util\connection.py", line 85, in create_connection
    sock.connect(sa)
ConnectionRefusedError: [WinError 10061] 由于目标计算机积极拒绝，无法连接。

During handling of the above exception, another exception occurred:

Traceback (most recent call last):
  File "E:\anaconda\lib\site-packages\urllib3\connectionpool.py", line 714, in urlopen
    httplib_response = self._make_request(
  File "E:\anaconda\lib\site-packages\urllib3\connectionpool.py", line 403, in _make_request
    self._validate_conn(conn)
  File "E:\anaconda\lib\site-packages\urllib3\connectionpool.py", line 1053, in _validate_conn
    conn.connect()
  File "E:\anaconda\lib\site-packages\urllib3\connection.py", line 363, in connect
    self.sock = conn = self._new_conn()
  File "E:\anaconda\lib\site-packages\urllib3\connection.py", line 186, in _new_conn
    raise NewConnectionError(
urllib3.exceptions.NewConnectionError: <urllib3.connection.HTTPSConnection object at 0x000001E233A76470>: Failed to establish a new connection: [WinError 10061] 由于目标计算机积极拒绝，无法连接。

During handling of the above exception, another exception occurred:

Traceback (most recent call last):
  File "E:\anaconda\lib\site-packages\requests\adapters.py", line 487, in send
    resp = conn.urlopen(
  File "E:\anaconda\lib\site-packages\urllib3\connectionpool.py", line 798, in urlopen
    retries = retries.increment(
  File "E:\anaconda\lib\site-packages\urllib3\util\retry.py", line 592, in increment
    raise MaxRetryError(_pool, url, error or ResponseError(cause))
urllib3.exceptions.MaxRetryError: HTTPSConnectionPool(host='storage.googleapis.com', port=443): Max retries exceeded with url: /wandb-production.appspot.com/princeporch/uncategorized/3oq1hjiv/wandb-metadata.json?Expires=1710421510&GoogleAccessId=gorilla-files-url-signer-man%40wandb-production.iam.gserviceaccount.com&Signature=eOp1F3K0OOM3nLDkP8XGnJ3vXn9pxmhpqBLHGF70JePq4N7T%2B4hDEXHcmhltlUQ4NQc9xeuf4L9NTUU%2BemKL1XjMPGZBND6%2FSrv8%2FeIjMQZGrjidNIcRFBDVeo8CmuxZxdJ8Gptyw1wtIbncOOpIPzc8V5H7JupruC5U8TClVinntCLXpAqXzilii5v6LTDWYxZOX6GKmUhaJ871cyuuHvd2XejOlPzybq50U7LJHzWK4pdv0BWmuuhQEqsLpnTIkJ8IIeqMvtDgkxzpt5Y%2Fctx%2BBpalC7l25wD67YQWlfLN78ndHS0nNNKhuSR2F6PrWYtKn5tRxqmu3wALLCLFJg%3D%3D (Caused by NewConnectionError('<urllib3.connection.HTTPSConnection object at 0x000001E233A76470>: Failed to establish a new connection: [WinError 10061] 由于目标计算机积极拒绝，无法连接。'))

During handling of the above exception, another exception occurred:

Traceback (most recent call last):
  File "E:\anaconda\lib\site-packages\wandb\sdk\internal\internal_api.py", line 2549, in upload_file
    response = self._upload_file_session.put(
  File "E:\anaconda\lib\site-packages\requests\sessions.py", line 647, in put
    return self.request("PUT", url, data=data, **kwargs)
  File "E:\anaconda\lib\site-packages\requests\sessions.py", line 587, in request
    resp = self.send(prep, **send_kwargs)
  File "E:\anaconda\lib\site-packages\requests\sessions.py", line 701, in send
    r = adapter.send(request, **kwargs)
  File "E:\anaconda\lib\site-packages\requests\adapters.py", line 520, in send
    raise ConnectionError(e, request=request)
requests.exceptions.ConnectionError: HTTPSConnectionPool(host='storage.googleapis.com', port=443): Max retries exceeded with url: /wandb-production.appspot.com/princeporch/uncategorized/3oq1hjiv/wandb-metadata.json?Expires=1710421510&GoogleAccessId=gorilla-files-url-signer-man%40wandb-production.iam.gserviceaccount.com&Signature=eOp1F3K0OOM3nLDkP8XGnJ3vXn9pxmhpqBLHGF70JePq4N7T%2B4hDEXHcmhltlUQ4NQc9xeuf4L9NTUU%2BemKL1XjMPGZBND6%2FSrv8%2FeIjMQZGrjidNIcRFBDVeo8CmuxZxdJ8Gptyw1wtIbncOOpIPzc8V5H7JupruC5U8TClVinntCLXpAqXzilii5v6LTDWYxZOX6GKmUhaJ871cyuuHvd2XejOlPzybq50U7LJHzWK4pdv0BWmuuhQEqsLpnTIkJ8IIeqMvtDgkxzpt5Y%2Fctx%2BBpalC7l25wD67YQWlfLN78ndHS0nNNKhuSR2F6PrWYtKn5tRxqmu3wALLCLFJg%3D%3D (Caused by NewConnectionError('<urllib3.connection.HTTPSConnection object at 0x000001E233A76470>: Failed to establish a new connection: [WinError 10061] 由于目标计算机积极拒绝，无法连接。'))

During handling of the above exception, another exception occurred:

Traceback (most recent call last):
  File "E:\anaconda\lib\site-packages\wandb\sdk\lib\retry.py", line 131, in __call__
    result = self._call_fn(*args, **kwargs)
  File "E:\anaconda\lib\site-packages\wandb\sdk\internal\internal_api.py", line 2580, in upload_file
    raise _e.with_traceback(sys.exc_info()[2])
  File "E:\anaconda\lib\site-packages\wandb\sdk\internal\internal_api.py", line 2549, in upload_file
    response = self._upload_file_session.put(
  File "E:\anaconda\lib\site-packages\requests\sessions.py", line 647, in put
    return self.request("PUT", url, data=data, **kwargs)
  File "E:\anaconda\lib\site-packages\requests\sessions.py", line 587, in request
    resp = self.send(prep, **send_kwargs)
  File "E:\anaconda\lib\site-packages\requests\sessions.py", line 701, in send
    r = adapter.send(request, **kwargs)
  File "E:\anaconda\lib\site-packages\requests\adapters.py", line 520, in send
    raise ConnectionError(e, request=request)
wandb.sdk.lib.retry.TransientError: None
2024-03-13 21:05:49,333 INFO    Thread-12 :11564 [dir_watcher.py:_on_file_modified():288] file/dir modified: E:\自动驾驶\车位检测\parking-space-Identification-in-different-weather-main\wandb\run-20240313_210453-3oq1hjiv\files\output.log
2024-03-13 21:05:49,596 DEBUG   HandlerThread:11564 [handler.py:handle_request():144] handle_request: status_report
2024-03-13 21:05:49,597 DEBUG   HandlerThread:11564 [handler.py:handle_request():144] handle_request: partial_history
2024-03-13 21:05:49,597 DEBUG   SenderThread:11564 [sender.py:send():380] send: history
2024-03-13 21:05:49,598 DEBUG   SenderThread:11564 [sender.py:send_request():407] send_request: summary_record
2024-03-13 21:05:49,599 INFO    SenderThread:11564 [sender.py:_save_file():1378] saving file wandb-summary.json with policy end
2024-03-13 21:05:50,134 ERROR   gpu       :11564 [interfaces.py:monitor():144] Failed to sample metric: Not Supported
2024-03-13 21:05:50,338 INFO    Thread-12 :11564 [dir_watcher.py:_on_file_modified():288] file/dir modified: E:\自动驾驶\车位检测\parking-space-Identification-in-different-weather-main\wandb\run-20240313_210453-3oq1hjiv\files\wandb-summary.json
2024-03-13 21:05:51,214 DEBUG   HandlerThread:11564 [handler.py:handle_request():144] handle_request: stop_status
2024-03-13 21:05:51,215 DEBUG   SenderThread:11564 [sender.py:send_request():407] send_request: stop_status
2024-03-13 21:05:51,229 DEBUG   HandlerThread:11564 [handler.py:handle_request():144] handle_request: internal_messages
2024-03-13 21:05:51,341 INFO    Thread-12 :11564 [dir_watcher.py:_on_file_modified():288] file/dir modified: E:\自动驾驶\车位检测\parking-space-Identification-in-different-weather-main\wandb\run-20240313_210453-3oq1hjiv\files\output.log
2024-03-13 21:05:51,490 DEBUG   HandlerThread:11564 [handler.py:handle_request():144] handle_request: partial_history
2024-03-13 21:05:51,491 DEBUG   HandlerThread:11564 [handler.py:handle_request():144] handle_request: partial_history
2024-03-13 21:05:51,594 DEBUG   SenderThread:11564 [sender.py:send():380] send: history
2024-03-13 21:05:51,595 DEBUG   SenderThread:11564 [sender.py:send_request():407] send_request: summary_record
2024-03-13 21:05:51,596 INFO    SenderThread:11564 [sender.py:_save_file():1378] saving file wandb-summary.json with policy end
2024-03-13 21:05:51,596 DEBUG   SenderThread:11564 [sender.py:send():380] send: history
2024-03-13 21:05:51,596 DEBUG   SenderThread:11564 [sender.py:send_request():407] send_request: summary_record
2024-03-13 21:05:51,597 INFO    SenderThread:11564 [sender.py:_save_file():1378] saving file wandb-summary.json with policy end
2024-03-13 21:05:52,173 ERROR   gpu       :11564 [interfaces.py:monitor():144] Failed to sample metric: Not Supported
2024-03-13 21:05:52,347 INFO    Thread-12 :11564 [dir_watcher.py:_on_file_modified():288] file/dir modified: E:\自动驾驶\车位检测\parking-space-Identification-in-different-weather-main\wandb\run-20240313_210453-3oq1hjiv\files\wandb-summary.json
2024-03-13 21:05:53,350 INFO    Thread-12 :11564 [dir_watcher.py:_on_file_modified():288] file/dir modified: E:\自动驾驶\车位检测\parking-space-Identification-in-different-weather-main\wandb\run-20240313_210453-3oq1hjiv\files\output.log
2024-03-13 21:05:54,184 DEBUG   HandlerThread:11564 [handler.py:handle_request():144] handle_request: partial_history
2024-03-13 21:05:54,185 DEBUG   SenderThread:11564 [sender.py:send():380] send: history
2024-03-13 21:05:54,185 DEBUG   SenderThread:11564 [sender.py:send_request():407] send_request: summary_record
2024-03-13 21:05:54,185 INFO    SenderThread:11564 [sender.py:_save_file():1378] saving file wandb-summary.json with policy end
2024-03-13 21:05:54,213 ERROR   gpu       :11564 [interfaces.py:monitor():144] Failed to sample metric: Not Supported
2024-03-13 21:05:54,364 INFO    Thread-12 :11564 [dir_watcher.py:_on_file_modified():288] file/dir modified: E:\自动驾驶\车位检测\parking-space-Identification-in-different-weather-main\wandb\run-20240313_210453-3oq1hjiv\files\wandb-summary.json
2024-03-13 21:05:55,191 DEBUG   HandlerThread:11564 [handler.py:handle_request():144] handle_request: status_report
2024-03-13 21:05:56,107 DEBUG   HandlerThread:11564 [handler.py:handle_request():144] handle_request: partial_history
2024-03-13 21:05:56,108 DEBUG   HandlerThread:11564 [handler.py:handle_request():144] handle_request: partial_history
2024-03-13 21:05:56,108 DEBUG   SenderThread:11564 [sender.py:send():380] send: history
2024-03-13 21:05:56,109 DEBUG   SenderThread:11564 [sender.py:send_request():407] send_request: summary_record
2024-03-13 21:05:56,110 INFO    SenderThread:11564 [sender.py:_save_file():1378] saving file wandb-summary.json with policy end
2024-03-13 21:05:56,110 DEBUG   SenderThread:11564 [sender.py:send():380] send: history
2024-03-13 21:05:56,110 DEBUG   SenderThread:11564 [sender.py:send_request():407] send_request: summary_record
2024-03-13 21:05:56,111 INFO    SenderThread:11564 [sender.py:_save_file():1378] saving file wandb-summary.json with policy end
2024-03-13 21:05:56,252 ERROR   gpu       :11564 [interfaces.py:monitor():144] Failed to sample metric: Not Supported
2024-03-13 21:05:56,371 INFO    Thread-12 :11564 [dir_watcher.py:_on_file_modified():288] file/dir modified: E:\自动驾驶\车位检测\parking-space-Identification-in-different-weather-main\wandb\run-20240313_210453-3oq1hjiv\files\wandb-summary.json
2024-03-13 21:05:56,372 INFO    Thread-12 :11564 [dir_watcher.py:_on_file_modified():288] file/dir modified: E:\自动驾驶\车位检测\parking-space-Identification-in-different-weather-main\wandb\run-20240313_210453-3oq1hjiv\files\output.log
2024-03-13 21:05:58,274 ERROR   gpu       :11564 [interfaces.py:monitor():144] Failed to sample metric: Not Supported
2024-03-13 21:05:58,383 INFO    Thread-12 :11564 [dir_watcher.py:_on_file_modified():288] file/dir modified: E:\自动驾驶\车位检测\parking-space-Identification-in-different-weather-main\wandb\run-20240313_210453-3oq1hjiv\files\output.log
2024-03-13 21:05:58,817 DEBUG   HandlerThread:11564 [handler.py:handle_request():144] handle_request: partial_history
2024-03-13 21:05:58,818 DEBUG   SenderThread:11564 [sender.py:send():380] send: history
2024-03-13 21:05:58,818 DEBUG   SenderThread:11564 [sender.py:send_request():407] send_request: summary_record
2024-03-13 21:05:58,819 INFO    SenderThread:11564 [sender.py:_save_file():1378] saving file wandb-summary.json with policy end
2024-03-13 21:05:59,210 DEBUG   SystemMonitor:11564 [system_monitor.py:_start():159] Starting system metrics aggregation loop
2024-03-13 21:05:59,212 DEBUG   SenderThread:11564 [sender.py:send():380] send: stats
2024-03-13 21:05:59,386 INFO    Thread-12 :11564 [dir_watcher.py:_on_file_modified():288] file/dir modified: E:\自动驾驶\车位检测\parking-space-Identification-in-different-weather-main\wandb\run-20240313_210453-3oq1hjiv\files\wandb-summary.json
2024-03-13 21:06:00,226 DEBUG   HandlerThread:11564 [handler.py:handle_request():144] handle_request: status_report
2024-03-13 21:06:00,352 ERROR   gpu       :11564 [interfaces.py:monitor():144] Failed to sample metric: Not Supported
2024-03-13 21:06:00,388 INFO    Thread-12 :11564 [dir_watcher.py:_on_file_modified():288] file/dir modified: E:\自动驾驶\车位检测\parking-space-Identification-in-different-weather-main\wandb\run-20240313_210453-3oq1hjiv\files\output.log
2024-03-13 21:06:00,708 DEBUG   HandlerThread:11564 [handler.py:handle_request():144] handle_request: partial_history
2024-03-13 21:06:00,708 DEBUG   HandlerThread:11564 [handler.py:handle_request():144] handle_request: partial_history
2024-03-13 21:06:00,709 DEBUG   SenderThread:11564 [sender.py:send():380] send: history
2024-03-13 21:06:00,710 DEBUG   SenderThread:11564 [sender.py:send_request():407] send_request: summary_record
2024-03-13 21:06:00,711 INFO    SenderThread:11564 [sender.py:_save_file():1378] saving file wandb-summary.json with policy end
2024-03-13 21:06:00,711 DEBUG   SenderThread:11564 [sender.py:send():380] send: history
2024-03-13 21:06:00,711 DEBUG   SenderThread:11564 [sender.py:send_request():407] send_request: summary_record
2024-03-13 21:06:00,712 INFO    SenderThread:11564 [sender.py:_save_file():1378] saving file wandb-summary.json with policy end
2024-03-13 21:06:01,404 INFO    Thread-12 :11564 [dir_watcher.py:_on_file_modified():288] file/dir modified: E:\自动驾驶\车位检测\parking-space-Identification-in-different-weather-main\wandb\run-20240313_210453-3oq1hjiv\files\wandb-summary.json
2024-03-13 21:06:02,372 ERROR   gpu       :11564 [interfaces.py:monitor():144] Failed to sample metric: Not Supported
2024-03-13 21:06:02,419 INFO    Thread-12 :11564 [dir_watcher.py:_on_file_modified():288] file/dir modified: E:\自动驾驶\车位检测\parking-space-Identification-in-different-weather-main\wandb\run-20240313_210453-3oq1hjiv\files\output.log
2024-03-13 21:06:03,399 DEBUG   HandlerThread:11564 [handler.py:handle_request():144] handle_request: partial_history
2024-03-13 21:06:03,399 DEBUG   SenderThread:11564 [sender.py:send():380] send: history
2024-03-13 21:06:03,400 DEBUG   SenderThread:11564 [sender.py:send_request():407] send_request: summary_record
2024-03-13 21:06:03,400 INFO    SenderThread:11564 [sender.py:_save_file():1378] saving file wandb-summary.json with policy end
2024-03-13 21:06:03,423 INFO    Thread-12 :11564 [dir_watcher.py:_on_file_modified():288] file/dir modified: E:\自动驾驶\车位检测\parking-space-Identification-in-different-weather-main\wandb\run-20240313_210453-3oq1hjiv\files\wandb-summary.json
2024-03-13 21:06:04,397 ERROR   gpu       :11564 [interfaces.py:monitor():144] Failed to sample metric: Not Supported
2024-03-13 21:06:04,427 INFO    Thread-12 :11564 [dir_watcher.py:_on_file_modified():288] file/dir modified: E:\自动驾驶\车位检测\parking-space-Identification-in-different-weather-main\wandb\run-20240313_210453-3oq1hjiv\files\output.log
2024-03-13 21:06:05,306 DEBUG   HandlerThread:11564 [handler.py:handle_request():144] handle_request: status_report
2024-03-13 21:06:05,306 DEBUG   HandlerThread:11564 [handler.py:handle_request():144] handle_request: partial_history
2024-03-13 21:06:05,307 DEBUG   HandlerThread:11564 [handler.py:handle_request():144] handle_request: partial_history
2024-03-13 21:06:05,308 DEBUG   SenderThread:11564 [sender.py:send():380] send: history
2024-03-13 21:06:05,308 DEBUG   SenderThread:11564 [sender.py:send_request():407] send_request: summary_record
2024-03-13 21:06:05,309 INFO    SenderThread:11564 [sender.py:_save_file():1378] saving file wandb-summary.json with policy end
2024-03-13 21:06:05,309 DEBUG   SenderThread:11564 [sender.py:send():380] send: history
2024-03-13 21:06:05,310 DEBUG   SenderThread:11564 [sender.py:send_request():407] send_request: summary_record
2024-03-13 21:06:05,310 INFO    SenderThread:11564 [sender.py:_save_file():1378] saving file wandb-summary.json with policy end
2024-03-13 21:06:05,413 ERROR   wandb-upload_0:11564 [internal_api.py:upload_file():2556] upload_file exception https://storage.googleapis.com/wandb-production.appspot.com/princeporch/uncategorized/3oq1hjiv/wandb-metadata.json?Expires=1710421510&GoogleAccessId=gorilla-files-url-signer-man%40wandb-production.iam.gserviceaccount.com&Signature=eOp1F3K0OOM3nLDkP8XGnJ3vXn9pxmhpqBLHGF70JePq4N7T%2B4hDEXHcmhltlUQ4NQc9xeuf4L9NTUU%2BemKL1XjMPGZBND6%2FSrv8%2FeIjMQZGrjidNIcRFBDVeo8CmuxZxdJ8Gptyw1wtIbncOOpIPzc8V5H7JupruC5U8TClVinntCLXpAqXzilii5v6LTDWYxZOX6GKmUhaJ871cyuuHvd2XejOlPzybq50U7LJHzWK4pdv0BWmuuhQEqsLpnTIkJ8IIeqMvtDgkxzpt5Y%2Fctx%2BBpalC7l25wD67YQWlfLN78ndHS0nNNKhuSR2F6PrWYtKn5tRxqmu3wALLCLFJg%3D%3D: HTTPSConnectionPool(host='storage.googleapis.com', port=443): Max retries exceeded with url: /wandb-production.appspot.com/princeporch/uncategorized/3oq1hjiv/wandb-metadata.json?Expires=1710421510&GoogleAccessId=gorilla-files-url-signer-man%40wandb-production.iam.gserviceaccount.com&Signature=eOp1F3K0OOM3nLDkP8XGnJ3vXn9pxmhpqBLHGF70JePq4N7T%2B4hDEXHcmhltlUQ4NQc9xeuf4L9NTUU%2BemKL1XjMPGZBND6%2FSrv8%2FeIjMQZGrjidNIcRFBDVeo8CmuxZxdJ8Gptyw1wtIbncOOpIPzc8V5H7JupruC5U8TClVinntCLXpAqXzilii5v6LTDWYxZOX6GKmUhaJ871cyuuHvd2XejOlPzybq50U7LJHzWK4pdv0BWmuuhQEqsLpnTIkJ8IIeqMvtDgkxzpt5Y%2Fctx%2BBpalC7l25wD67YQWlfLN78ndHS0nNNKhuSR2F6PrWYtKn5tRxqmu3wALLCLFJg%3D%3D (Caused by NewConnectionError('<urllib3.connection.HTTPSConnection object at 0x000001E233A57610>: Failed to establish a new connection: [WinError 10061] 由于目标计算机积极拒绝，无法连接。'))
2024-03-13 21:06:05,413 ERROR   wandb-upload_0:11564 [internal_api.py:upload_file():2558] upload_file request headers: {'User-Agent': 'python-requests/2.29.0', 'Accept-Encoding': 'gzip, deflate, br', 'Accept': '*/*', 'Connection': 'keep-alive', 'Content-Length': '1321'}
2024-03-13 21:06:05,413 ERROR   wandb-upload_0:11564 [internal_api.py:upload_file():2560] upload_file response body: 
2024-03-13 21:06:05,430 INFO    Thread-12 :11564 [dir_watcher.py:_on_file_modified():288] file/dir modified: E:\自动驾驶\车位检测\parking-space-Identification-in-different-weather-main\wandb\run-20240313_210453-3oq1hjiv\files\wandb-summary.json
2024-03-13 21:06:06,209 DEBUG   HandlerThread:11564 [handler.py:handle_request():144] handle_request: stop_status
2024-03-13 21:06:06,210 DEBUG   SenderThread:11564 [sender.py:send_request():407] send_request: stop_status
2024-03-13 21:06:06,241 DEBUG   HandlerThread:11564 [handler.py:handle_request():144] handle_request: internal_messages
2024-03-13 21:06:06,419 ERROR   gpu       :11564 [interfaces.py:monitor():144] Failed to sample metric: Not Supported
2024-03-13 21:06:06,433 INFO    Thread-12 :11564 [dir_watcher.py:_on_file_modified():288] file/dir modified: E:\自动驾驶\车位检测\parking-space-Identification-in-different-weather-main\wandb\run-20240313_210453-3oq1hjiv\files\output.log
2024-03-13 21:06:08,016 DEBUG   HandlerThread:11564 [handler.py:handle_request():144] handle_request: partial_history
2024-03-13 21:06:08,017 DEBUG   SenderThread:11564 [sender.py:send():380] send: history
2024-03-13 21:06:08,017 DEBUG   SenderThread:11564 [sender.py:send_request():407] send_request: summary_record
2024-03-13 21:06:08,018 INFO    SenderThread:11564 [sender.py:_save_file():1378] saving file wandb-summary.json with policy end
2024-03-13 21:06:08,445 INFO    Thread-12 :11564 [dir_watcher.py:_on_file_modified():288] file/dir modified: E:\自动驾驶\车位检测\parking-space-Identification-in-different-weather-main\wandb\run-20240313_210453-3oq1hjiv\files\wandb-summary.json
2024-03-13 21:06:08,446 INFO    Thread-12 :11564 [dir_watcher.py:_on_file_modified():288] file/dir modified: E:\自动驾驶\车位检测\parking-space-Identification-in-different-weather-main\wandb\run-20240313_210453-3oq1hjiv\files\output.log
2024-03-13 21:06:08,450 ERROR   gpu       :11564 [interfaces.py:monitor():144] Failed to sample metric: Not Supported
2024-03-13 21:06:10,006 DEBUG   HandlerThread:11564 [handler.py:handle_request():144] handle_request: partial_history
2024-03-13 21:06:10,007 DEBUG   HandlerThread:11564 [handler.py:handle_request():144] handle_request: partial_history
2024-03-13 21:06:10,007 DEBUG   SenderThread:11564 [sender.py:send():380] send: history
2024-03-13 21:06:10,008 DEBUG   SenderThread:11564 [sender.py:send_request():407] send_request: summary_record
2024-03-13 21:06:10,008 INFO    SenderThread:11564 [sender.py:_save_file():1378] saving file wandb-summary.json with policy end
2024-03-13 21:06:10,009 DEBUG   SenderThread:11564 [sender.py:send():380] send: history
2024-03-13 21:06:10,009 DEBUG   SenderThread:11564 [sender.py:send_request():407] send_request: summary_record
2024-03-13 21:06:10,010 INFO    SenderThread:11564 [sender.py:_save_file():1378] saving file wandb-summary.json with policy end
2024-03-13 21:06:10,469 INFO    Thread-12 :11564 [dir_watcher.py:_on_file_modified():288] file/dir modified: E:\自动驾驶\车位检测\parking-space-Identification-in-different-weather-main\wandb\run-20240313_210453-3oq1hjiv\files\wandb-summary.json
2024-03-13 21:06:10,470 INFO    Thread-12 :11564 [dir_watcher.py:_on_file_modified():288] file/dir modified: E:\自动驾驶\车位检测\parking-space-Identification-in-different-weather-main\wandb\run-20240313_210453-3oq1hjiv\files\output.log
2024-03-13 21:06:10,489 ERROR   gpu       :11564 [interfaces.py:monitor():144] Failed to sample metric: Not Supported
2024-03-13 21:06:11,016 DEBUG   HandlerThread:11564 [handler.py:handle_request():144] handle_request: status_report
2024-03-13 21:06:12,519 ERROR   gpu       :11564 [interfaces.py:monitor():144] Failed to sample metric: Not Supported
2024-03-13 21:06:12,695 DEBUG   HandlerThread:11564 [handler.py:handle_request():144] handle_request: partial_history
2024-03-13 21:06:12,696 DEBUG   SenderThread:11564 [sender.py:send():380] send: history
2024-03-13 21:06:12,696 DEBUG   SenderThread:11564 [sender.py:send_request():407] send_request: summary_record
2024-03-13 21:06:12,697 INFO    SenderThread:11564 [sender.py:_save_file():1378] saving file wandb-summary.json with policy end
2024-03-13 21:06:13,508 INFO    Thread-12 :11564 [dir_watcher.py:_on_file_modified():288] file/dir modified: E:\自动驾驶\车位检测\parking-space-Identification-in-different-weather-main\wandb\run-20240313_210453-3oq1hjiv\files\wandb-summary.json
2024-03-13 21:06:14,540 INFO    Thread-12 :11564 [dir_watcher.py:_on_file_modified():288] file/dir modified: E:\自动驾驶\车位检测\parking-space-Identification-in-different-weather-main\wandb\run-20240313_210453-3oq1hjiv\files\output.log
2024-03-13 21:06:14,556 ERROR   gpu       :11564 [interfaces.py:monitor():144] Failed to sample metric: Not Supported
2024-03-13 21:06:14,629 DEBUG   HandlerThread:11564 [handler.py:handle_request():144] handle_request: partial_history
2024-03-13 21:06:14,630 DEBUG   HandlerThread:11564 [handler.py:handle_request():144] handle_request: partial_history
2024-03-13 21:06:14,630 DEBUG   SenderThread:11564 [sender.py:send():380] send: history
2024-03-13 21:06:14,631 DEBUG   SenderThread:11564 [sender.py:send_request():407] send_request: summary_record
2024-03-13 21:06:14,632 INFO    SenderThread:11564 [sender.py:_save_file():1378] saving file wandb-summary.json with policy end
2024-03-13 21:06:14,632 DEBUG   SenderThread:11564 [sender.py:send():380] send: history
2024-03-13 21:06:14,632 DEBUG   SenderThread:11564 [sender.py:send_request():407] send_request: summary_record
2024-03-13 21:06:14,633 INFO    SenderThread:11564 [sender.py:_save_file():1378] saving file wandb-summary.json with policy end
2024-03-13 21:06:15,551 INFO    Thread-12 :11564 [dir_watcher.py:_on_file_modified():288] file/dir modified: E:\自动驾驶\车位检测\parking-space-Identification-in-different-weather-main\wandb\run-20240313_210453-3oq1hjiv\files\wandb-summary.json
2024-03-13 21:06:16,583 INFO    Thread-12 :11564 [dir_watcher.py:_on_file_modified():288] file/dir modified: E:\自动驾驶\车位检测\parking-space-Identification-in-different-weather-main\wandb\run-20240313_210453-3oq1hjiv\files\output.log
2024-03-13 21:06:16,604 ERROR   gpu       :11564 [interfaces.py:monitor():144] Failed to sample metric: Not Supported
2024-03-13 21:06:16,650 DEBUG   HandlerThread:11564 [handler.py:handle_request():144] handle_request: status_report
2024-03-13 21:06:17,317 DEBUG   HandlerThread:11564 [handler.py:handle_request():144] handle_request: partial_history
2024-03-13 21:06:17,318 DEBUG   SenderThread:11564 [sender.py:send():380] send: history
2024-03-13 21:06:17,318 DEBUG   SenderThread:11564 [sender.py:send_request():407] send_request: summary_record
2024-03-13 21:06:17,319 INFO    SenderThread:11564 [sender.py:_save_file():1378] saving file wandb-summary.json with policy end
2024-03-13 21:06:17,593 INFO    Thread-12 :11564 [dir_watcher.py:_on_file_modified():288] file/dir modified: E:\自动驾驶\车位检测\parking-space-Identification-in-different-weather-main\wandb\run-20240313_210453-3oq1hjiv\files\wandb-summary.json
2024-03-13 21:06:18,623 INFO    Thread-12 :11564 [dir_watcher.py:_on_file_modified():288] file/dir modified: E:\自动驾驶\车位检测\parking-space-Identification-in-different-weather-main\wandb\run-20240313_210453-3oq1hjiv\files\output.log
2024-03-13 21:06:18,646 ERROR   gpu       :11564 [interfaces.py:monitor():144] Failed to sample metric: Not Supported
2024-03-13 21:06:19,302 DEBUG   HandlerThread:11564 [handler.py:handle_request():144] handle_request: partial_history
2024-03-13 21:06:19,303 DEBUG   HandlerThread:11564 [handler.py:handle_request():144] handle_request: partial_history
2024-03-13 21:06:19,304 DEBUG   SenderThread:11564 [sender.py:send():380] send: history
2024-03-13 21:06:19,304 DEBUG   SenderThread:11564 [sender.py:send_request():407] send_request: summary_record
2024-03-13 21:06:19,305 INFO    SenderThread:11564 [sender.py:_save_file():1378] saving file wandb-summary.json with policy end
2024-03-13 21:06:19,306 DEBUG   SenderThread:11564 [sender.py:send():380] send: history
2024-03-13 21:06:19,306 DEBUG   SenderThread:11564 [sender.py:send_request():407] send_request: summary_record
2024-03-13 21:06:19,306 INFO    SenderThread:11564 [sender.py:_save_file():1378] saving file wandb-summary.json with policy end
2024-03-13 21:06:19,631 INFO    Thread-12 :11564 [dir_watcher.py:_on_file_modified():288] file/dir modified: E:\自动驾驶\车位检测\parking-space-Identification-in-different-weather-main\wandb\run-20240313_210453-3oq1hjiv\files\wandb-summary.json
2024-03-13 21:06:20,666 INFO    Thread-12 :11564 [dir_watcher.py:_on_file_modified():288] file/dir modified: E:\自动驾驶\车位检测\parking-space-Identification-in-different-weather-main\wandb\run-20240313_210453-3oq1hjiv\files\output.log
2024-03-13 21:06:20,685 ERROR   gpu       :11564 [interfaces.py:monitor():144] Failed to sample metric: Not Supported
2024-03-13 21:06:21,227 DEBUG   HandlerThread:11564 [handler.py:handle_request():144] handle_request: stop_status
2024-03-13 21:06:21,228 DEBUG   SenderThread:11564 [sender.py:send_request():407] send_request: stop_status
2024-03-13 21:06:21,243 DEBUG   HandlerThread:11564 [handler.py:handle_request():144] handle_request: internal_messages
2024-03-13 21:06:21,656 DEBUG   HandlerThread:11564 [handler.py:handle_request():144] handle_request: status_report
2024-03-13 21:06:22,002 DEBUG   HandlerThread:11564 [handler.py:handle_request():144] handle_request: partial_history
2024-03-13 21:06:22,003 DEBUG   SenderThread:11564 [sender.py:send():380] send: history
2024-03-13 21:06:22,003 DEBUG   SenderThread:11564 [sender.py:send_request():407] send_request: summary_record
2024-03-13 21:06:22,004 INFO    SenderThread:11564 [sender.py:_save_file():1378] saving file wandb-summary.json with policy end
2024-03-13 21:06:22,707 INFO    Thread-12 :11564 [dir_watcher.py:_on_file_modified():288] file/dir modified: E:\自动驾驶\车位检测\parking-space-Identification-in-different-weather-main\wandb\run-20240313_210453-3oq1hjiv\files\wandb-summary.json
2024-03-13 21:06:22,708 INFO    Thread-12 :11564 [dir_watcher.py:_on_file_modified():288] file/dir modified: E:\自动驾驶\车位检测\parking-space-Identification-in-different-weather-main\wandb\run-20240313_210453-3oq1hjiv\files\output.log
2024-03-13 21:06:22,725 ERROR   gpu       :11564 [interfaces.py:monitor():144] Failed to sample metric: Not Supported
2024-03-13 21:06:23,977 DEBUG   HandlerThread:11564 [handler.py:handle_request():144] handle_request: partial_history
2024-03-13 21:06:23,978 DEBUG   HandlerThread:11564 [handler.py:handle_request():144] handle_request: partial_history
2024-03-13 21:06:23,979 DEBUG   SenderThread:11564 [sender.py:send():380] send: history
2024-03-13 21:06:23,979 DEBUG   SenderThread:11564 [sender.py:send_request():407] send_request: summary_record
2024-03-13 21:06:23,980 INFO    SenderThread:11564 [sender.py:_save_file():1378] saving file wandb-summary.json with policy end
2024-03-13 21:06:23,981 DEBUG   SenderThread:11564 [sender.py:send():380] send: history
2024-03-13 21:06:23,981 DEBUG   SenderThread:11564 [sender.py:send_request():407] send_request: summary_record
2024-03-13 21:06:23,981 INFO    SenderThread:11564 [sender.py:_save_file():1378] saving file wandb-summary.json with policy end
2024-03-13 21:06:24,744 INFO    Thread-12 :11564 [dir_watcher.py:_on_file_modified():288] file/dir modified: E:\自动驾驶\车位检测\parking-space-Identification-in-different-weather-main\wandb\run-20240313_210453-3oq1hjiv\files\wandb-summary.json
2024-03-13 21:06:24,745 INFO    Thread-12 :11564 [dir_watcher.py:_on_file_modified():288] file/dir modified: E:\自动驾驶\车位检测\parking-space-Identification-in-different-weather-main\wandb\run-20240313_210453-3oq1hjiv\files\output.log
2024-03-13 21:06:24,764 ERROR   gpu       :11564 [interfaces.py:monitor():144] Failed to sample metric: Not Supported
2024-03-13 21:06:26,660 DEBUG   HandlerThread:11564 [handler.py:handle_request():144] handle_request: status_report
2024-03-13 21:06:26,660 DEBUG   HandlerThread:11564 [handler.py:handle_request():144] handle_request: partial_history
2024-03-13 21:06:26,661 DEBUG   SenderThread:11564 [sender.py:send():380] send: history
2024-03-13 21:06:26,661 DEBUG   SenderThread:11564 [sender.py:send_request():407] send_request: summary_record
2024-03-13 21:06:26,662 INFO    SenderThread:11564 [sender.py:_save_file():1378] saving file wandb-summary.json with policy end
2024-03-13 21:06:26,781 ERROR   wandb-upload_0:11564 [internal_api.py:upload_file():2556] upload_file exception https://storage.googleapis.com/wandb-production.appspot.com/princeporch/uncategorized/3oq1hjiv/wandb-metadata.json?Expires=1710421510&GoogleAccessId=gorilla-files-url-signer-man%40wandb-production.iam.gserviceaccount.com&Signature=eOp1F3K0OOM3nLDkP8XGnJ3vXn9pxmhpqBLHGF70JePq4N7T%2B4hDEXHcmhltlUQ4NQc9xeuf4L9NTUU%2BemKL1XjMPGZBND6%2FSrv8%2FeIjMQZGrjidNIcRFBDVeo8CmuxZxdJ8Gptyw1wtIbncOOpIPzc8V5H7JupruC5U8TClVinntCLXpAqXzilii5v6LTDWYxZOX6GKmUhaJ871cyuuHvd2XejOlPzybq50U7LJHzWK4pdv0BWmuuhQEqsLpnTIkJ8IIeqMvtDgkxzpt5Y%2Fctx%2BBpalC7l25wD67YQWlfLN78ndHS0nNNKhuSR2F6PrWYtKn5tRxqmu3wALLCLFJg%3D%3D: HTTPSConnectionPool(host='storage.googleapis.com', port=443): Max retries exceeded with url: /wandb-production.appspot.com/princeporch/uncategorized/3oq1hjiv/wandb-metadata.json?Expires=1710421510&GoogleAccessId=gorilla-files-url-signer-man%40wandb-production.iam.gserviceaccount.com&Signature=eOp1F3K0OOM3nLDkP8XGnJ3vXn9pxmhpqBLHGF70JePq4N7T%2B4hDEXHcmhltlUQ4NQc9xeuf4L9NTUU%2BemKL1XjMPGZBND6%2FSrv8%2FeIjMQZGrjidNIcRFBDVeo8CmuxZxdJ8Gptyw1wtIbncOOpIPzc8V5H7JupruC5U8TClVinntCLXpAqXzilii5v6LTDWYxZOX6GKmUhaJ871cyuuHvd2XejOlPzybq50U7LJHzWK4pdv0BWmuuhQEqsLpnTIkJ8IIeqMvtDgkxzpt5Y%2Fctx%2BBpalC7l25wD67YQWlfLN78ndHS0nNNKhuSR2F6PrWYtKn5tRxqmu3wALLCLFJg%3D%3D (Caused by NewConnectionError('<urllib3.connection.HTTPSConnection object at 0x000001E233A742E0>: Failed to establish a new connection: [WinError 10061] 由于目标计算机积极拒绝，无法连接。'))
2024-03-13 21:06:26,781 ERROR   wandb-upload_0:11564 [internal_api.py:upload_file():2558] upload_file request headers: {'User-Agent': 'python-requests/2.29.0', 'Accept-Encoding': 'gzip, deflate, br', 'Accept': '*/*', 'Connection': 'keep-alive', 'Content-Length': '1321'}
2024-03-13 21:06:26,781 ERROR   wandb-upload_0:11564 [internal_api.py:upload_file():2560] upload_file response body: 
2024-03-13 21:06:26,782 INFO    Thread-12 :11564 [dir_watcher.py:_on_file_modified():288] file/dir modified: E:\自动驾驶\车位检测\parking-space-Identification-in-different-weather-main\wandb\run-20240313_210453-3oq1hjiv\files\wandb-summary.json
2024-03-13 21:06:26,802 ERROR   gpu       :11564 [interfaces.py:monitor():144] Failed to sample metric: Not Supported
2024-03-13 21:06:28,625 DEBUG   HandlerThread:11564 [handler.py:handle_request():144] handle_request: partial_history
2024-03-13 21:06:28,625 DEBUG   HandlerThread:11564 [handler.py:handle_request():144] handle_request: partial_history
2024-03-13 21:06:28,626 DEBUG   SenderThread:11564 [sender.py:send():380] send: history
2024-03-13 21:06:28,627 DEBUG   SenderThread:11564 [sender.py:send_request():407] send_request: summary_record
2024-03-13 21:06:28,627 INFO    SenderThread:11564 [sender.py:_save_file():1378] saving file wandb-summary.json with policy end
2024-03-13 21:06:28,628 DEBUG   SenderThread:11564 [sender.py:send():380] send: history
2024-03-13 21:06:28,628 DEBUG   SenderThread:11564 [sender.py:send_request():407] send_request: summary_record
2024-03-13 21:06:28,629 INFO    SenderThread:11564 [sender.py:_save_file():1378] saving file wandb-summary.json with policy end
2024-03-13 21:06:28,818 INFO    Thread-12 :11564 [dir_watcher.py:_on_file_modified():288] file/dir modified: E:\自动驾驶\车位检测\parking-space-Identification-in-different-weather-main\wandb\run-20240313_210453-3oq1hjiv\files\wandb-summary.json
2024-03-13 21:06:28,819 INFO    Thread-12 :11564 [dir_watcher.py:_on_file_modified():288] file/dir modified: E:\自动驾驶\车位检测\parking-space-Identification-in-different-weather-main\wandb\run-20240313_210453-3oq1hjiv\files\output.log
2024-03-13 21:06:28,835 ERROR   gpu       :11564 [interfaces.py:monitor():144] Failed to sample metric: Not Supported
2024-03-13 21:06:29,221 DEBUG   SenderThread:11564 [sender.py:send():380] send: stats
2024-03-13 21:06:30,871 INFO    Thread-12 :11564 [dir_watcher.py:_on_file_modified():288] file/dir modified: E:\自动驾驶\车位检测\parking-space-Identification-in-different-weather-main\wandb\run-20240313_210453-3oq1hjiv\files\output.log
2024-03-13 21:06:30,922 ERROR   gpu       :11564 [interfaces.py:monitor():144] Failed to sample metric: Not Supported
2024-03-13 21:06:31,330 DEBUG   HandlerThread:11564 [handler.py:handle_request():144] handle_request: partial_history
2024-03-13 21:06:31,331 DEBUG   SenderThread:11564 [sender.py:send():380] send: history
2024-03-13 21:06:31,331 DEBUG   SenderThread:11564 [sender.py:send_request():407] send_request: summary_record
2024-03-13 21:06:31,332 INFO    SenderThread:11564 [sender.py:_save_file():1378] saving file wandb-summary.json with policy end
2024-03-13 21:06:31,867 INFO    Thread-12 :11564 [dir_watcher.py:_on_file_modified():288] file/dir modified: E:\自动驾驶\车位检测\parking-space-Identification-in-different-weather-main\wandb\run-20240313_210453-3oq1hjiv\files\wandb-summary.json
2024-03-13 21:06:32,345 DEBUG   HandlerThread:11564 [handler.py:handle_request():144] handle_request: status_report
2024-03-13 21:06:32,907 INFO    Thread-12 :11564 [dir_watcher.py:_on_file_modified():288] file/dir modified: E:\自动驾驶\车位检测\parking-space-Identification-in-different-weather-main\wandb\run-20240313_210453-3oq1hjiv\files\output.log
2024-03-13 21:06:32,959 ERROR   gpu       :11564 [interfaces.py:monitor():144] Failed to sample metric: Not Supported
2024-03-13 21:06:33,317 DEBUG   HandlerThread:11564 [handler.py:handle_request():144] handle_request: partial_history
2024-03-13 21:06:33,317 DEBUG   HandlerThread:11564 [handler.py:handle_request():144] handle_request: partial_history
2024-03-13 21:06:33,318 DEBUG   SenderThread:11564 [sender.py:send():380] send: history
2024-03-13 21:06:33,319 DEBUG   SenderThread:11564 [sender.py:send_request():407] send_request: summary_record
2024-03-13 21:06:33,320 INFO    SenderThread:11564 [sender.py:_save_file():1378] saving file wandb-summary.json with policy end
2024-03-13 21:06:33,320 DEBUG   SenderThread:11564 [sender.py:send():380] send: history
2024-03-13 21:06:33,320 DEBUG   SenderThread:11564 [sender.py:send_request():407] send_request: summary_record
2024-03-13 21:06:33,321 INFO    SenderThread:11564 [sender.py:_save_file():1378] saving file wandb-summary.json with policy end
2024-03-13 21:06:33,921 INFO    Thread-12 :11564 [dir_watcher.py:_on_file_modified():288] file/dir modified: E:\自动驾驶\车位检测\parking-space-Identification-in-different-weather-main\wandb\run-20240313_210453-3oq1hjiv\files\wandb-summary.json
2024-03-13 21:06:34,944 INFO    Thread-12 :11564 [dir_watcher.py:_on_file_modified():288] file/dir modified: E:\自动驾驶\车位检测\parking-space-Identification-in-different-weather-main\wandb\run-20240313_210453-3oq1hjiv\files\output.log
2024-03-13 21:06:34,998 ERROR   gpu       :11564 [interfaces.py:monitor():144] Failed to sample metric: Not Supported
2024-03-13 21:06:36,017 DEBUG   HandlerThread:11564 [handler.py:handle_request():144] handle_request: partial_history
2024-03-13 21:06:36,017 DEBUG   SenderThread:11564 [sender.py:send():380] send: history
2024-03-13 21:06:36,017 DEBUG   SenderThread:11564 [sender.py:send_request():407] send_request: summary_record
2024-03-13 21:06:36,018 INFO    SenderThread:11564 [sender.py:_save_file():1378] saving file wandb-summary.json with policy end
2024-03-13 21:06:36,239 DEBUG   HandlerThread:11564 [handler.py:handle_request():144] handle_request: stop_status
2024-03-13 21:06:36,239 DEBUG   SenderThread:11564 [sender.py:send_request():407] send_request: stop_status
2024-03-13 21:06:36,254 DEBUG   HandlerThread:11564 [handler.py:handle_request():144] handle_request: internal_messages
2024-03-13 21:06:36,985 INFO    Thread-12 :11564 [dir_watcher.py:_on_file_modified():288] file/dir modified: E:\自动驾驶\车位检测\parking-space-Identification-in-different-weather-main\wandb\run-20240313_210453-3oq1hjiv\files\wandb-summary.json
2024-03-13 21:06:36,986 INFO    Thread-12 :11564 [dir_watcher.py:_on_file_modified():288] file/dir modified: E:\自动驾驶\车位检测\parking-space-Identification-in-different-weather-main\wandb\run-20240313_210453-3oq1hjiv\files\output.log
2024-03-13 21:06:37,021 ERROR   gpu       :11564 [interfaces.py:monitor():144] Failed to sample metric: Not Supported
2024-03-13 21:06:37,609 DEBUG   HandlerThread:11564 [handler.py:handle_request():144] handle_request: status_report
2024-03-13 21:06:38,007 DEBUG   HandlerThread:11564 [handler.py:handle_request():144] handle_request: partial_history
2024-03-13 21:06:38,008 DEBUG   HandlerThread:11564 [handler.py:handle_request():144] handle_request: partial_history
2024-03-13 21:06:38,009 DEBUG   SenderThread:11564 [sender.py:send():380] send: history
2024-03-13 21:06:38,009 DEBUG   SenderThread:11564 [sender.py:send_request():407] send_request: summary_record
2024-03-13 21:06:38,010 INFO    SenderThread:11564 [sender.py:_save_file():1378] saving file wandb-summary.json with policy end
2024-03-13 21:06:38,010 DEBUG   SenderThread:11564 [sender.py:send():380] send: history
2024-03-13 21:06:38,010 DEBUG   SenderThread:11564 [sender.py:send_request():407] send_request: summary_record
2024-03-13 21:06:38,011 INFO    SenderThread:11564 [sender.py:_save_file():1378] saving file wandb-summary.json with policy end
2024-03-13 21:06:39,026 INFO    Thread-12 :11564 [dir_watcher.py:_on_file_modified():288] file/dir modified: E:\自动驾驶\车位检测\parking-space-Identification-in-different-weather-main\wandb\run-20240313_210453-3oq1hjiv\files\wandb-summary.json
2024-03-13 21:06:39,027 INFO    Thread-12 :11564 [dir_watcher.py:_on_file_modified():288] file/dir modified: E:\自动驾驶\车位检测\parking-space-Identification-in-different-weather-main\wandb\run-20240313_210453-3oq1hjiv\files\output.log
2024-03-13 21:06:39,046 ERROR   gpu       :11564 [interfaces.py:monitor():144] Failed to sample metric: Not Supported
2024-03-13 21:06:40,693 DEBUG   HandlerThread:11564 [handler.py:handle_request():144] handle_request: partial_history
2024-03-13 21:06:40,694 DEBUG   SenderThread:11564 [sender.py:send():380] send: history
2024-03-13 21:06:40,694 DEBUG   SenderThread:11564 [sender.py:send_request():407] send_request: summary_record
2024-03-13 21:06:40,695 INFO    SenderThread:11564 [sender.py:_save_file():1378] saving file wandb-summary.json with policy end
2024-03-13 21:06:41,070 INFO    Thread-12 :11564 [dir_watcher.py:_on_file_modified():288] file/dir modified: E:\自动驾驶\车位检测\parking-space-Identification-in-different-weather-main\wandb\run-20240313_210453-3oq1hjiv\files\wandb-summary.json
2024-03-13 21:06:41,086 ERROR   gpu       :11564 [interfaces.py:monitor():144] Failed to sample metric: Not Supported
2024-03-13 21:06:42,645 DEBUG   HandlerThread:11564 [handler.py:handle_request():144] handle_request: status_report
2024-03-13 21:06:42,645 DEBUG   HandlerThread:11564 [handler.py:handle_request():144] handle_request: partial_history
2024-03-13 21:06:42,646 DEBUG   HandlerThread:11564 [handler.py:handle_request():144] handle_request: partial_history
2024-03-13 21:06:42,647 DEBUG   SenderThread:11564 [sender.py:send():380] send: history
2024-03-13 21:06:42,647 DEBUG   SenderThread:11564 [sender.py:send_request():407] send_request: summary_record
2024-03-13 21:06:42,648 INFO    SenderThread:11564 [sender.py:_save_file():1378] saving file wandb-summary.json with policy end
2024-03-13 21:06:42,648 DEBUG   SenderThread:11564 [sender.py:send():380] send: history
2024-03-13 21:06:42,648 DEBUG   SenderThread:11564 [sender.py:send_request():407] send_request: summary_record
2024-03-13 21:06:42,649 INFO    SenderThread:11564 [sender.py:_save_file():1378] saving file wandb-summary.json with policy end
2024-03-13 21:06:42,789 DEBUG   SenderThread:11564 [sender.py:send():380] send: exit
2024-03-13 21:06:42,789 INFO    SenderThread:11564 [sender.py:send_exit():585] handling exit code: 0
2024-03-13 21:06:42,790 INFO    SenderThread:11564 [sender.py:send_exit():587] handling runtime: 103
2024-03-13 21:06:42,790 INFO    SenderThread:11564 [sender.py:_save_file():1378] saving file wandb-summary.json with policy end
2024-03-13 21:06:42,791 INFO    SenderThread:11564 [sender.py:send_exit():593] send defer
2024-03-13 21:06:42,791 DEBUG   HandlerThread:11564 [handler.py:handle_request():144] handle_request: defer
2024-03-13 21:06:42,791 INFO    HandlerThread:11564 [handler.py:handle_request_defer():170] handle defer: 0
2024-03-13 21:06:42,791 DEBUG   SenderThread:11564 [sender.py:send_request():407] send_request: defer
2024-03-13 21:06:42,791 INFO    SenderThread:11564 [sender.py:send_request_defer():609] handle sender defer: 0
2024-03-13 21:06:42,791 INFO    SenderThread:11564 [sender.py:transition_state():613] send defer: 1
2024-03-13 21:06:42,791 DEBUG   HandlerThread:11564 [handler.py:handle_request():144] handle_request: defer
2024-03-13 21:06:42,792 INFO    HandlerThread:11564 [handler.py:handle_request_defer():170] handle defer: 1
2024-03-13 21:06:42,792 DEBUG   SenderThread:11564 [sender.py:send_request():407] send_request: defer
2024-03-13 21:06:42,792 INFO    SenderThread:11564 [sender.py:send_request_defer():609] handle sender defer: 1
2024-03-13 21:06:42,792 INFO    SenderThread:11564 [sender.py:transition_state():613] send defer: 2
2024-03-13 21:06:42,792 DEBUG   HandlerThread:11564 [handler.py:handle_request():144] handle_request: defer
2024-03-13 21:06:42,792 INFO    HandlerThread:11564 [handler.py:handle_request_defer():170] handle defer: 2
2024-03-13 21:06:42,792 INFO    HandlerThread:11564 [system_monitor.py:finish():190] Stopping system monitor
2024-03-13 21:06:42,792 DEBUG   SystemMonitor:11564 [system_monitor.py:_start():166] Finished system metrics aggregation loop
2024-03-13 21:06:42,799 DEBUG   SystemMonitor:11564 [system_monitor.py:_start():170] Publishing last batch of metrics
2024-03-13 21:06:42,800 INFO    HandlerThread:11564 [interfaces.py:finish():202] Joined cpu monitor
2024-03-13 21:06:42,801 INFO    HandlerThread:11564 [interfaces.py:finish():202] Joined disk monitor
2024-03-13 21:06:42,838 INFO    HandlerThread:11564 [interfaces.py:finish():202] Joined gpu monitor
2024-03-13 21:06:42,838 INFO    HandlerThread:11564 [interfaces.py:finish():202] Joined memory monitor
2024-03-13 21:06:42,839 INFO    HandlerThread:11564 [interfaces.py:finish():202] Joined network monitor
2024-03-13 21:06:42,839 DEBUG   SenderThread:11564 [sender.py:send_request():407] send_request: defer
2024-03-13 21:06:42,840 INFO    SenderThread:11564 [sender.py:send_request_defer():609] handle sender defer: 2
2024-03-13 21:06:42,840 INFO    SenderThread:11564 [sender.py:transition_state():613] send defer: 3
2024-03-13 21:06:42,840 DEBUG   SenderThread:11564 [sender.py:send():380] send: stats
2024-03-13 21:06:42,840 DEBUG   HandlerThread:11564 [handler.py:handle_request():144] handle_request: defer
2024-03-13 21:06:42,840 INFO    HandlerThread:11564 [handler.py:handle_request_defer():170] handle defer: 3
2024-03-13 21:06:42,841 DEBUG   SenderThread:11564 [sender.py:send_request():407] send_request: defer
2024-03-13 21:06:42,841 INFO    SenderThread:11564 [sender.py:send_request_defer():609] handle sender defer: 3
2024-03-13 21:06:42,841 INFO    SenderThread:11564 [sender.py:transition_state():613] send defer: 4
2024-03-13 21:06:42,841 DEBUG   HandlerThread:11564 [handler.py:handle_request():144] handle_request: defer
2024-03-13 21:06:42,841 INFO    HandlerThread:11564 [handler.py:handle_request_defer():170] handle defer: 4
2024-03-13 21:06:42,841 DEBUG   SenderThread:11564 [sender.py:send_request():407] send_request: defer
2024-03-13 21:06:42,841 INFO    SenderThread:11564 [sender.py:send_request_defer():609] handle sender defer: 4
2024-03-13 21:06:42,841 INFO    SenderThread:11564 [sender.py:transition_state():613] send defer: 5
2024-03-13 21:06:42,841 DEBUG   HandlerThread:11564 [handler.py:handle_request():144] handle_request: defer
2024-03-13 21:06:42,842 INFO    HandlerThread:11564 [handler.py:handle_request_defer():170] handle defer: 5
2024-03-13 21:06:42,842 DEBUG   SenderThread:11564 [sender.py:send():380] send: summary
2024-03-13 21:06:42,843 INFO    SenderThread:11564 [sender.py:_save_file():1378] saving file wandb-summary.json with policy end
2024-03-13 21:06:42,843 DEBUG   SenderThread:11564 [sender.py:send_request():407] send_request: defer
2024-03-13 21:06:42,843 INFO    SenderThread:11564 [sender.py:send_request_defer():609] handle sender defer: 5
2024-03-13 21:06:42,843 INFO    SenderThread:11564 [sender.py:transition_state():613] send defer: 6
2024-03-13 21:06:42,844 DEBUG   HandlerThread:11564 [handler.py:handle_request():144] handle_request: defer
2024-03-13 21:06:42,844 INFO    HandlerThread:11564 [handler.py:handle_request_defer():170] handle defer: 6
2024-03-13 21:06:42,844 DEBUG   SenderThread:11564 [sender.py:send_request():407] send_request: defer
2024-03-13 21:06:42,844 INFO    SenderThread:11564 [sender.py:send_request_defer():609] handle sender defer: 6
2024-03-13 21:06:42,844 INFO    SenderThread:11564 [sender.py:transition_state():613] send defer: 7
2024-03-13 21:06:42,844 DEBUG   HandlerThread:11564 [handler.py:handle_request():144] handle_request: status_report
2024-03-13 21:06:42,844 DEBUG   HandlerThread:11564 [handler.py:handle_request():144] handle_request: defer
2024-03-13 21:06:42,844 INFO    HandlerThread:11564 [handler.py:handle_request_defer():170] handle defer: 7
2024-03-13 21:06:42,844 DEBUG   SenderThread:11564 [sender.py:send_request():407] send_request: defer
2024-03-13 21:06:42,844 INFO    SenderThread:11564 [sender.py:send_request_defer():609] handle sender defer: 7
2024-03-13 21:06:43,096 INFO    Thread-12 :11564 [dir_watcher.py:_on_file_modified():288] file/dir modified: E:\自动驾驶\车位检测\parking-space-Identification-in-different-weather-main\wandb\run-20240313_210453-3oq1hjiv\files\wandb-summary.json
2024-03-13 21:06:43,097 INFO    Thread-12 :11564 [dir_watcher.py:_on_file_modified():288] file/dir modified: E:\自动驾驶\车位检测\parking-space-Identification-in-different-weather-main\wandb\run-20240313_210453-3oq1hjiv\files\output.log
2024-03-13 21:06:43,790 DEBUG   HandlerThread:11564 [handler.py:handle_request():144] handle_request: poll_exit
2024-03-13 21:06:44,609 INFO    SenderThread:11564 [sender.py:transition_state():613] send defer: 8
2024-03-13 21:06:44,609 DEBUG   SenderThread:11564 [sender.py:send_request():407] send_request: poll_exit
2024-03-13 21:06:44,609 DEBUG   HandlerThread:11564 [handler.py:handle_request():144] handle_request: defer
2024-03-13 21:06:44,610 INFO    HandlerThread:11564 [handler.py:handle_request_defer():170] handle defer: 8
2024-03-13 21:06:44,610 DEBUG   SenderThread:11564 [sender.py:send_request():407] send_request: defer
2024-03-13 21:06:44,610 INFO    SenderThread:11564 [sender.py:send_request_defer():609] handle sender defer: 8
2024-03-13 21:06:44,610 INFO    SenderThread:11564 [job_builder.py:build():281] Attempting to build job artifact
2024-03-13 21:06:44,611 INFO    SenderThread:11564 [job_builder.py:_get_source_type():404] no source found
2024-03-13 21:06:44,611 INFO    SenderThread:11564 [sender.py:transition_state():613] send defer: 9
2024-03-13 21:06:44,611 DEBUG   HandlerThread:11564 [handler.py:handle_request():144] handle_request: defer
2024-03-13 21:06:44,611 INFO    HandlerThread:11564 [handler.py:handle_request_defer():170] handle defer: 9
2024-03-13 21:06:44,612 DEBUG   SenderThread:11564 [sender.py:send_request():407] send_request: defer
2024-03-13 21:06:44,612 INFO    SenderThread:11564 [sender.py:send_request_defer():609] handle sender defer: 9
2024-03-13 21:06:44,612 INFO    SenderThread:11564 [dir_watcher.py:finish():358] shutting down directory watcher
2024-03-13 21:06:44,798 DEBUG   HandlerThread:11564 [handler.py:handle_request():144] handle_request: poll_exit
2024-03-13 21:06:45,110 INFO    SenderThread:11564 [dir_watcher.py:_on_file_modified():288] file/dir modified: E:\自动驾驶\车位检测\parking-space-Identification-in-different-weather-main\wandb\run-20240313_210453-3oq1hjiv\files\output.log
2024-03-13 21:06:45,112 INFO    SenderThread:11564 [dir_watcher.py:finish():388] scan: E:\自动驾驶\车位检测\parking-space-Identification-in-different-weather-main\wandb\run-20240313_210453-3oq1hjiv\files
2024-03-13 21:06:45,112 INFO    SenderThread:11564 [dir_watcher.py:finish():402] scan save: E:\自动驾驶\车位检测\parking-space-Identification-in-different-weather-main\wandb\run-20240313_210453-3oq1hjiv\files\conda-environment.yaml conda-environment.yaml
2024-03-13 21:06:45,113 INFO    SenderThread:11564 [dir_watcher.py:finish():402] scan save: E:\自动驾驶\车位检测\parking-space-Identification-in-different-weather-main\wandb\run-20240313_210453-3oq1hjiv\files\config.yaml config.yaml
2024-03-13 21:06:45,115 INFO    SenderThread:11564 [dir_watcher.py:finish():402] scan save: E:\自动驾驶\车位检测\parking-space-Identification-in-different-weather-main\wandb\run-20240313_210453-3oq1hjiv\files\output.log output.log
2024-03-13 21:06:45,118 INFO    SenderThread:11564 [dir_watcher.py:finish():402] scan save: E:\自动驾驶\车位检测\parking-space-Identification-in-different-weather-main\wandb\run-20240313_210453-3oq1hjiv\files\requirements.txt requirements.txt
2024-03-13 21:06:45,120 INFO    SenderThread:11564 [dir_watcher.py:finish():402] scan save: E:\自动驾驶\车位检测\parking-space-Identification-in-different-weather-main\wandb\run-20240313_210453-3oq1hjiv\files\wandb-metadata.json wandb-metadata.json
2024-03-13 21:06:45,120 INFO    SenderThread:11564 [dir_watcher.py:finish():402] scan save: E:\自动驾驶\车位检测\parking-space-Identification-in-different-weather-main\wandb\run-20240313_210453-3oq1hjiv\files\wandb-summary.json wandb-summary.json
2024-03-13 21:06:45,122 INFO    SenderThread:11564 [sender.py:transition_state():613] send defer: 10
2024-03-13 21:06:45,122 DEBUG   SenderThread:11564 [sender.py:send_request():407] send_request: poll_exit
2024-03-13 21:06:45,122 DEBUG   HandlerThread:11564 [handler.py:handle_request():144] handle_request: defer
2024-03-13 21:06:45,123 INFO    HandlerThread:11564 [handler.py:handle_request_defer():170] handle defer: 10
2024-03-13 21:06:45,124 DEBUG   SenderThread:11564 [sender.py:send_request():407] send_request: defer
2024-03-13 21:06:45,125 INFO    SenderThread:11564 [sender.py:send_request_defer():609] handle sender defer: 10
2024-03-13 21:06:45,125 INFO    SenderThread:11564 [file_pusher.py:finish():175] shutting down file pusher
2024-03-13 21:06:45,810 DEBUG   HandlerThread:11564 [handler.py:handle_request():144] handle_request: poll_exit
2024-03-13 21:06:45,811 DEBUG   SenderThread:11564 [sender.py:send_request():407] send_request: poll_exit
2024-03-13 21:06:46,814 DEBUG   HandlerThread:11564 [handler.py:handle_request():144] handle_request: poll_exit
2024-03-13 21:06:46,815 DEBUG   SenderThread:11564 [sender.py:send_request():407] send_request: poll_exit
2024-03-13 21:06:47,822 DEBUG   HandlerThread:11564 [handler.py:handle_request():144] handle_request: poll_exit
2024-03-13 21:06:47,823 DEBUG   SenderThread:11564 [sender.py:send_request():407] send_request: poll_exit
2024-03-13 21:06:48,830 DEBUG   HandlerThread:11564 [handler.py:handle_request():144] handle_request: poll_exit
2024-03-13 21:06:48,830 DEBUG   SenderThread:11564 [sender.py:send_request():407] send_request: poll_exit
2024-03-13 21:06:49,838 DEBUG   HandlerThread:11564 [handler.py:handle_request():144] handle_request: poll_exit
2024-03-13 21:06:49,839 DEBUG   SenderThread:11564 [sender.py:send_request():407] send_request: poll_exit
2024-03-13 21:06:50,842 DEBUG   HandlerThread:11564 [handler.py:handle_request():144] handle_request: poll_exit
2024-03-13 21:06:50,843 DEBUG   SenderThread:11564 [sender.py:send_request():407] send_request: poll_exit
2024-03-13 21:06:51,849 DEBUG   HandlerThread:11564 [handler.py:handle_request():144] handle_request: poll_exit
2024-03-13 21:06:51,849 DEBUG   SenderThread:11564 [sender.py:send_request():407] send_request: poll_exit
2024-03-13 21:06:52,855 DEBUG   HandlerThread:11564 [handler.py:handle_request():144] handle_request: poll_exit
2024-03-13 21:06:52,856 DEBUG   HandlerThread:11564 [handler.py:handle_request():144] handle_request: status_report
2024-03-13 21:06:52,856 DEBUG   SenderThread:11564 [sender.py:send_request():407] send_request: poll_exit
2024-03-13 21:06:53,863 DEBUG   HandlerThread:11564 [handler.py:handle_request():144] handle_request: poll_exit
2024-03-13 21:06:53,863 DEBUG   SenderThread:11564 [sender.py:send_request():407] send_request: poll_exit
2024-03-13 21:06:54,866 DEBUG   HandlerThread:11564 [handler.py:handle_request():144] handle_request: poll_exit
2024-03-13 21:06:54,867 DEBUG   SenderThread:11564 [sender.py:send_request():407] send_request: poll_exit
2024-03-13 21:06:55,875 DEBUG   HandlerThread:11564 [handler.py:handle_request():144] handle_request: poll_exit
2024-03-13 21:06:55,875 DEBUG   SenderThread:11564 [sender.py:send_request():407] send_request: poll_exit
2024-03-13 21:06:56,888 DEBUG   HandlerThread:11564 [handler.py:handle_request():144] handle_request: poll_exit
2024-03-13 21:06:56,888 DEBUG   SenderThread:11564 [sender.py:send_request():407] send_request: poll_exit
2024-03-13 21:06:57,902 DEBUG   HandlerThread:11564 [handler.py:handle_request():144] handle_request: status_report
2024-03-13 21:06:57,902 DEBUG   HandlerThread:11564 [handler.py:handle_request():144] handle_request: poll_exit
2024-03-13 21:06:57,903 DEBUG   SenderThread:11564 [sender.py:send_request():407] send_request: poll_exit
2024-03-13 21:06:58,913 DEBUG   HandlerThread:11564 [handler.py:handle_request():144] handle_request: poll_exit
2024-03-13 21:06:58,913 DEBUG   SenderThread:11564 [sender.py:send_request():407] send_request: poll_exit
2024-03-13 21:06:59,927 DEBUG   HandlerThread:11564 [handler.py:handle_request():144] handle_request: poll_exit
2024-03-13 21:06:59,928 DEBUG   SenderThread:11564 [sender.py:send_request():407] send_request: poll_exit
2024-03-13 21:07:00,928 DEBUG   HandlerThread:11564 [handler.py:handle_request():144] handle_request: poll_exit
2024-03-13 21:07:00,929 DEBUG   SenderThread:11564 [sender.py:send_request():407] send_request: poll_exit
2024-03-13 21:07:01,941 DEBUG   HandlerThread:11564 [handler.py:handle_request():144] handle_request: poll_exit
2024-03-13 21:07:01,942 DEBUG   SenderThread:11564 [sender.py:send_request():407] send_request: poll_exit
2024-03-13 21:07:02,953 DEBUG   HandlerThread:11564 [handler.py:handle_request():144] handle_request: status_report
2024-03-13 21:07:02,953 DEBUG   HandlerThread:11564 [handler.py:handle_request():144] handle_request: poll_exit
2024-03-13 21:07:02,954 DEBUG   SenderThread:11564 [sender.py:send_request():407] send_request: poll_exit
2024-03-13 21:07:03,957 DEBUG   HandlerThread:11564 [handler.py:handle_request():144] handle_request: poll_exit
2024-03-13 21:07:03,958 DEBUG   SenderThread:11564 [sender.py:send_request():407] send_request: poll_exit
2024-03-13 21:07:04,959 DEBUG   HandlerThread:11564 [handler.py:handle_request():144] handle_request: poll_exit
2024-03-13 21:07:04,960 DEBUG   SenderThread:11564 [sender.py:send_request():407] send_request: poll_exit
2024-03-13 21:07:05,972 DEBUG   HandlerThread:11564 [handler.py:handle_request():144] handle_request: poll_exit
2024-03-13 21:07:05,973 DEBUG   SenderThread:11564 [sender.py:send_request():407] send_request: poll_exit
2024-03-13 21:07:06,973 DEBUG   HandlerThread:11564 [handler.py:handle_request():144] handle_request: poll_exit
2024-03-13 21:07:06,974 DEBUG   SenderThread:11564 [sender.py:send_request():407] send_request: poll_exit
2024-03-13 21:07:07,148 ERROR   wandb-upload_2:11564 [internal_api.py:upload_file():2556] upload_file exception https://storage.googleapis.com/wandb-production.appspot.com/princeporch/uncategorized/3oq1hjiv/config.yaml?Expires=1710421608&GoogleAccessId=gorilla-files-url-signer-man%40wandb-production.iam.gserviceaccount.com&Signature=sNlmpu%2FIH5JtVJvvk5mIkTrXxesU%2Fi3Y5PNkHvnjJ9D0%2Bcdu5B7DYBhRNE6LgNlYMVrhq7ihjyzI83y0L4rk7YO6MllMl8hmvccZIYucveUhYbu%2BnQ3JE2txEH4IsYiXlXuVSrRh4rs6BFDYEGFdWieR7NsY%2BZRBuLlJdRzwDNhOIUC1nn5TOK%2BvGONJ%2BN9QKf%2FPiw493eR5TC6C6q%2BkD1XsmPhZ08MVPXHsxnAOsMzcmASBtN2vZnyHAXGx4Gyicfy%2BB0Wv6BHSKKzfeuG5IwltveeAgb5SXuVESHXV6Ahgg5vVCmoX8IbNCiP4FULt1MkDe2HtaF6LJGzZarQk8A%3D%3D: HTTPSConnectionPool(host='storage.googleapis.com', port=443): Max retries exceeded with url: /wandb-production.appspot.com/princeporch/uncategorized/3oq1hjiv/config.yaml?Expires=1710421608&GoogleAccessId=gorilla-files-url-signer-man%40wandb-production.iam.gserviceaccount.com&Signature=sNlmpu%2FIH5JtVJvvk5mIkTrXxesU%2Fi3Y5PNkHvnjJ9D0%2Bcdu5B7DYBhRNE6LgNlYMVrhq7ihjyzI83y0L4rk7YO6MllMl8hmvccZIYucveUhYbu%2BnQ3JE2txEH4IsYiXlXuVSrRh4rs6BFDYEGFdWieR7NsY%2BZRBuLlJdRzwDNhOIUC1nn5TOK%2BvGONJ%2BN9QKf%2FPiw493eR5TC6C6q%2BkD1XsmPhZ08MVPXHsxnAOsMzcmASBtN2vZnyHAXGx4Gyicfy%2BB0Wv6BHSKKzfeuG5IwltveeAgb5SXuVESHXV6Ahgg5vVCmoX8IbNCiP4FULt1MkDe2HtaF6LJGzZarQk8A%3D%3D (Caused by NewConnectionError('<urllib3.connection.HTTPSConnection object at 0x000001E233A74A90>: Failed to establish a new connection: [WinError 10061] 由于目标计算机积极拒绝，无法连接。'))
2024-03-13 21:07:07,149 ERROR   wandb-upload_2:11564 [internal_api.py:upload_file():2558] upload_file request headers: {'User-Agent': 'python-requests/2.29.0', 'Accept-Encoding': 'gzip, deflate, br', 'Accept': '*/*', 'Connection': 'keep-alive', 'Content-Length': '456'}
2024-03-13 21:07:07,149 ERROR   wandb-upload_2:11564 [internal_api.py:upload_file():2560] upload_file response body: 
2024-03-13 21:07:07,510 ERROR   wandb-upload_0:11564 [internal_api.py:upload_file():2556] upload_file exception https://storage.googleapis.com/wandb-production.appspot.com/princeporch/uncategorized/3oq1hjiv/wandb-metadata.json?Expires=1710421510&GoogleAccessId=gorilla-files-url-signer-man%40wandb-production.iam.gserviceaccount.com&Signature=eOp1F3K0OOM3nLDkP8XGnJ3vXn9pxmhpqBLHGF70JePq4N7T%2B4hDEXHcmhltlUQ4NQc9xeuf4L9NTUU%2BemKL1XjMPGZBND6%2FSrv8%2FeIjMQZGrjidNIcRFBDVeo8CmuxZxdJ8Gptyw1wtIbncOOpIPzc8V5H7JupruC5U8TClVinntCLXpAqXzilii5v6LTDWYxZOX6GKmUhaJ871cyuuHvd2XejOlPzybq50U7LJHzWK4pdv0BWmuuhQEqsLpnTIkJ8IIeqMvtDgkxzpt5Y%2Fctx%2BBpalC7l25wD67YQWlfLN78ndHS0nNNKhuSR2F6PrWYtKn5tRxqmu3wALLCLFJg%3D%3D: HTTPSConnectionPool(host='storage.googleapis.com', port=443): Max retries exceeded with url: /wandb-production.appspot.com/princeporch/uncategorized/3oq1hjiv/wandb-metadata.json?Expires=1710421510&GoogleAccessId=gorilla-files-url-signer-man%40wandb-production.iam.gserviceaccount.com&Signature=eOp1F3K0OOM3nLDkP8XGnJ3vXn9pxmhpqBLHGF70JePq4N7T%2B4hDEXHcmhltlUQ4NQc9xeuf4L9NTUU%2BemKL1XjMPGZBND6%2FSrv8%2FeIjMQZGrjidNIcRFBDVeo8CmuxZxdJ8Gptyw1wtIbncOOpIPzc8V5H7JupruC5U8TClVinntCLXpAqXzilii5v6LTDWYxZOX6GKmUhaJ871cyuuHvd2XejOlPzybq50U7LJHzWK4pdv0BWmuuhQEqsLpnTIkJ8IIeqMvtDgkxzpt5Y%2Fctx%2BBpalC7l25wD67YQWlfLN78ndHS0nNNKhuSR2F6PrWYtKn5tRxqmu3wALLCLFJg%3D%3D (Caused by NewConnectionError('<urllib3.connection.HTTPSConnection object at 0x000001E2338B1510>: Failed to establish a new connection: [WinError 10061] 由于目标计算机积极拒绝，无法连接。'))
2024-03-13 21:07:07,510 ERROR   wandb-upload_0:11564 [internal_api.py:upload_file():2558] upload_file request headers: {'User-Agent': 'python-requests/2.29.0', 'Accept-Encoding': 'gzip, deflate, br', 'Accept': '*/*', 'Connection': 'keep-alive', 'Content-Length': '1321'}
2024-03-13 21:07:07,510 ERROR   wandb-upload_0:11564 [internal_api.py:upload_file():2560] upload_file response body: 
2024-03-13 21:07:07,769 ERROR   wandb-upload_1:11564 [internal_api.py:upload_file():2556] upload_file exception https://storage.googleapis.com/wandb-production.appspot.com/princeporch/uncategorized/3oq1hjiv/conda-environment.yaml?Expires=1710421608&GoogleAccessId=gorilla-files-url-signer-man%40wandb-production.iam.gserviceaccount.com&Signature=aitRQrHsilg%2FzKEwqkcWmGPUHjos3RP2WMR968fsXTpNrlNjdvUg7u3EXOly2ThKaAWT%2BJf6q236RUHU0hsAXWRXw3NPdGQbCkk6MinR8uqy3roCbvc4hkAxKX6kCk6Al3g8kc%2F1J4Vwi6oxiKk1UySlM5y7CAlZnJ9iYaac394ZdjY8sKoEOzyVV8s9MEeZOViTZhwH4DYHAbiA6YPeMrvfSFHB6p5imiPyiNHIiKuqVQy7TkvO3vFyGkvFw0FFCtqEq5gt3lz3fQHGdQqbavcTcYI8B5xjVKe1ej%2FVkzz82CTW2EpNAWSEDd3HcuoirfZhjhakiBrdxlVDD9fKAA%3D%3D: HTTPSConnectionPool(host='storage.googleapis.com', port=443): Max retries exceeded with url: /wandb-production.appspot.com/princeporch/uncategorized/3oq1hjiv/conda-environment.yaml?Expires=1710421608&GoogleAccessId=gorilla-files-url-signer-man%40wandb-production.iam.gserviceaccount.com&Signature=aitRQrHsilg%2FzKEwqkcWmGPUHjos3RP2WMR968fsXTpNrlNjdvUg7u3EXOly2ThKaAWT%2BJf6q236RUHU0hsAXWRXw3NPdGQbCkk6MinR8uqy3roCbvc4hkAxKX6kCk6Al3g8kc%2F1J4Vwi6oxiKk1UySlM5y7CAlZnJ9iYaac394ZdjY8sKoEOzyVV8s9MEeZOViTZhwH4DYHAbiA6YPeMrvfSFHB6p5imiPyiNHIiKuqVQy7TkvO3vFyGkvFw0FFCtqEq5gt3lz3fQHGdQqbavcTcYI8B5xjVKe1ej%2FVkzz82CTW2EpNAWSEDd3HcuoirfZhjhakiBrdxlVDD9fKAA%3D%3D (Caused by NewConnectionError('<urllib3.connection.HTTPSConnection object at 0x000001E233A747F0>: Failed to establish a new connection: [WinError 10061] 由于目标计算机积极拒绝，无法连接。'))
2024-03-13 21:07:07,770 ERROR   wandb-upload_1:11564 [internal_api.py:upload_file():2558] upload_file request headers: {'User-Agent': 'python-requests/2.29.0', 'Accept-Encoding': 'gzip, deflate, br', 'Accept': '*/*', 'Connection': 'keep-alive', 'Content-Length': '9492'}
2024-03-13 21:07:07,770 ERROR   wandb-upload_1:11564 [internal_api.py:upload_file():2560] upload_file response body: 
2024-03-13 21:07:07,977 DEBUG   HandlerThread:11564 [handler.py:handle_request():144] handle_request: poll_exit
2024-03-13 21:07:07,977 DEBUG   HandlerThread:11564 [handler.py:handle_request():144] handle_request: status_report
2024-03-13 21:07:07,977 DEBUG   SenderThread:11564 [sender.py:send_request():407] send_request: poll_exit
2024-03-13 21:07:08,986 DEBUG   HandlerThread:11564 [handler.py:handle_request():144] handle_request: poll_exit
2024-03-13 21:07:08,987 DEBUG   SenderThread:11564 [sender.py:send_request():407] send_request: poll_exit
2024-03-13 21:07:08,996 ERROR   wandb-upload_4:11564 [internal_api.py:upload_file():2556] upload_file exception https://storage.googleapis.com/wandb-production.appspot.com/princeporch/uncategorized/3oq1hjiv/requirements.txt?Expires=1710421619&GoogleAccessId=gorilla-files-url-signer-man%40wandb-production.iam.gserviceaccount.com&Signature=u7dGtXVPVcgPT24WQ38jd7g74stCo%2BEaLYegyiVpcQGxZY5%2BLl79DLu13dtyPhjRd6V2aCF4W4cfojHZxGaAf3g4vQHLEOaZANXX7gSQKxGydbY39gTZ9qQXpSUf5MfrMmiyjVcumFWW7g22e5NN9iRT4B4jZzqUqQqUL4gaGgkAEKvRiLmI6hOqgpyTzQp32LqLGgS%2BMu1udnQV530MiYc6OSoy6IPRAtNfcaSCIULV2B6caR4N7Nz0o6RS5pHIESO%2FdaClhBjVtz57vDHKzrXg0i6RUVdcL5GXvF13L1PsX%2BjwLBLc6eGgkCwHR8vuVpjMy%2FyvMS6E4nGF2IVyWA%3D%3D: HTTPSConnectionPool(host='storage.googleapis.com', port=443): Max retries exceeded with url: /wandb-production.appspot.com/princeporch/uncategorized/3oq1hjiv/requirements.txt?Expires=1710421619&GoogleAccessId=gorilla-files-url-signer-man%40wandb-production.iam.gserviceaccount.com&Signature=u7dGtXVPVcgPT24WQ38jd7g74stCo%2BEaLYegyiVpcQGxZY5%2BLl79DLu13dtyPhjRd6V2aCF4W4cfojHZxGaAf3g4vQHLEOaZANXX7gSQKxGydbY39gTZ9qQXpSUf5MfrMmiyjVcumFWW7g22e5NN9iRT4B4jZzqUqQqUL4gaGgkAEKvRiLmI6hOqgpyTzQp32LqLGgS%2BMu1udnQV530MiYc6OSoy6IPRAtNfcaSCIULV2B6caR4N7Nz0o6RS5pHIESO%2FdaClhBjVtz57vDHKzrXg0i6RUVdcL5GXvF13L1PsX%2BjwLBLc6eGgkCwHR8vuVpjMy%2FyvMS6E4nGF2IVyWA%3D%3D (Caused by NewConnectionError('<urllib3.connection.HTTPSConnection object at 0x000001E233A77490>: Failed to establish a new connection: [WinError 10061] 由于目标计算机积极拒绝，无法连接。'))
2024-03-13 21:07:08,996 ERROR   wandb-upload_4:11564 [internal_api.py:upload_file():2558] upload_file request headers: {'User-Agent': 'python-requests/2.29.0', 'Accept-Encoding': 'gzip, deflate, br', 'Accept': '*/*', 'Connection': 'keep-alive', 'Content-Length': '3463'}
2024-03-13 21:07:08,996 ERROR   wandb-upload_4:11564 [internal_api.py:upload_file():2560] upload_file response body: 
2024-03-13 21:07:08,997 INFO    wandb-upload_4:11564 [retry.py:__call__():172] Retry attempt failed:
Traceback (most recent call last):
  File "E:\anaconda\lib\site-packages\urllib3\connection.py", line 174, in _new_conn
    conn = connection.create_connection(
  File "E:\anaconda\lib\site-packages\urllib3\util\connection.py", line 95, in create_connection
    raise err
  File "E:\anaconda\lib\site-packages\urllib3\util\connection.py", line 85, in create_connection
    sock.connect(sa)
ConnectionRefusedError: [WinError 10061] 由于目标计算机积极拒绝，无法连接。

During handling of the above exception, another exception occurred:

Traceback (most recent call last):
  File "E:\anaconda\lib\site-packages\urllib3\connectionpool.py", line 714, in urlopen
    httplib_response = self._make_request(
  File "E:\anaconda\lib\site-packages\urllib3\connectionpool.py", line 403, in _make_request
    self._validate_conn(conn)
  File "E:\anaconda\lib\site-packages\urllib3\connectionpool.py", line 1053, in _validate_conn
    conn.connect()
  File "E:\anaconda\lib\site-packages\urllib3\connection.py", line 363, in connect
    self.sock = conn = self._new_conn()
  File "E:\anaconda\lib\site-packages\urllib3\connection.py", line 186, in _new_conn
    raise NewConnectionError(
urllib3.exceptions.NewConnectionError: <urllib3.connection.HTTPSConnection object at 0x000001E233A77490>: Failed to establish a new connection: [WinError 10061] 由于目标计算机积极拒绝，无法连接。

During handling of the above exception, another exception occurred:

Traceback (most recent call last):
  File "E:\anaconda\lib\site-packages\requests\adapters.py", line 487, in send
    resp = conn.urlopen(
  File "E:\anaconda\lib\site-packages\urllib3\connectionpool.py", line 798, in urlopen
    retries = retries.increment(
  File "E:\anaconda\lib\site-packages\urllib3\util\retry.py", line 592, in increment
    raise MaxRetryError(_pool, url, error or ResponseError(cause))
urllib3.exceptions.MaxRetryError: HTTPSConnectionPool(host='storage.googleapis.com', port=443): Max retries exceeded with url: /wandb-production.appspot.com/princeporch/uncategorized/3oq1hjiv/requirements.txt?Expires=1710421619&GoogleAccessId=gorilla-files-url-signer-man%40wandb-production.iam.gserviceaccount.com&Signature=u7dGtXVPVcgPT24WQ38jd7g74stCo%2BEaLYegyiVpcQGxZY5%2BLl79DLu13dtyPhjRd6V2aCF4W4cfojHZxGaAf3g4vQHLEOaZANXX7gSQKxGydbY39gTZ9qQXpSUf5MfrMmiyjVcumFWW7g22e5NN9iRT4B4jZzqUqQqUL4gaGgkAEKvRiLmI6hOqgpyTzQp32LqLGgS%2BMu1udnQV530MiYc6OSoy6IPRAtNfcaSCIULV2B6caR4N7Nz0o6RS5pHIESO%2FdaClhBjVtz57vDHKzrXg0i6RUVdcL5GXvF13L1PsX%2BjwLBLc6eGgkCwHR8vuVpjMy%2FyvMS6E4nGF2IVyWA%3D%3D (Caused by NewConnectionError('<urllib3.connection.HTTPSConnection object at 0x000001E233A77490>: Failed to establish a new connection: [WinError 10061] 由于目标计算机积极拒绝，无法连接。'))

During handling of the above exception, another exception occurred:

Traceback (most recent call last):
  File "E:\anaconda\lib\site-packages\wandb\sdk\internal\internal_api.py", line 2549, in upload_file
    response = self._upload_file_session.put(
  File "E:\anaconda\lib\site-packages\requests\sessions.py", line 647, in put
    return self.request("PUT", url, data=data, **kwargs)
  File "E:\anaconda\lib\site-packages\requests\sessions.py", line 587, in request
    resp = self.send(prep, **send_kwargs)
  File "E:\anaconda\lib\site-packages\requests\sessions.py", line 701, in send
    r = adapter.send(request, **kwargs)
  File "E:\anaconda\lib\site-packages\requests\adapters.py", line 520, in send
    raise ConnectionError(e, request=request)
requests.exceptions.ConnectionError: HTTPSConnectionPool(host='storage.googleapis.com', port=443): Max retries exceeded with url: /wandb-production.appspot.com/princeporch/uncategorized/3oq1hjiv/requirements.txt?Expires=1710421619&GoogleAccessId=gorilla-files-url-signer-man%40wandb-production.iam.gserviceaccount.com&Signature=u7dGtXVPVcgPT24WQ38jd7g74stCo%2BEaLYegyiVpcQGxZY5%2BLl79DLu13dtyPhjRd6V2aCF4W4cfojHZxGaAf3g4vQHLEOaZANXX7gSQKxGydbY39gTZ9qQXpSUf5MfrMmiyjVcumFWW7g22e5NN9iRT4B4jZzqUqQqUL4gaGgkAEKvRiLmI6hOqgpyTzQp32LqLGgS%2BMu1udnQV530MiYc6OSoy6IPRAtNfcaSCIULV2B6caR4N7Nz0o6RS5pHIESO%2FdaClhBjVtz57vDHKzrXg0i6RUVdcL5GXvF13L1PsX%2BjwLBLc6eGgkCwHR8vuVpjMy%2FyvMS6E4nGF2IVyWA%3D%3D (Caused by NewConnectionError('<urllib3.connection.HTTPSConnection object at 0x000001E233A77490>: Failed to establish a new connection: [WinError 10061] 由于目标计算机积极拒绝，无法连接。'))

During handling of the above exception, another exception occurred:

Traceback (most recent call last):
  File "E:\anaconda\lib\site-packages\wandb\sdk\lib\retry.py", line 131, in __call__
    result = self._call_fn(*args, **kwargs)
  File "E:\anaconda\lib\site-packages\wandb\sdk\internal\internal_api.py", line 2580, in upload_file
    raise _e.with_traceback(sys.exc_info()[2])
  File "E:\anaconda\lib\site-packages\wandb\sdk\internal\internal_api.py", line 2549, in upload_file
    response = self._upload_file_session.put(
  File "E:\anaconda\lib\site-packages\requests\sessions.py", line 647, in put
    return self.request("PUT", url, data=data, **kwargs)
  File "E:\anaconda\lib\site-packages\requests\sessions.py", line 587, in request
    resp = self.send(prep, **send_kwargs)
  File "E:\anaconda\lib\site-packages\requests\sessions.py", line 701, in send
    r = adapter.send(request, **kwargs)
  File "E:\anaconda\lib\site-packages\requests\adapters.py", line 520, in send
    raise ConnectionError(e, request=request)
wandb.sdk.lib.retry.TransientError: None
2024-03-13 21:07:09,334 ERROR   wandb-upload_3:11564 [internal_api.py:upload_file():2556] upload_file exception https://storage.googleapis.com/wandb-production.appspot.com/princeporch/uncategorized/3oq1hjiv/output.log?Expires=1710421619&GoogleAccessId=gorilla-files-url-signer-man%40wandb-production.iam.gserviceaccount.com&Signature=vXaEkCUQ85QzfttJFCpAaRP%2Fr8dGB1bKyJgeJqw6r08tu7%2B2%2FTb58PbNh2uWgqPkng%2BC52ZVgUe%2BVS%2BNrNVHnRsfudxdt7cQUb0Txx4bvPEYq8flFJ9GhI4x1YI26DxEViph6Vpr8LJnf65aWMMUUv6dyI%2BFXCdyGlJL2N2DTPdjC5oNPXalc%2BPRbpf0g09CrK4xkEs4oWHqM1yL%2FlqrUt5Z4t7F8Dt%2FNEXXwUT5KBeLTEimUzjiYgwPmrpjGE1qle1ngNd2KH1wot9L2Gpx3xcKcTD401FAwjIk%2FqUr2pTxfyyHJu9lijqHF59onQl%2FZO%2FxpYR8rq9IN%2ByGb3Imog%3D%3D: HTTPSConnectionPool(host='storage.googleapis.com', port=443): Max retries exceeded with url: /wandb-production.appspot.com/princeporch/uncategorized/3oq1hjiv/output.log?Expires=1710421619&GoogleAccessId=gorilla-files-url-signer-man%40wandb-production.iam.gserviceaccount.com&Signature=vXaEkCUQ85QzfttJFCpAaRP%2Fr8dGB1bKyJgeJqw6r08tu7%2B2%2FTb58PbNh2uWgqPkng%2BC52ZVgUe%2BVS%2BNrNVHnRsfudxdt7cQUb0Txx4bvPEYq8flFJ9GhI4x1YI26DxEViph6Vpr8LJnf65aWMMUUv6dyI%2BFXCdyGlJL2N2DTPdjC5oNPXalc%2BPRbpf0g09CrK4xkEs4oWHqM1yL%2FlqrUt5Z4t7F8Dt%2FNEXXwUT5KBeLTEimUzjiYgwPmrpjGE1qle1ngNd2KH1wot9L2Gpx3xcKcTD401FAwjIk%2FqUr2pTxfyyHJu9lijqHF59onQl%2FZO%2FxpYR8rq9IN%2ByGb3Imog%3D%3D (Caused by NewConnectionError('<urllib3.connection.HTTPSConnection object at 0x000001E2338B29E0>: Failed to establish a new connection: [WinError 10061] 由于目标计算机积极拒绝，无法连接。'))
2024-03-13 21:07:09,334 ERROR   wandb-upload_5:11564 [internal_api.py:upload_file():2556] upload_file exception https://storage.googleapis.com/wandb-production.appspot.com/princeporch/uncategorized/3oq1hjiv/wandb-summary.json?Expires=1710421619&GoogleAccessId=gorilla-files-url-signer-man%40wandb-production.iam.gserviceaccount.com&Signature=PSmEYJju6wiwsS%2BCP4TPAyMXoCRCkZH3wzTlB%2FNxzsOXGTGYQ5QQU8I5IoTKNuPIxBqzdVXEa%2BrfaEnkfknhU6dEJifKU%2F08YafAvOZCLyed0VZJ9ASrGfb%2BDarR5FyKREfA7PXy7pqX7bxuEuu5Qwkn26ZJjd4fLt4d1Ni1R%2Fm63sh2Xk6vNcot0Yv6ixC1nJekAZ5k88d7gFfaOHHvD9kVEQGfvNNNiXo%2FnhI2xbV%2FwyQmBnkW%2Fo%2BlL2ml0PTbvO57lq9r%2F9yPdlKM%2BmMLOGvYF%2F0v5rA3fwdzpsShlMzEFugGIJDIHiid27UMWkVZrFn7%2BKJoSB4Us2lh3lLBTQ%3D%3D: HTTPSConnectionPool(host='storage.googleapis.com', port=443): Max retries exceeded with url: /wandb-production.appspot.com/princeporch/uncategorized/3oq1hjiv/wandb-summary.json?Expires=1710421619&GoogleAccessId=gorilla-files-url-signer-man%40wandb-production.iam.gserviceaccount.com&Signature=PSmEYJju6wiwsS%2BCP4TPAyMXoCRCkZH3wzTlB%2FNxzsOXGTGYQ5QQU8I5IoTKNuPIxBqzdVXEa%2BrfaEnkfknhU6dEJifKU%2F08YafAvOZCLyed0VZJ9ASrGfb%2BDarR5FyKREfA7PXy7pqX7bxuEuu5Qwkn26ZJjd4fLt4d1Ni1R%2Fm63sh2Xk6vNcot0Yv6ixC1nJekAZ5k88d7gFfaOHHvD9kVEQGfvNNNiXo%2FnhI2xbV%2FwyQmBnkW%2Fo%2BlL2ml0PTbvO57lq9r%2F9yPdlKM%2BmMLOGvYF%2F0v5rA3fwdzpsShlMzEFugGIJDIHiid27UMWkVZrFn7%2BKJoSB4Us2lh3lLBTQ%3D%3D (Caused by NewConnectionError('<urllib3.connection.HTTPSConnection object at 0x000001E233A76D10>: Failed to establish a new connection: [WinError 10061] 由于目标计算机积极拒绝，无法连接。'))
2024-03-13 21:07:09,334 ERROR   wandb-upload_3:11564 [internal_api.py:upload_file():2558] upload_file request headers: {'User-Agent': 'python-requests/2.29.0', 'Accept-Encoding': 'gzip, deflate, br', 'Accept': '*/*', 'Connection': 'keep-alive', 'Content-Length': '1442'}
2024-03-13 21:07:09,334 ERROR   wandb-upload_5:11564 [internal_api.py:upload_file():2558] upload_file request headers: {'User-Agent': 'python-requests/2.29.0', 'Accept-Encoding': 'gzip, deflate, br', 'Accept': '*/*', 'Connection': 'keep-alive', 'Content-Length': '210'}
2024-03-13 21:07:09,334 ERROR   wandb-upload_3:11564 [internal_api.py:upload_file():2560] upload_file response body: 
2024-03-13 21:07:09,334 ERROR   wandb-upload_5:11564 [internal_api.py:upload_file():2560] upload_file response body: 
2024-03-13 21:07:09,334 INFO    wandb-upload_3:11564 [retry.py:__call__():172] Retry attempt failed:
Traceback (most recent call last):
  File "E:\anaconda\lib\site-packages\urllib3\connection.py", line 174, in _new_conn
    conn = connection.create_connection(
  File "E:\anaconda\lib\site-packages\urllib3\util\connection.py", line 95, in create_connection
    raise err
  File "E:\anaconda\lib\site-packages\urllib3\util\connection.py", line 85, in create_connection
    sock.connect(sa)
ConnectionRefusedError: [WinError 10061] 由于目标计算机积极拒绝，无法连接。

During handling of the above exception, another exception occurred:

Traceback (most recent call last):
  File "E:\anaconda\lib\site-packages\urllib3\connectionpool.py", line 714, in urlopen
    httplib_response = self._make_request(
  File "E:\anaconda\lib\site-packages\urllib3\connectionpool.py", line 403, in _make_request
    self._validate_conn(conn)
  File "E:\anaconda\lib\site-packages\urllib3\connectionpool.py", line 1053, in _validate_conn
    conn.connect()
  File "E:\anaconda\lib\site-packages\urllib3\connection.py", line 363, in connect
    self.sock = conn = self._new_conn()
  File "E:\anaconda\lib\site-packages\urllib3\connection.py", line 186, in _new_conn
    raise NewConnectionError(
urllib3.exceptions.NewConnectionError: <urllib3.connection.HTTPSConnection object at 0x000001E2338B29E0>: Failed to establish a new connection: [WinError 10061] 由于目标计算机积极拒绝，无法连接。

During handling of the above exception, another exception occurred:

Traceback (most recent call last):
  File "E:\anaconda\lib\site-packages\requests\adapters.py", line 487, in send
    resp = conn.urlopen(
  File "E:\anaconda\lib\site-packages\urllib3\connectionpool.py", line 798, in urlopen
    retries = retries.increment(
  File "E:\anaconda\lib\site-packages\urllib3\util\retry.py", line 592, in increment
    raise MaxRetryError(_pool, url, error or ResponseError(cause))
urllib3.exceptions.MaxRetryError: HTTPSConnectionPool(host='storage.googleapis.com', port=443): Max retries exceeded with url: /wandb-production.appspot.com/princeporch/uncategorized/3oq1hjiv/output.log?Expires=1710421619&GoogleAccessId=gorilla-files-url-signer-man%40wandb-production.iam.gserviceaccount.com&Signature=vXaEkCUQ85QzfttJFCpAaRP%2Fr8dGB1bKyJgeJqw6r08tu7%2B2%2FTb58PbNh2uWgqPkng%2BC52ZVgUe%2BVS%2BNrNVHnRsfudxdt7cQUb0Txx4bvPEYq8flFJ9GhI4x1YI26DxEViph6Vpr8LJnf65aWMMUUv6dyI%2BFXCdyGlJL2N2DTPdjC5oNPXalc%2BPRbpf0g09CrK4xkEs4oWHqM1yL%2FlqrUt5Z4t7F8Dt%2FNEXXwUT5KBeLTEimUzjiYgwPmrpjGE1qle1ngNd2KH1wot9L2Gpx3xcKcTD401FAwjIk%2FqUr2pTxfyyHJu9lijqHF59onQl%2FZO%2FxpYR8rq9IN%2ByGb3Imog%3D%3D (Caused by NewConnectionError('<urllib3.connection.HTTPSConnection object at 0x000001E2338B29E0>: Failed to establish a new connection: [WinError 10061] 由于目标计算机积极拒绝，无法连接。'))

During handling of the above exception, another exception occurred:

Traceback (most recent call last):
  File "E:\anaconda\lib\site-packages\wandb\sdk\internal\internal_api.py", line 2549, in upload_file
    response = self._upload_file_session.put(
  File "E:\anaconda\lib\site-packages\requests\sessions.py", line 647, in put
    return self.request("PUT", url, data=data, **kwargs)
  File "E:\anaconda\lib\site-packages\requests\sessions.py", line 587, in request
    resp = self.send(prep, **send_kwargs)
  File "E:\anaconda\lib\site-packages\requests\sessions.py", line 701, in send
    r = adapter.send(request, **kwargs)
  File "E:\anaconda\lib\site-packages\requests\adapters.py", line 520, in send
    raise ConnectionError(e, request=request)
requests.exceptions.ConnectionError: HTTPSConnectionPool(host='storage.googleapis.com', port=443): Max retries exceeded with url: /wandb-production.appspot.com/princeporch/uncategorized/3oq1hjiv/output.log?Expires=1710421619&GoogleAccessId=gorilla-files-url-signer-man%40wandb-production.iam.gserviceaccount.com&Signature=vXaEkCUQ85QzfttJFCpAaRP%2Fr8dGB1bKyJgeJqw6r08tu7%2B2%2FTb58PbNh2uWgqPkng%2BC52ZVgUe%2BVS%2BNrNVHnRsfudxdt7cQUb0Txx4bvPEYq8flFJ9GhI4x1YI26DxEViph6Vpr8LJnf65aWMMUUv6dyI%2BFXCdyGlJL2N2DTPdjC5oNPXalc%2BPRbpf0g09CrK4xkEs4oWHqM1yL%2FlqrUt5Z4t7F8Dt%2FNEXXwUT5KBeLTEimUzjiYgwPmrpjGE1qle1ngNd2KH1wot9L2Gpx3xcKcTD401FAwjIk%2FqUr2pTxfyyHJu9lijqHF59onQl%2FZO%2FxpYR8rq9IN%2ByGb3Imog%3D%3D (Caused by NewConnectionError('<urllib3.connection.HTTPSConnection object at 0x000001E2338B29E0>: Failed to establish a new connection: [WinError 10061] 由于目标计算机积极拒绝，无法连接。'))

During handling of the above exception, another exception occurred:

Traceback (most recent call last):
  File "E:\anaconda\lib\site-packages\wandb\sdk\lib\retry.py", line 131, in __call__
    result = self._call_fn(*args, **kwargs)
  File "E:\anaconda\lib\site-packages\wandb\sdk\internal\internal_api.py", line 2580, in upload_file
    raise _e.with_traceback(sys.exc_info()[2])
  File "E:\anaconda\lib\site-packages\wandb\sdk\internal\internal_api.py", line 2549, in upload_file
    response = self._upload_file_session.put(
  File "E:\anaconda\lib\site-packages\requests\sessions.py", line 647, in put
    return self.request("PUT", url, data=data, **kwargs)
  File "E:\anaconda\lib\site-packages\requests\sessions.py", line 587, in request
    resp = self.send(prep, **send_kwargs)
  File "E:\anaconda\lib\site-packages\requests\sessions.py", line 701, in send
    r = adapter.send(request, **kwargs)
  File "E:\anaconda\lib\site-packages\requests\adapters.py", line 520, in send
    raise ConnectionError(e, request=request)
wandb.sdk.lib.retry.TransientError: None
2024-03-13 21:07:09,334 INFO    wandb-upload_5:11564 [retry.py:__call__():172] Retry attempt failed:
Traceback (most recent call last):
  File "E:\anaconda\lib\site-packages\urllib3\connection.py", line 174, in _new_conn
    conn = connection.create_connection(
  File "E:\anaconda\lib\site-packages\urllib3\util\connection.py", line 95, in create_connection
    raise err
  File "E:\anaconda\lib\site-packages\urllib3\util\connection.py", line 85, in create_connection
    sock.connect(sa)
ConnectionRefusedError: [WinError 10061] 由于目标计算机积极拒绝，无法连接。

During handling of the above exception, another exception occurred:

Traceback (most recent call last):
  File "E:\anaconda\lib\site-packages\urllib3\connectionpool.py", line 714, in urlopen
    httplib_response = self._make_request(
  File "E:\anaconda\lib\site-packages\urllib3\connectionpool.py", line 403, in _make_request
    self._validate_conn(conn)
  File "E:\anaconda\lib\site-packages\urllib3\connectionpool.py", line 1053, in _validate_conn
    conn.connect()
  File "E:\anaconda\lib\site-packages\urllib3\connection.py", line 363, in connect
    self.sock = conn = self._new_conn()
  File "E:\anaconda\lib\site-packages\urllib3\connection.py", line 186, in _new_conn
    raise NewConnectionError(
urllib3.exceptions.NewConnectionError: <urllib3.connection.HTTPSConnection object at 0x000001E233A76D10>: Failed to establish a new connection: [WinError 10061] 由于目标计算机积极拒绝，无法连接。

During handling of the above exception, another exception occurred:

Traceback (most recent call last):
  File "E:\anaconda\lib\site-packages\requests\adapters.py", line 487, in send
    resp = conn.urlopen(
  File "E:\anaconda\lib\site-packages\urllib3\connectionpool.py", line 798, in urlopen
    retries = retries.increment(
  File "E:\anaconda\lib\site-packages\urllib3\util\retry.py", line 592, in increment
    raise MaxRetryError(_pool, url, error or ResponseError(cause))
urllib3.exceptions.MaxRetryError: HTTPSConnectionPool(host='storage.googleapis.com', port=443): Max retries exceeded with url: /wandb-production.appspot.com/princeporch/uncategorized/3oq1hjiv/wandb-summary.json?Expires=1710421619&GoogleAccessId=gorilla-files-url-signer-man%40wandb-production.iam.gserviceaccount.com&Signature=PSmEYJju6wiwsS%2BCP4TPAyMXoCRCkZH3wzTlB%2FNxzsOXGTGYQ5QQU8I5IoTKNuPIxBqzdVXEa%2BrfaEnkfknhU6dEJifKU%2F08YafAvOZCLyed0VZJ9ASrGfb%2BDarR5FyKREfA7PXy7pqX7bxuEuu5Qwkn26ZJjd4fLt4d1Ni1R%2Fm63sh2Xk6vNcot0Yv6ixC1nJekAZ5k88d7gFfaOHHvD9kVEQGfvNNNiXo%2FnhI2xbV%2FwyQmBnkW%2Fo%2BlL2ml0PTbvO57lq9r%2F9yPdlKM%2BmMLOGvYF%2F0v5rA3fwdzpsShlMzEFugGIJDIHiid27UMWkVZrFn7%2BKJoSB4Us2lh3lLBTQ%3D%3D (Caused by NewConnectionError('<urllib3.connection.HTTPSConnection object at 0x000001E233A76D10>: Failed to establish a new connection: [WinError 10061] 由于目标计算机积极拒绝，无法连接。'))

During handling of the above exception, another exception occurred:

Traceback (most recent call last):
  File "E:\anaconda\lib\site-packages\wandb\sdk\internal\internal_api.py", line 2549, in upload_file
    response = self._upload_file_session.put(
  File "E:\anaconda\lib\site-packages\requests\sessions.py", line 647, in put
    return self.request("PUT", url, data=data, **kwargs)
  File "E:\anaconda\lib\site-packages\requests\sessions.py", line 587, in request
    resp = self.send(prep, **send_kwargs)
  File "E:\anaconda\lib\site-packages\requests\sessions.py", line 701, in send
    r = adapter.send(request, **kwargs)
  File "E:\anaconda\lib\site-packages\requests\adapters.py", line 520, in send
    raise ConnectionError(e, request=request)
requests.exceptions.ConnectionError: HTTPSConnectionPool(host='storage.googleapis.com', port=443): Max retries exceeded with url: /wandb-production.appspot.com/princeporch/uncategorized/3oq1hjiv/wandb-summary.json?Expires=1710421619&GoogleAccessId=gorilla-files-url-signer-man%40wandb-production.iam.gserviceaccount.com&Signature=PSmEYJju6wiwsS%2BCP4TPAyMXoCRCkZH3wzTlB%2FNxzsOXGTGYQ5QQU8I5IoTKNuPIxBqzdVXEa%2BrfaEnkfknhU6dEJifKU%2F08YafAvOZCLyed0VZJ9ASrGfb%2BDarR5FyKREfA7PXy7pqX7bxuEuu5Qwkn26ZJjd4fLt4d1Ni1R%2Fm63sh2Xk6vNcot0Yv6ixC1nJekAZ5k88d7gFfaOHHvD9kVEQGfvNNNiXo%2FnhI2xbV%2FwyQmBnkW%2Fo%2BlL2ml0PTbvO57lq9r%2F9yPdlKM%2BmMLOGvYF%2F0v5rA3fwdzpsShlMzEFugGIJDIHiid27UMWkVZrFn7%2BKJoSB4Us2lh3lLBTQ%3D%3D (Caused by NewConnectionError('<urllib3.connection.HTTPSConnection object at 0x000001E233A76D10>: Failed to establish a new connection: [WinError 10061] 由于目标计算机积极拒绝，无法连接。'))

During handling of the above exception, another exception occurred:

Traceback (most recent call last):
  File "E:\anaconda\lib\site-packages\wandb\sdk\lib\retry.py", line 131, in __call__
    result = self._call_fn(*args, **kwargs)
  File "E:\anaconda\lib\site-packages\wandb\sdk\internal\internal_api.py", line 2580, in upload_file
    raise _e.with_traceback(sys.exc_info()[2])
  File "E:\anaconda\lib\site-packages\wandb\sdk\internal\internal_api.py", line 2549, in upload_file
    response = self._upload_file_session.put(
  File "E:\anaconda\lib\site-packages\requests\sessions.py", line 647, in put
    return self.request("PUT", url, data=data, **kwargs)
  File "E:\anaconda\lib\site-packages\requests\sessions.py", line 587, in request
    resp = self.send(prep, **send_kwargs)
  File "E:\anaconda\lib\site-packages\requests\sessions.py", line 701, in send
    r = adapter.send(request, **kwargs)
  File "E:\anaconda\lib\site-packages\requests\adapters.py", line 520, in send
    raise ConnectionError(e, request=request)
wandb.sdk.lib.retry.TransientError: None
2024-03-13 21:07:09,990 DEBUG   HandlerThread:11564 [handler.py:handle_request():144] handle_request: poll_exit
2024-03-13 21:07:09,991 DEBUG   SenderThread:11564 [sender.py:send_request():407] send_request: poll_exit
2024-03-13 21:07:11,005 DEBUG   HandlerThread:11564 [handler.py:handle_request():144] handle_request: poll_exit
2024-03-13 21:07:11,005 DEBUG   SenderThread:11564 [sender.py:send_request():407] send_request: poll_exit
2024-03-13 21:07:12,007 DEBUG   HandlerThread:11564 [handler.py:handle_request():144] handle_request: poll_exit
2024-03-13 21:07:12,008 DEBUG   SenderThread:11564 [sender.py:send_request():407] send_request: poll_exit
2024-03-13 21:07:13,022 DEBUG   HandlerThread:11564 [handler.py:handle_request():144] handle_request: poll_exit
2024-03-13 21:07:13,022 DEBUG   HandlerThread:11564 [handler.py:handle_request():144] handle_request: status_report
2024-03-13 21:07:13,022 DEBUG   SenderThread:11564 [sender.py:send_request():407] send_request: poll_exit
2024-03-13 21:07:14,024 DEBUG   HandlerThread:11564 [handler.py:handle_request():144] handle_request: poll_exit
2024-03-13 21:07:14,024 DEBUG   SenderThread:11564 [sender.py:send_request():407] send_request: poll_exit
2024-03-13 21:07:15,037 DEBUG   HandlerThread:11564 [handler.py:handle_request():144] handle_request: poll_exit
2024-03-13 21:07:15,037 DEBUG   SenderThread:11564 [sender.py:send_request():407] send_request: poll_exit
2024-03-13 21:07:16,050 DEBUG   HandlerThread:11564 [handler.py:handle_request():144] handle_request: poll_exit
2024-03-13 21:07:16,051 DEBUG   SenderThread:11564 [sender.py:send_request():407] send_request: poll_exit
2024-03-13 21:07:17,066 DEBUG   HandlerThread:11564 [handler.py:handle_request():144] handle_request: poll_exit
2024-03-13 21:07:17,067 DEBUG   SenderThread:11564 [sender.py:send_request():407] send_request: poll_exit
2024-03-13 21:07:18,067 DEBUG   HandlerThread:11564 [handler.py:handle_request():144] handle_request: poll_exit
2024-03-13 21:07:18,069 DEBUG   HandlerThread:11564 [handler.py:handle_request():144] handle_request: status_report
2024-03-13 21:07:18,069 DEBUG   SenderThread:11564 [sender.py:send_request():407] send_request: poll_exit
2024-03-13 21:07:19,082 DEBUG   HandlerThread:11564 [handler.py:handle_request():144] handle_request: poll_exit
2024-03-13 21:07:19,082 DEBUG   SenderThread:11564 [sender.py:send_request():407] send_request: poll_exit
2024-03-13 21:07:20,096 DEBUG   HandlerThread:11564 [handler.py:handle_request():144] handle_request: poll_exit
2024-03-13 21:07:20,096 DEBUG   SenderThread:11564 [sender.py:send_request():407] send_request: poll_exit
2024-03-13 21:07:20,480 ERROR   wandb-upload_2:11564 [internal_api.py:upload_file():2556] upload_file exception https://storage.googleapis.com/wandb-production.appspot.com/princeporch/uncategorized/3oq1hjiv/config.yaml?Expires=1710421608&GoogleAccessId=gorilla-files-url-signer-man%40wandb-production.iam.gserviceaccount.com&Signature=sNlmpu%2FIH5JtVJvvk5mIkTrXxesU%2Fi3Y5PNkHvnjJ9D0%2Bcdu5B7DYBhRNE6LgNlYMVrhq7ihjyzI83y0L4rk7YO6MllMl8hmvccZIYucveUhYbu%2BnQ3JE2txEH4IsYiXlXuVSrRh4rs6BFDYEGFdWieR7NsY%2BZRBuLlJdRzwDNhOIUC1nn5TOK%2BvGONJ%2BN9QKf%2FPiw493eR5TC6C6q%2BkD1XsmPhZ08MVPXHsxnAOsMzcmASBtN2vZnyHAXGx4Gyicfy%2BB0Wv6BHSKKzfeuG5IwltveeAgb5SXuVESHXV6Ahgg5vVCmoX8IbNCiP4FULt1MkDe2HtaF6LJGzZarQk8A%3D%3D: HTTPSConnectionPool(host='storage.googleapis.com', port=443): Max retries exceeded with url: /wandb-production.appspot.com/princeporch/uncategorized/3oq1hjiv/config.yaml?Expires=1710421608&GoogleAccessId=gorilla-files-url-signer-man%40wandb-production.iam.gserviceaccount.com&Signature=sNlmpu%2FIH5JtVJvvk5mIkTrXxesU%2Fi3Y5PNkHvnjJ9D0%2Bcdu5B7DYBhRNE6LgNlYMVrhq7ihjyzI83y0L4rk7YO6MllMl8hmvccZIYucveUhYbu%2BnQ3JE2txEH4IsYiXlXuVSrRh4rs6BFDYEGFdWieR7NsY%2BZRBuLlJdRzwDNhOIUC1nn5TOK%2BvGONJ%2BN9QKf%2FPiw493eR5TC6C6q%2BkD1XsmPhZ08MVPXHsxnAOsMzcmASBtN2vZnyHAXGx4Gyicfy%2BB0Wv6BHSKKzfeuG5IwltveeAgb5SXuVESHXV6Ahgg5vVCmoX8IbNCiP4FULt1MkDe2HtaF6LJGzZarQk8A%3D%3D (Caused by NewConnectionError('<urllib3.connection.HTTPSConnection object at 0x000001E233A74880>: Failed to establish a new connection: [WinError 10061] 由于目标计算机积极拒绝，无法连接。'))
2024-03-13 21:07:20,480 ERROR   wandb-upload_2:11564 [internal_api.py:upload_file():2558] upload_file request headers: {'User-Agent': 'python-requests/2.29.0', 'Accept-Encoding': 'gzip, deflate, br', 'Accept': '*/*', 'Connection': 'keep-alive', 'Content-Length': '456'}
2024-03-13 21:07:20,480 ERROR   wandb-upload_2:11564 [internal_api.py:upload_file():2560] upload_file response body: 
2024-03-13 21:07:21,111 DEBUG   HandlerThread:11564 [handler.py:handle_request():144] handle_request: poll_exit
2024-03-13 21:07:21,111 DEBUG   SenderThread:11564 [sender.py:send_request():407] send_request: poll_exit
2024-03-13 21:07:21,489 ERROR   wandb-upload_1:11564 [internal_api.py:upload_file():2556] upload_file exception https://storage.googleapis.com/wandb-production.appspot.com/princeporch/uncategorized/3oq1hjiv/conda-environment.yaml?Expires=1710421608&GoogleAccessId=gorilla-files-url-signer-man%40wandb-production.iam.gserviceaccount.com&Signature=aitRQrHsilg%2FzKEwqkcWmGPUHjos3RP2WMR968fsXTpNrlNjdvUg7u3EXOly2ThKaAWT%2BJf6q236RUHU0hsAXWRXw3NPdGQbCkk6MinR8uqy3roCbvc4hkAxKX6kCk6Al3g8kc%2F1J4Vwi6oxiKk1UySlM5y7CAlZnJ9iYaac394ZdjY8sKoEOzyVV8s9MEeZOViTZhwH4DYHAbiA6YPeMrvfSFHB6p5imiPyiNHIiKuqVQy7TkvO3vFyGkvFw0FFCtqEq5gt3lz3fQHGdQqbavcTcYI8B5xjVKe1ej%2FVkzz82CTW2EpNAWSEDd3HcuoirfZhjhakiBrdxlVDD9fKAA%3D%3D: HTTPSConnectionPool(host='storage.googleapis.com', port=443): Max retries exceeded with url: /wandb-production.appspot.com/princeporch/uncategorized/3oq1hjiv/conda-environment.yaml?Expires=1710421608&GoogleAccessId=gorilla-files-url-signer-man%40wandb-production.iam.gserviceaccount.com&Signature=aitRQrHsilg%2FzKEwqkcWmGPUHjos3RP2WMR968fsXTpNrlNjdvUg7u3EXOly2ThKaAWT%2BJf6q236RUHU0hsAXWRXw3NPdGQbCkk6MinR8uqy3roCbvc4hkAxKX6kCk6Al3g8kc%2F1J4Vwi6oxiKk1UySlM5y7CAlZnJ9iYaac394ZdjY8sKoEOzyVV8s9MEeZOViTZhwH4DYHAbiA6YPeMrvfSFHB6p5imiPyiNHIiKuqVQy7TkvO3vFyGkvFw0FFCtqEq5gt3lz3fQHGdQqbavcTcYI8B5xjVKe1ej%2FVkzz82CTW2EpNAWSEDd3HcuoirfZhjhakiBrdxlVDD9fKAA%3D%3D (Caused by NewConnectionError('<urllib3.connection.HTTPSConnection object at 0x000001E233A77550>: Failed to establish a new connection: [WinError 10061] 由于目标计算机积极拒绝，无法连接。'))
2024-03-13 21:07:21,489 ERROR   wandb-upload_1:11564 [internal_api.py:upload_file():2558] upload_file request headers: {'User-Agent': 'python-requests/2.29.0', 'Accept-Encoding': 'gzip, deflate, br', 'Accept': '*/*', 'Connection': 'keep-alive', 'Content-Length': '9492'}
2024-03-13 21:07:21,489 ERROR   wandb-upload_1:11564 [internal_api.py:upload_file():2560] upload_file response body: 
2024-03-13 21:07:22,117 DEBUG   HandlerThread:11564 [handler.py:handle_request():144] handle_request: poll_exit
2024-03-13 21:07:22,118 DEBUG   SenderThread:11564 [sender.py:send_request():407] send_request: poll_exit
2024-03-13 21:07:22,713 ERROR   wandb-upload_3:11564 [internal_api.py:upload_file():2556] upload_file exception https://storage.googleapis.com/wandb-production.appspot.com/princeporch/uncategorized/3oq1hjiv/output.log?Expires=1710421619&GoogleAccessId=gorilla-files-url-signer-man%40wandb-production.iam.gserviceaccount.com&Signature=vXaEkCUQ85QzfttJFCpAaRP%2Fr8dGB1bKyJgeJqw6r08tu7%2B2%2FTb58PbNh2uWgqPkng%2BC52ZVgUe%2BVS%2BNrNVHnRsfudxdt7cQUb0Txx4bvPEYq8flFJ9GhI4x1YI26DxEViph6Vpr8LJnf65aWMMUUv6dyI%2BFXCdyGlJL2N2DTPdjC5oNPXalc%2BPRbpf0g09CrK4xkEs4oWHqM1yL%2FlqrUt5Z4t7F8Dt%2FNEXXwUT5KBeLTEimUzjiYgwPmrpjGE1qle1ngNd2KH1wot9L2Gpx3xcKcTD401FAwjIk%2FqUr2pTxfyyHJu9lijqHF59onQl%2FZO%2FxpYR8rq9IN%2ByGb3Imog%3D%3D: HTTPSConnectionPool(host='storage.googleapis.com', port=443): Max retries exceeded with url: /wandb-production.appspot.com/princeporch/uncategorized/3oq1hjiv/output.log?Expires=1710421619&GoogleAccessId=gorilla-files-url-signer-man%40wandb-production.iam.gserviceaccount.com&Signature=vXaEkCUQ85QzfttJFCpAaRP%2Fr8dGB1bKyJgeJqw6r08tu7%2B2%2FTb58PbNh2uWgqPkng%2BC52ZVgUe%2BVS%2BNrNVHnRsfudxdt7cQUb0Txx4bvPEYq8flFJ9GhI4x1YI26DxEViph6Vpr8LJnf65aWMMUUv6dyI%2BFXCdyGlJL2N2DTPdjC5oNPXalc%2BPRbpf0g09CrK4xkEs4oWHqM1yL%2FlqrUt5Z4t7F8Dt%2FNEXXwUT5KBeLTEimUzjiYgwPmrpjGE1qle1ngNd2KH1wot9L2Gpx3xcKcTD401FAwjIk%2FqUr2pTxfyyHJu9lijqHF59onQl%2FZO%2FxpYR8rq9IN%2ByGb3Imog%3D%3D (Caused by NewConnectionError('<urllib3.connection.HTTPSConnection object at 0x000001E2311D80A0>: Failed to establish a new connection: [WinError 10061] 由于目标计算机积极拒绝，无法连接。'))
2024-03-13 21:07:22,714 ERROR   wandb-upload_4:11564 [internal_api.py:upload_file():2556] upload_file exception https://storage.googleapis.com/wandb-production.appspot.com/princeporch/uncategorized/3oq1hjiv/requirements.txt?Expires=1710421619&GoogleAccessId=gorilla-files-url-signer-man%40wandb-production.iam.gserviceaccount.com&Signature=u7dGtXVPVcgPT24WQ38jd7g74stCo%2BEaLYegyiVpcQGxZY5%2BLl79DLu13dtyPhjRd6V2aCF4W4cfojHZxGaAf3g4vQHLEOaZANXX7gSQKxGydbY39gTZ9qQXpSUf5MfrMmiyjVcumFWW7g22e5NN9iRT4B4jZzqUqQqUL4gaGgkAEKvRiLmI6hOqgpyTzQp32LqLGgS%2BMu1udnQV530MiYc6OSoy6IPRAtNfcaSCIULV2B6caR4N7Nz0o6RS5pHIESO%2FdaClhBjVtz57vDHKzrXg0i6RUVdcL5GXvF13L1PsX%2BjwLBLc6eGgkCwHR8vuVpjMy%2FyvMS6E4nGF2IVyWA%3D%3D: HTTPSConnectionPool(host='storage.googleapis.com', port=443): Max retries exceeded with url: /wandb-production.appspot.com/princeporch/uncategorized/3oq1hjiv/requirements.txt?Expires=1710421619&GoogleAccessId=gorilla-files-url-signer-man%40wandb-production.iam.gserviceaccount.com&Signature=u7dGtXVPVcgPT24WQ38jd7g74stCo%2BEaLYegyiVpcQGxZY5%2BLl79DLu13dtyPhjRd6V2aCF4W4cfojHZxGaAf3g4vQHLEOaZANXX7gSQKxGydbY39gTZ9qQXpSUf5MfrMmiyjVcumFWW7g22e5NN9iRT4B4jZzqUqQqUL4gaGgkAEKvRiLmI6hOqgpyTzQp32LqLGgS%2BMu1udnQV530MiYc6OSoy6IPRAtNfcaSCIULV2B6caR4N7Nz0o6RS5pHIESO%2FdaClhBjVtz57vDHKzrXg0i6RUVdcL5GXvF13L1PsX%2BjwLBLc6eGgkCwHR8vuVpjMy%2FyvMS6E4nGF2IVyWA%3D%3D (Caused by NewConnectionError('<urllib3.connection.HTTPSConnection object at 0x000001E233A750F0>: Failed to establish a new connection: [WinError 10061] 由于目标计算机积极拒绝，无法连接。'))
2024-03-13 21:07:22,714 ERROR   wandb-upload_3:11564 [internal_api.py:upload_file():2558] upload_file request headers: {'User-Agent': 'python-requests/2.29.0', 'Accept-Encoding': 'gzip, deflate, br', 'Accept': '*/*', 'Connection': 'keep-alive', 'Content-Length': '1442'}
2024-03-13 21:07:22,714 ERROR   wandb-upload_4:11564 [internal_api.py:upload_file():2558] upload_file request headers: {'User-Agent': 'python-requests/2.29.0', 'Accept-Encoding': 'gzip, deflate, br', 'Accept': '*/*', 'Connection': 'keep-alive', 'Content-Length': '3463'}
2024-03-13 21:07:22,714 ERROR   wandb-upload_3:11564 [internal_api.py:upload_file():2560] upload_file response body: 
2024-03-13 21:07:22,714 ERROR   wandb-upload_4:11564 [internal_api.py:upload_file():2560] upload_file response body: 
2024-03-13 21:07:22,953 ERROR   wandb-upload_5:11564 [internal_api.py:upload_file():2556] upload_file exception https://storage.googleapis.com/wandb-production.appspot.com/princeporch/uncategorized/3oq1hjiv/wandb-summary.json?Expires=1710421619&GoogleAccessId=gorilla-files-url-signer-man%40wandb-production.iam.gserviceaccount.com&Signature=PSmEYJju6wiwsS%2BCP4TPAyMXoCRCkZH3wzTlB%2FNxzsOXGTGYQ5QQU8I5IoTKNuPIxBqzdVXEa%2BrfaEnkfknhU6dEJifKU%2F08YafAvOZCLyed0VZJ9ASrGfb%2BDarR5FyKREfA7PXy7pqX7bxuEuu5Qwkn26ZJjd4fLt4d1Ni1R%2Fm63sh2Xk6vNcot0Yv6ixC1nJekAZ5k88d7gFfaOHHvD9kVEQGfvNNNiXo%2FnhI2xbV%2FwyQmBnkW%2Fo%2BlL2ml0PTbvO57lq9r%2F9yPdlKM%2BmMLOGvYF%2F0v5rA3fwdzpsShlMzEFugGIJDIHiid27UMWkVZrFn7%2BKJoSB4Us2lh3lLBTQ%3D%3D: HTTPSConnectionPool(host='storage.googleapis.com', port=443): Max retries exceeded with url: /wandb-production.appspot.com/princeporch/uncategorized/3oq1hjiv/wandb-summary.json?Expires=1710421619&GoogleAccessId=gorilla-files-url-signer-man%40wandb-production.iam.gserviceaccount.com&Signature=PSmEYJju6wiwsS%2BCP4TPAyMXoCRCkZH3wzTlB%2FNxzsOXGTGYQ5QQU8I5IoTKNuPIxBqzdVXEa%2BrfaEnkfknhU6dEJifKU%2F08YafAvOZCLyed0VZJ9ASrGfb%2BDarR5FyKREfA7PXy7pqX7bxuEuu5Qwkn26ZJjd4fLt4d1Ni1R%2Fm63sh2Xk6vNcot0Yv6ixC1nJekAZ5k88d7gFfaOHHvD9kVEQGfvNNNiXo%2FnhI2xbV%2FwyQmBnkW%2Fo%2BlL2ml0PTbvO57lq9r%2F9yPdlKM%2BmMLOGvYF%2F0v5rA3fwdzpsShlMzEFugGIJDIHiid27UMWkVZrFn7%2BKJoSB4Us2lh3lLBTQ%3D%3D (Caused by NewConnectionError('<urllib3.connection.HTTPSConnection object at 0x000001E2311D8550>: Failed to establish a new connection: [WinError 10061] 由于目标计算机积极拒绝，无法连接。'))
2024-03-13 21:07:22,953 ERROR   wandb-upload_5:11564 [internal_api.py:upload_file():2558] upload_file request headers: {'User-Agent': 'python-requests/2.29.0', 'Accept-Encoding': 'gzip, deflate, br', 'Accept': '*/*', 'Connection': 'keep-alive', 'Content-Length': '210'}
2024-03-13 21:07:22,953 ERROR   wandb-upload_5:11564 [internal_api.py:upload_file():2560] upload_file response body: 
2024-03-13 21:07:23,131 DEBUG   HandlerThread:11564 [handler.py:handle_request():144] handle_request: status_report
2024-03-13 21:07:23,131 DEBUG   HandlerThread:11564 [handler.py:handle_request():144] handle_request: poll_exit
2024-03-13 21:07:23,131 DEBUG   SenderThread:11564 [sender.py:send_request():407] send_request: poll_exit
2024-03-13 21:07:24,135 DEBUG   HandlerThread:11564 [handler.py:handle_request():144] handle_request: poll_exit
2024-03-13 21:07:24,135 DEBUG   SenderThread:11564 [sender.py:send_request():407] send_request: poll_exit
2024-03-13 21:07:25,142 DEBUG   HandlerThread:11564 [handler.py:handle_request():144] handle_request: poll_exit
2024-03-13 21:07:25,143 DEBUG   SenderThread:11564 [sender.py:send_request():407] send_request: poll_exit
2024-03-13 21:07:26,148 DEBUG   HandlerThread:11564 [handler.py:handle_request():144] handle_request: poll_exit
2024-03-13 21:07:26,149 DEBUG   SenderThread:11564 [sender.py:send_request():407] send_request: poll_exit
2024-03-13 21:07:27,164 DEBUG   HandlerThread:11564 [handler.py:handle_request():144] handle_request: poll_exit
2024-03-13 21:07:27,164 DEBUG   SenderThread:11564 [sender.py:send_request():407] send_request: poll_exit
2024-03-13 21:07:28,178 DEBUG   HandlerThread:11564 [handler.py:handle_request():144] handle_request: poll_exit
2024-03-13 21:07:28,179 DEBUG   HandlerThread:11564 [handler.py:handle_request():144] handle_request: status_report
2024-03-13 21:07:28,179 DEBUG   SenderThread:11564 [sender.py:send_request():407] send_request: poll_exit
2024-03-13 21:07:29,194 DEBUG   HandlerThread:11564 [handler.py:handle_request():144] handle_request: poll_exit
2024-03-13 21:07:29,195 DEBUG   SenderThread:11564 [sender.py:send_request():407] send_request: poll_exit
2024-03-13 21:07:30,209 DEBUG   HandlerThread:11564 [handler.py:handle_request():144] handle_request: poll_exit
2024-03-13 21:07:30,210 DEBUG   SenderThread:11564 [sender.py:send_request():407] send_request: poll_exit
2024-03-13 21:07:31,213 DEBUG   HandlerThread:11564 [handler.py:handle_request():144] handle_request: poll_exit
2024-03-13 21:07:31,214 DEBUG   SenderThread:11564 [sender.py:send_request():407] send_request: poll_exit
2024-03-13 21:07:32,222 DEBUG   HandlerThread:11564 [handler.py:handle_request():144] handle_request: poll_exit
2024-03-13 21:07:32,222 DEBUG   SenderThread:11564 [sender.py:send_request():407] send_request: poll_exit
2024-03-13 21:07:33,225 DEBUG   HandlerThread:11564 [handler.py:handle_request():144] handle_request: poll_exit
2024-03-13 21:07:33,226 DEBUG   HandlerThread:11564 [handler.py:handle_request():144] handle_request: status_report
2024-03-13 21:07:33,226 DEBUG   SenderThread:11564 [sender.py:send_request():407] send_request: poll_exit
2024-03-13 21:07:34,231 DEBUG   HandlerThread:11564 [handler.py:handle_request():144] handle_request: poll_exit
2024-03-13 21:07:34,231 DEBUG   SenderThread:11564 [sender.py:send_request():407] send_request: poll_exit
2024-03-13 21:07:34,562 ERROR   wandb-upload_2:11564 [internal_api.py:upload_file():2556] upload_file exception https://storage.googleapis.com/wandb-production.appspot.com/princeporch/uncategorized/3oq1hjiv/config.yaml?Expires=1710421608&GoogleAccessId=gorilla-files-url-signer-man%40wandb-production.iam.gserviceaccount.com&Signature=sNlmpu%2FIH5JtVJvvk5mIkTrXxesU%2Fi3Y5PNkHvnjJ9D0%2Bcdu5B7DYBhRNE6LgNlYMVrhq7ihjyzI83y0L4rk7YO6MllMl8hmvccZIYucveUhYbu%2BnQ3JE2txEH4IsYiXlXuVSrRh4rs6BFDYEGFdWieR7NsY%2BZRBuLlJdRzwDNhOIUC1nn5TOK%2BvGONJ%2BN9QKf%2FPiw493eR5TC6C6q%2BkD1XsmPhZ08MVPXHsxnAOsMzcmASBtN2vZnyHAXGx4Gyicfy%2BB0Wv6BHSKKzfeuG5IwltveeAgb5SXuVESHXV6Ahgg5vVCmoX8IbNCiP4FULt1MkDe2HtaF6LJGzZarQk8A%3D%3D: HTTPSConnectionPool(host='storage.googleapis.com', port=443): Max retries exceeded with url: /wandb-production.appspot.com/princeporch/uncategorized/3oq1hjiv/config.yaml?Expires=1710421608&GoogleAccessId=gorilla-files-url-signer-man%40wandb-production.iam.gserviceaccount.com&Signature=sNlmpu%2FIH5JtVJvvk5mIkTrXxesU%2Fi3Y5PNkHvnjJ9D0%2Bcdu5B7DYBhRNE6LgNlYMVrhq7ihjyzI83y0L4rk7YO6MllMl8hmvccZIYucveUhYbu%2BnQ3JE2txEH4IsYiXlXuVSrRh4rs6BFDYEGFdWieR7NsY%2BZRBuLlJdRzwDNhOIUC1nn5TOK%2BvGONJ%2BN9QKf%2FPiw493eR5TC6C6q%2BkD1XsmPhZ08MVPXHsxnAOsMzcmASBtN2vZnyHAXGx4Gyicfy%2BB0Wv6BHSKKzfeuG5IwltveeAgb5SXuVESHXV6Ahgg5vVCmoX8IbNCiP4FULt1MkDe2HtaF6LJGzZarQk8A%3D%3D (Caused by NewConnectionError('<urllib3.connection.HTTPSConnection object at 0x000001E2311D8B20>: Failed to establish a new connection: [WinError 10061] 由于目标计算机积极拒绝，无法连接。'))
2024-03-13 21:07:34,562 ERROR   wandb-upload_2:11564 [internal_api.py:upload_file():2558] upload_file request headers: {'User-Agent': 'python-requests/2.29.0', 'Accept-Encoding': 'gzip, deflate, br', 'Accept': '*/*', 'Connection': 'keep-alive', 'Content-Length': '456'}
2024-03-13 21:07:34,562 ERROR   wandb-upload_2:11564 [internal_api.py:upload_file():2560] upload_file response body: 
2024-03-13 21:07:35,233 DEBUG   HandlerThread:11564 [handler.py:handle_request():144] handle_request: poll_exit
2024-03-13 21:07:35,234 DEBUG   SenderThread:11564 [sender.py:send_request():407] send_request: poll_exit
2024-03-13 21:07:35,978 ERROR   wandb-upload_1:11564 [internal_api.py:upload_file():2556] upload_file exception https://storage.googleapis.com/wandb-production.appspot.com/princeporch/uncategorized/3oq1hjiv/conda-environment.yaml?Expires=1710421608&GoogleAccessId=gorilla-files-url-signer-man%40wandb-production.iam.gserviceaccount.com&Signature=aitRQrHsilg%2FzKEwqkcWmGPUHjos3RP2WMR968fsXTpNrlNjdvUg7u3EXOly2ThKaAWT%2BJf6q236RUHU0hsAXWRXw3NPdGQbCkk6MinR8uqy3roCbvc4hkAxKX6kCk6Al3g8kc%2F1J4Vwi6oxiKk1UySlM5y7CAlZnJ9iYaac394ZdjY8sKoEOzyVV8s9MEeZOViTZhwH4DYHAbiA6YPeMrvfSFHB6p5imiPyiNHIiKuqVQy7TkvO3vFyGkvFw0FFCtqEq5gt3lz3fQHGdQqbavcTcYI8B5xjVKe1ej%2FVkzz82CTW2EpNAWSEDd3HcuoirfZhjhakiBrdxlVDD9fKAA%3D%3D: HTTPSConnectionPool(host='storage.googleapis.com', port=443): Max retries exceeded with url: /wandb-production.appspot.com/princeporch/uncategorized/3oq1hjiv/conda-environment.yaml?Expires=1710421608&GoogleAccessId=gorilla-files-url-signer-man%40wandb-production.iam.gserviceaccount.com&Signature=aitRQrHsilg%2FzKEwqkcWmGPUHjos3RP2WMR968fsXTpNrlNjdvUg7u3EXOly2ThKaAWT%2BJf6q236RUHU0hsAXWRXw3NPdGQbCkk6MinR8uqy3roCbvc4hkAxKX6kCk6Al3g8kc%2F1J4Vwi6oxiKk1UySlM5y7CAlZnJ9iYaac394ZdjY8sKoEOzyVV8s9MEeZOViTZhwH4DYHAbiA6YPeMrvfSFHB6p5imiPyiNHIiKuqVQy7TkvO3vFyGkvFw0FFCtqEq5gt3lz3fQHGdQqbavcTcYI8B5xjVKe1ej%2FVkzz82CTW2EpNAWSEDd3HcuoirfZhjhakiBrdxlVDD9fKAA%3D%3D (Caused by NewConnectionError('<urllib3.connection.HTTPSConnection object at 0x000001E233A75ED0>: Failed to establish a new connection: [WinError 10061] 由于目标计算机积极拒绝，无法连接。'))
2024-03-13 21:07:35,978 ERROR   wandb-upload_1:11564 [internal_api.py:upload_file():2558] upload_file request headers: {'User-Agent': 'python-requests/2.29.0', 'Accept-Encoding': 'gzip, deflate, br', 'Accept': '*/*', 'Connection': 'keep-alive', 'Content-Length': '9492'}
2024-03-13 21:07:35,978 ERROR   wandb-upload_1:11564 [internal_api.py:upload_file():2560] upload_file response body: 
2024-03-13 21:07:36,240 DEBUG   HandlerThread:11564 [handler.py:handle_request():144] handle_request: poll_exit
2024-03-13 21:07:36,240 DEBUG   SenderThread:11564 [sender.py:send_request():407] send_request: poll_exit
2024-03-13 21:07:37,074 ERROR   wandb-upload_3:11564 [internal_api.py:upload_file():2556] upload_file exception https://storage.googleapis.com/wandb-production.appspot.com/princeporch/uncategorized/3oq1hjiv/output.log?Expires=1710421619&GoogleAccessId=gorilla-files-url-signer-man%40wandb-production.iam.gserviceaccount.com&Signature=vXaEkCUQ85QzfttJFCpAaRP%2Fr8dGB1bKyJgeJqw6r08tu7%2B2%2FTb58PbNh2uWgqPkng%2BC52ZVgUe%2BVS%2BNrNVHnRsfudxdt7cQUb0Txx4bvPEYq8flFJ9GhI4x1YI26DxEViph6Vpr8LJnf65aWMMUUv6dyI%2BFXCdyGlJL2N2DTPdjC5oNPXalc%2BPRbpf0g09CrK4xkEs4oWHqM1yL%2FlqrUt5Z4t7F8Dt%2FNEXXwUT5KBeLTEimUzjiYgwPmrpjGE1qle1ngNd2KH1wot9L2Gpx3xcKcTD401FAwjIk%2FqUr2pTxfyyHJu9lijqHF59onQl%2FZO%2FxpYR8rq9IN%2ByGb3Imog%3D%3D: HTTPSConnectionPool(host='storage.googleapis.com', port=443): Max retries exceeded with url: /wandb-production.appspot.com/princeporch/uncategorized/3oq1hjiv/output.log?Expires=1710421619&GoogleAccessId=gorilla-files-url-signer-man%40wandb-production.iam.gserviceaccount.com&Signature=vXaEkCUQ85QzfttJFCpAaRP%2Fr8dGB1bKyJgeJqw6r08tu7%2B2%2FTb58PbNh2uWgqPkng%2BC52ZVgUe%2BVS%2BNrNVHnRsfudxdt7cQUb0Txx4bvPEYq8flFJ9GhI4x1YI26DxEViph6Vpr8LJnf65aWMMUUv6dyI%2BFXCdyGlJL2N2DTPdjC5oNPXalc%2BPRbpf0g09CrK4xkEs4oWHqM1yL%2FlqrUt5Z4t7F8Dt%2FNEXXwUT5KBeLTEimUzjiYgwPmrpjGE1qle1ngNd2KH1wot9L2Gpx3xcKcTD401FAwjIk%2FqUr2pTxfyyHJu9lijqHF59onQl%2FZO%2FxpYR8rq9IN%2ByGb3Imog%3D%3D (Caused by NewConnectionError('<urllib3.connection.HTTPSConnection object at 0x000001E233A77430>: Failed to establish a new connection: [WinError 10061] 由于目标计算机积极拒绝，无法连接。'))
2024-03-13 21:07:37,074 ERROR   wandb-upload_4:11564 [internal_api.py:upload_file():2556] upload_file exception https://storage.googleapis.com/wandb-production.appspot.com/princeporch/uncategorized/3oq1hjiv/requirements.txt?Expires=1710421619&GoogleAccessId=gorilla-files-url-signer-man%40wandb-production.iam.gserviceaccount.com&Signature=u7dGtXVPVcgPT24WQ38jd7g74stCo%2BEaLYegyiVpcQGxZY5%2BLl79DLu13dtyPhjRd6V2aCF4W4cfojHZxGaAf3g4vQHLEOaZANXX7gSQKxGydbY39gTZ9qQXpSUf5MfrMmiyjVcumFWW7g22e5NN9iRT4B4jZzqUqQqUL4gaGgkAEKvRiLmI6hOqgpyTzQp32LqLGgS%2BMu1udnQV530MiYc6OSoy6IPRAtNfcaSCIULV2B6caR4N7Nz0o6RS5pHIESO%2FdaClhBjVtz57vDHKzrXg0i6RUVdcL5GXvF13L1PsX%2BjwLBLc6eGgkCwHR8vuVpjMy%2FyvMS6E4nGF2IVyWA%3D%3D: HTTPSConnectionPool(host='storage.googleapis.com', port=443): Max retries exceeded with url: /wandb-production.appspot.com/princeporch/uncategorized/3oq1hjiv/requirements.txt?Expires=1710421619&GoogleAccessId=gorilla-files-url-signer-man%40wandb-production.iam.gserviceaccount.com&Signature=u7dGtXVPVcgPT24WQ38jd7g74stCo%2BEaLYegyiVpcQGxZY5%2BLl79DLu13dtyPhjRd6V2aCF4W4cfojHZxGaAf3g4vQHLEOaZANXX7gSQKxGydbY39gTZ9qQXpSUf5MfrMmiyjVcumFWW7g22e5NN9iRT4B4jZzqUqQqUL4gaGgkAEKvRiLmI6hOqgpyTzQp32LqLGgS%2BMu1udnQV530MiYc6OSoy6IPRAtNfcaSCIULV2B6caR4N7Nz0o6RS5pHIESO%2FdaClhBjVtz57vDHKzrXg0i6RUVdcL5GXvF13L1PsX%2BjwLBLc6eGgkCwHR8vuVpjMy%2FyvMS6E4nGF2IVyWA%3D%3D (Caused by NewConnectionError('<urllib3.connection.HTTPSConnection object at 0x000001E233A776A0>: Failed to establish a new connection: [WinError 10061] 由于目标计算机积极拒绝，无法连接。'))
2024-03-13 21:07:37,074 ERROR   wandb-upload_3:11564 [internal_api.py:upload_file():2558] upload_file request headers: {'User-Agent': 'python-requests/2.29.0', 'Accept-Encoding': 'gzip, deflate, br', 'Accept': '*/*', 'Connection': 'keep-alive', 'Content-Length': '1442'}
2024-03-13 21:07:37,075 ERROR   wandb-upload_4:11564 [internal_api.py:upload_file():2558] upload_file request headers: {'User-Agent': 'python-requests/2.29.0', 'Accept-Encoding': 'gzip, deflate, br', 'Accept': '*/*', 'Connection': 'keep-alive', 'Content-Length': '3463'}
2024-03-13 21:07:37,075 ERROR   wandb-upload_3:11564 [internal_api.py:upload_file():2560] upload_file response body: 
2024-03-13 21:07:37,075 ERROR   wandb-upload_4:11564 [internal_api.py:upload_file():2560] upload_file response body: 
2024-03-13 21:07:37,241 DEBUG   HandlerThread:11564 [handler.py:handle_request():144] handle_request: poll_exit
2024-03-13 21:07:37,242 DEBUG   SenderThread:11564 [sender.py:send_request():407] send_request: poll_exit
2024-03-13 21:07:38,245 DEBUG   HandlerThread:11564 [handler.py:handle_request():144] handle_request: status_report
2024-03-13 21:07:38,245 DEBUG   HandlerThread:11564 [handler.py:handle_request():144] handle_request: poll_exit
2024-03-13 21:07:38,246 DEBUG   SenderThread:11564 [sender.py:send_request():407] send_request: poll_exit
2024-03-13 21:07:38,249 ERROR   wandb-upload_5:11564 [internal_api.py:upload_file():2556] upload_file exception https://storage.googleapis.com/wandb-production.appspot.com/princeporch/uncategorized/3oq1hjiv/wandb-summary.json?Expires=1710421619&GoogleAccessId=gorilla-files-url-signer-man%40wandb-production.iam.gserviceaccount.com&Signature=PSmEYJju6wiwsS%2BCP4TPAyMXoCRCkZH3wzTlB%2FNxzsOXGTGYQ5QQU8I5IoTKNuPIxBqzdVXEa%2BrfaEnkfknhU6dEJifKU%2F08YafAvOZCLyed0VZJ9ASrGfb%2BDarR5FyKREfA7PXy7pqX7bxuEuu5Qwkn26ZJjd4fLt4d1Ni1R%2Fm63sh2Xk6vNcot0Yv6ixC1nJekAZ5k88d7gFfaOHHvD9kVEQGfvNNNiXo%2FnhI2xbV%2FwyQmBnkW%2Fo%2BlL2ml0PTbvO57lq9r%2F9yPdlKM%2BmMLOGvYF%2F0v5rA3fwdzpsShlMzEFugGIJDIHiid27UMWkVZrFn7%2BKJoSB4Us2lh3lLBTQ%3D%3D: HTTPSConnectionPool(host='storage.googleapis.com', port=443): Max retries exceeded with url: /wandb-production.appspot.com/princeporch/uncategorized/3oq1hjiv/wandb-summary.json?Expires=1710421619&GoogleAccessId=gorilla-files-url-signer-man%40wandb-production.iam.gserviceaccount.com&Signature=PSmEYJju6wiwsS%2BCP4TPAyMXoCRCkZH3wzTlB%2FNxzsOXGTGYQ5QQU8I5IoTKNuPIxBqzdVXEa%2BrfaEnkfknhU6dEJifKU%2F08YafAvOZCLyed0VZJ9ASrGfb%2BDarR5FyKREfA7PXy7pqX7bxuEuu5Qwkn26ZJjd4fLt4d1Ni1R%2Fm63sh2Xk6vNcot0Yv6ixC1nJekAZ5k88d7gFfaOHHvD9kVEQGfvNNNiXo%2FnhI2xbV%2FwyQmBnkW%2Fo%2BlL2ml0PTbvO57lq9r%2F9yPdlKM%2BmMLOGvYF%2F0v5rA3fwdzpsShlMzEFugGIJDIHiid27UMWkVZrFn7%2BKJoSB4Us2lh3lLBTQ%3D%3D (Caused by NewConnectionError('<urllib3.connection.HTTPSConnection object at 0x000001E233A774C0>: Failed to establish a new connection: [WinError 10061] 由于目标计算机积极拒绝，无法连接。'))
2024-03-13 21:07:38,249 ERROR   wandb-upload_5:11564 [internal_api.py:upload_file():2558] upload_file request headers: {'User-Agent': 'python-requests/2.29.0', 'Accept-Encoding': 'gzip, deflate, br', 'Accept': '*/*', 'Connection': 'keep-alive', 'Content-Length': '210'}
2024-03-13 21:07:38,249 ERROR   wandb-upload_5:11564 [internal_api.py:upload_file():2560] upload_file response body: 
2024-03-13 21:07:39,247 DEBUG   HandlerThread:11564 [handler.py:handle_request():144] handle_request: poll_exit
2024-03-13 21:07:39,248 DEBUG   SenderThread:11564 [sender.py:send_request():407] send_request: poll_exit
2024-03-13 21:07:40,255 DEBUG   HandlerThread:11564 [handler.py:handle_request():144] handle_request: poll_exit
2024-03-13 21:07:40,255 DEBUG   SenderThread:11564 [sender.py:send_request():407] send_request: poll_exit
2024-03-13 21:07:41,260 DEBUG   HandlerThread:11564 [handler.py:handle_request():144] handle_request: poll_exit
2024-03-13 21:07:41,260 DEBUG   SenderThread:11564 [sender.py:send_request():407] send_request: poll_exit
2024-03-13 21:07:42,274 DEBUG   HandlerThread:11564 [handler.py:handle_request():144] handle_request: poll_exit
2024-03-13 21:07:42,274 DEBUG   SenderThread:11564 [sender.py:send_request():407] send_request: poll_exit
2024-03-13 21:07:43,288 DEBUG   HandlerThread:11564 [handler.py:handle_request():144] handle_request: status_report
2024-03-13 21:07:43,289 DEBUG   HandlerThread:11564 [handler.py:handle_request():144] handle_request: poll_exit
2024-03-13 21:07:43,289 DEBUG   SenderThread:11564 [sender.py:send_request():407] send_request: poll_exit
2024-03-13 21:07:44,304 DEBUG   HandlerThread:11564 [handler.py:handle_request():144] handle_request: poll_exit
2024-03-13 21:07:44,304 DEBUG   SenderThread:11564 [sender.py:send_request():407] send_request: poll_exit
2024-03-13 21:07:45,305 DEBUG   HandlerThread:11564 [handler.py:handle_request():144] handle_request: poll_exit
2024-03-13 21:07:45,306 DEBUG   SenderThread:11564 [sender.py:send_request():407] send_request: poll_exit
2024-03-13 21:07:46,309 DEBUG   HandlerThread:11564 [handler.py:handle_request():144] handle_request: poll_exit
2024-03-13 21:07:46,309 DEBUG   SenderThread:11564 [sender.py:send_request():407] send_request: poll_exit
2024-03-13 21:07:47,312 DEBUG   HandlerThread:11564 [handler.py:handle_request():144] handle_request: poll_exit
2024-03-13 21:07:47,313 DEBUG   SenderThread:11564 [sender.py:send_request():407] send_request: poll_exit
2024-03-13 21:07:48,323 DEBUG   HandlerThread:11564 [handler.py:handle_request():144] handle_request: status_report
2024-03-13 21:07:48,324 DEBUG   HandlerThread:11564 [handler.py:handle_request():144] handle_request: poll_exit
2024-03-13 21:07:48,324 DEBUG   SenderThread:11564 [sender.py:send_request():407] send_request: poll_exit
2024-03-13 21:07:49,338 DEBUG   HandlerThread:11564 [handler.py:handle_request():144] handle_request: poll_exit
2024-03-13 21:07:49,338 DEBUG   SenderThread:11564 [sender.py:send_request():407] send_request: poll_exit
2024-03-13 21:07:50,349 DEBUG   HandlerThread:11564 [handler.py:handle_request():144] handle_request: poll_exit
2024-03-13 21:07:50,350 DEBUG   SenderThread:11564 [sender.py:send_request():407] send_request: poll_exit
2024-03-13 21:07:51,353 DEBUG   HandlerThread:11564 [handler.py:handle_request():144] handle_request: poll_exit
2024-03-13 21:07:51,354 DEBUG   SenderThread:11564 [sender.py:send_request():407] send_request: poll_exit
2024-03-13 21:07:52,241 ERROR   wandb-upload_2:11564 [internal_api.py:upload_file():2556] upload_file exception https://storage.googleapis.com/wandb-production.appspot.com/princeporch/uncategorized/3oq1hjiv/config.yaml?Expires=1710421608&GoogleAccessId=gorilla-files-url-signer-man%40wandb-production.iam.gserviceaccount.com&Signature=sNlmpu%2FIH5JtVJvvk5mIkTrXxesU%2Fi3Y5PNkHvnjJ9D0%2Bcdu5B7DYBhRNE6LgNlYMVrhq7ihjyzI83y0L4rk7YO6MllMl8hmvccZIYucveUhYbu%2BnQ3JE2txEH4IsYiXlXuVSrRh4rs6BFDYEGFdWieR7NsY%2BZRBuLlJdRzwDNhOIUC1nn5TOK%2BvGONJ%2BN9QKf%2FPiw493eR5TC6C6q%2BkD1XsmPhZ08MVPXHsxnAOsMzcmASBtN2vZnyHAXGx4Gyicfy%2BB0Wv6BHSKKzfeuG5IwltveeAgb5SXuVESHXV6Ahgg5vVCmoX8IbNCiP4FULt1MkDe2HtaF6LJGzZarQk8A%3D%3D: HTTPSConnectionPool(host='storage.googleapis.com', port=443): Max retries exceeded with url: /wandb-production.appspot.com/princeporch/uncategorized/3oq1hjiv/config.yaml?Expires=1710421608&GoogleAccessId=gorilla-files-url-signer-man%40wandb-production.iam.gserviceaccount.com&Signature=sNlmpu%2FIH5JtVJvvk5mIkTrXxesU%2Fi3Y5PNkHvnjJ9D0%2Bcdu5B7DYBhRNE6LgNlYMVrhq7ihjyzI83y0L4rk7YO6MllMl8hmvccZIYucveUhYbu%2BnQ3JE2txEH4IsYiXlXuVSrRh4rs6BFDYEGFdWieR7NsY%2BZRBuLlJdRzwDNhOIUC1nn5TOK%2BvGONJ%2BN9QKf%2FPiw493eR5TC6C6q%2BkD1XsmPhZ08MVPXHsxnAOsMzcmASBtN2vZnyHAXGx4Gyicfy%2BB0Wv6BHSKKzfeuG5IwltveeAgb5SXuVESHXV6Ahgg5vVCmoX8IbNCiP4FULt1MkDe2HtaF6LJGzZarQk8A%3D%3D (Caused by NewConnectionError('<urllib3.connection.HTTPSConnection object at 0x000001E233A77C10>: Failed to establish a new connection: [WinError 10061] 由于目标计算机积极拒绝，无法连接。'))
2024-03-13 21:07:52,241 ERROR   wandb-upload_2:11564 [internal_api.py:upload_file():2558] upload_file request headers: {'User-Agent': 'python-requests/2.29.0', 'Accept-Encoding': 'gzip, deflate, br', 'Accept': '*/*', 'Connection': 'keep-alive', 'Content-Length': '456'}
2024-03-13 21:07:52,241 ERROR   wandb-upload_2:11564 [internal_api.py:upload_file():2560] upload_file response body: 
2024-03-13 21:07:52,364 DEBUG   HandlerThread:11564 [handler.py:handle_request():144] handle_request: poll_exit
2024-03-13 21:07:52,365 DEBUG   SenderThread:11564 [sender.py:send_request():407] send_request: poll_exit
2024-03-13 21:07:52,524 ERROR   wandb-upload_1:11564 [internal_api.py:upload_file():2556] upload_file exception https://storage.googleapis.com/wandb-production.appspot.com/princeporch/uncategorized/3oq1hjiv/conda-environment.yaml?Expires=1710421608&GoogleAccessId=gorilla-files-url-signer-man%40wandb-production.iam.gserviceaccount.com&Signature=aitRQrHsilg%2FzKEwqkcWmGPUHjos3RP2WMR968fsXTpNrlNjdvUg7u3EXOly2ThKaAWT%2BJf6q236RUHU0hsAXWRXw3NPdGQbCkk6MinR8uqy3roCbvc4hkAxKX6kCk6Al3g8kc%2F1J4Vwi6oxiKk1UySlM5y7CAlZnJ9iYaac394ZdjY8sKoEOzyVV8s9MEeZOViTZhwH4DYHAbiA6YPeMrvfSFHB6p5imiPyiNHIiKuqVQy7TkvO3vFyGkvFw0FFCtqEq5gt3lz3fQHGdQqbavcTcYI8B5xjVKe1ej%2FVkzz82CTW2EpNAWSEDd3HcuoirfZhjhakiBrdxlVDD9fKAA%3D%3D: HTTPSConnectionPool(host='storage.googleapis.com', port=443): Max retries exceeded with url: /wandb-production.appspot.com/princeporch/uncategorized/3oq1hjiv/conda-environment.yaml?Expires=1710421608&GoogleAccessId=gorilla-files-url-signer-man%40wandb-production.iam.gserviceaccount.com&Signature=aitRQrHsilg%2FzKEwqkcWmGPUHjos3RP2WMR968fsXTpNrlNjdvUg7u3EXOly2ThKaAWT%2BJf6q236RUHU0hsAXWRXw3NPdGQbCkk6MinR8uqy3roCbvc4hkAxKX6kCk6Al3g8kc%2F1J4Vwi6oxiKk1UySlM5y7CAlZnJ9iYaac394ZdjY8sKoEOzyVV8s9MEeZOViTZhwH4DYHAbiA6YPeMrvfSFHB6p5imiPyiNHIiKuqVQy7TkvO3vFyGkvFw0FFCtqEq5gt3lz3fQHGdQqbavcTcYI8B5xjVKe1ej%2FVkzz82CTW2EpNAWSEDd3HcuoirfZhjhakiBrdxlVDD9fKAA%3D%3D (Caused by NewConnectionError('<urllib3.connection.HTTPSConnection object at 0x000001E2338B15A0>: Failed to establish a new connection: [WinError 10061] 由于目标计算机积极拒绝，无法连接。'))
2024-03-13 21:07:52,524 ERROR   wandb-upload_1:11564 [internal_api.py:upload_file():2558] upload_file request headers: {'User-Agent': 'python-requests/2.29.0', 'Accept-Encoding': 'gzip, deflate, br', 'Accept': '*/*', 'Connection': 'keep-alive', 'Content-Length': '9492'}
2024-03-13 21:07:52,524 ERROR   wandb-upload_1:11564 [internal_api.py:upload_file():2560] upload_file response body: 
2024-03-13 21:07:53,206 ERROR   wandb-upload_3:11564 [internal_api.py:upload_file():2556] upload_file exception https://storage.googleapis.com/wandb-production.appspot.com/princeporch/uncategorized/3oq1hjiv/output.log?Expires=1710421619&GoogleAccessId=gorilla-files-url-signer-man%40wandb-production.iam.gserviceaccount.com&Signature=vXaEkCUQ85QzfttJFCpAaRP%2Fr8dGB1bKyJgeJqw6r08tu7%2B2%2FTb58PbNh2uWgqPkng%2BC52ZVgUe%2BVS%2BNrNVHnRsfudxdt7cQUb0Txx4bvPEYq8flFJ9GhI4x1YI26DxEViph6Vpr8LJnf65aWMMUUv6dyI%2BFXCdyGlJL2N2DTPdjC5oNPXalc%2BPRbpf0g09CrK4xkEs4oWHqM1yL%2FlqrUt5Z4t7F8Dt%2FNEXXwUT5KBeLTEimUzjiYgwPmrpjGE1qle1ngNd2KH1wot9L2Gpx3xcKcTD401FAwjIk%2FqUr2pTxfyyHJu9lijqHF59onQl%2FZO%2FxpYR8rq9IN%2ByGb3Imog%3D%3D: HTTPSConnectionPool(host='storage.googleapis.com', port=443): Max retries exceeded with url: /wandb-production.appspot.com/princeporch/uncategorized/3oq1hjiv/output.log?Expires=1710421619&GoogleAccessId=gorilla-files-url-signer-man%40wandb-production.iam.gserviceaccount.com&Signature=vXaEkCUQ85QzfttJFCpAaRP%2Fr8dGB1bKyJgeJqw6r08tu7%2B2%2FTb58PbNh2uWgqPkng%2BC52ZVgUe%2BVS%2BNrNVHnRsfudxdt7cQUb0Txx4bvPEYq8flFJ9GhI4x1YI26DxEViph6Vpr8LJnf65aWMMUUv6dyI%2BFXCdyGlJL2N2DTPdjC5oNPXalc%2BPRbpf0g09CrK4xkEs4oWHqM1yL%2FlqrUt5Z4t7F8Dt%2FNEXXwUT5KBeLTEimUzjiYgwPmrpjGE1qle1ngNd2KH1wot9L2Gpx3xcKcTD401FAwjIk%2FqUr2pTxfyyHJu9lijqHF59onQl%2FZO%2FxpYR8rq9IN%2ByGb3Imog%3D%3D (Caused by NewConnectionError('<urllib3.connection.HTTPSConnection object at 0x000001E2311D90F0>: Failed to establish a new connection: [WinError 10061] 由于目标计算机积极拒绝，无法连接。'))
2024-03-13 21:07:53,206 ERROR   wandb-upload_3:11564 [internal_api.py:upload_file():2558] upload_file request headers: {'User-Agent': 'python-requests/2.29.0', 'Accept-Encoding': 'gzip, deflate, br', 'Accept': '*/*', 'Connection': 'keep-alive', 'Content-Length': '1442'}
2024-03-13 21:07:53,206 ERROR   wandb-upload_3:11564 [internal_api.py:upload_file():2560] upload_file response body: 
2024-03-13 21:07:53,221 ERROR   wandb-upload_4:11564 [internal_api.py:upload_file():2556] upload_file exception https://storage.googleapis.com/wandb-production.appspot.com/princeporch/uncategorized/3oq1hjiv/requirements.txt?Expires=1710421619&GoogleAccessId=gorilla-files-url-signer-man%40wandb-production.iam.gserviceaccount.com&Signature=u7dGtXVPVcgPT24WQ38jd7g74stCo%2BEaLYegyiVpcQGxZY5%2BLl79DLu13dtyPhjRd6V2aCF4W4cfojHZxGaAf3g4vQHLEOaZANXX7gSQKxGydbY39gTZ9qQXpSUf5MfrMmiyjVcumFWW7g22e5NN9iRT4B4jZzqUqQqUL4gaGgkAEKvRiLmI6hOqgpyTzQp32LqLGgS%2BMu1udnQV530MiYc6OSoy6IPRAtNfcaSCIULV2B6caR4N7Nz0o6RS5pHIESO%2FdaClhBjVtz57vDHKzrXg0i6RUVdcL5GXvF13L1PsX%2BjwLBLc6eGgkCwHR8vuVpjMy%2FyvMS6E4nGF2IVyWA%3D%3D: HTTPSConnectionPool(host='storage.googleapis.com', port=443): Max retries exceeded with url: /wandb-production.appspot.com/princeporch/uncategorized/3oq1hjiv/requirements.txt?Expires=1710421619&GoogleAccessId=gorilla-files-url-signer-man%40wandb-production.iam.gserviceaccount.com&Signature=u7dGtXVPVcgPT24WQ38jd7g74stCo%2BEaLYegyiVpcQGxZY5%2BLl79DLu13dtyPhjRd6V2aCF4W4cfojHZxGaAf3g4vQHLEOaZANXX7gSQKxGydbY39gTZ9qQXpSUf5MfrMmiyjVcumFWW7g22e5NN9iRT4B4jZzqUqQqUL4gaGgkAEKvRiLmI6hOqgpyTzQp32LqLGgS%2BMu1udnQV530MiYc6OSoy6IPRAtNfcaSCIULV2B6caR4N7Nz0o6RS5pHIESO%2FdaClhBjVtz57vDHKzrXg0i6RUVdcL5GXvF13L1PsX%2BjwLBLc6eGgkCwHR8vuVpjMy%2FyvMS6E4nGF2IVyWA%3D%3D (Caused by NewConnectionError('<urllib3.connection.HTTPSConnection object at 0x000001E2338B1060>: Failed to establish a new connection: [WinError 10061] 由于目标计算机积极拒绝，无法连接。'))
2024-03-13 21:07:53,221 ERROR   wandb-upload_4:11564 [internal_api.py:upload_file():2558] upload_file request headers: {'User-Agent': 'python-requests/2.29.0', 'Accept-Encoding': 'gzip, deflate, br', 'Accept': '*/*', 'Connection': 'keep-alive', 'Content-Length': '3463'}
2024-03-13 21:07:53,221 ERROR   wandb-upload_4:11564 [internal_api.py:upload_file():2560] upload_file response body: 
2024-03-13 21:07:53,380 DEBUG   HandlerThread:11564 [handler.py:handle_request():144] handle_request: poll_exit
2024-03-13 21:07:53,380 DEBUG   HandlerThread:11564 [handler.py:handle_request():144] handle_request: status_report
2024-03-13 21:07:53,380 DEBUG   SenderThread:11564 [sender.py:send_request():407] send_request: poll_exit
2024-03-13 21:07:54,391 DEBUG   HandlerThread:11564 [handler.py:handle_request():144] handle_request: poll_exit
2024-03-13 21:07:54,392 DEBUG   SenderThread:11564 [sender.py:send_request():407] send_request: poll_exit
2024-03-13 21:07:55,397 DEBUG   HandlerThread:11564 [handler.py:handle_request():144] handle_request: poll_exit
2024-03-13 21:07:55,398 DEBUG   SenderThread:11564 [sender.py:send_request():407] send_request: poll_exit
2024-03-13 21:07:55,569 ERROR   wandb-upload_5:11564 [internal_api.py:upload_file():2556] upload_file exception https://storage.googleapis.com/wandb-production.appspot.com/princeporch/uncategorized/3oq1hjiv/wandb-summary.json?Expires=1710421619&GoogleAccessId=gorilla-files-url-signer-man%40wandb-production.iam.gserviceaccount.com&Signature=PSmEYJju6wiwsS%2BCP4TPAyMXoCRCkZH3wzTlB%2FNxzsOXGTGYQ5QQU8I5IoTKNuPIxBqzdVXEa%2BrfaEnkfknhU6dEJifKU%2F08YafAvOZCLyed0VZJ9ASrGfb%2BDarR5FyKREfA7PXy7pqX7bxuEuu5Qwkn26ZJjd4fLt4d1Ni1R%2Fm63sh2Xk6vNcot0Yv6ixC1nJekAZ5k88d7gFfaOHHvD9kVEQGfvNNNiXo%2FnhI2xbV%2FwyQmBnkW%2Fo%2BlL2ml0PTbvO57lq9r%2F9yPdlKM%2BmMLOGvYF%2F0v5rA3fwdzpsShlMzEFugGIJDIHiid27UMWkVZrFn7%2BKJoSB4Us2lh3lLBTQ%3D%3D: HTTPSConnectionPool(host='storage.googleapis.com', port=443): Max retries exceeded with url: /wandb-production.appspot.com/princeporch/uncategorized/3oq1hjiv/wandb-summary.json?Expires=1710421619&GoogleAccessId=gorilla-files-url-signer-man%40wandb-production.iam.gserviceaccount.com&Signature=PSmEYJju6wiwsS%2BCP4TPAyMXoCRCkZH3wzTlB%2FNxzsOXGTGYQ5QQU8I5IoTKNuPIxBqzdVXEa%2BrfaEnkfknhU6dEJifKU%2F08YafAvOZCLyed0VZJ9ASrGfb%2BDarR5FyKREfA7PXy7pqX7bxuEuu5Qwkn26ZJjd4fLt4d1Ni1R%2Fm63sh2Xk6vNcot0Yv6ixC1nJekAZ5k88d7gFfaOHHvD9kVEQGfvNNNiXo%2FnhI2xbV%2FwyQmBnkW%2Fo%2BlL2ml0PTbvO57lq9r%2F9yPdlKM%2BmMLOGvYF%2F0v5rA3fwdzpsShlMzEFugGIJDIHiid27UMWkVZrFn7%2BKJoSB4Us2lh3lLBTQ%3D%3D (Caused by NewConnectionError('<urllib3.connection.HTTPSConnection object at 0x000001E2311D94B0>: Failed to establish a new connection: [WinError 10061] 由于目标计算机积极拒绝，无法连接。'))
2024-03-13 21:07:55,569 ERROR   wandb-upload_5:11564 [internal_api.py:upload_file():2558] upload_file request headers: {'User-Agent': 'python-requests/2.29.0', 'Accept-Encoding': 'gzip, deflate, br', 'Accept': '*/*', 'Connection': 'keep-alive', 'Content-Length': '210'}
2024-03-13 21:07:55,569 ERROR   wandb-upload_5:11564 [internal_api.py:upload_file():2560] upload_file response body: 
2024-03-13 21:07:56,412 DEBUG   HandlerThread:11564 [handler.py:handle_request():144] handle_request: poll_exit
2024-03-13 21:07:56,413 DEBUG   SenderThread:11564 [sender.py:send_request():407] send_request: poll_exit
2024-03-13 21:07:57,418 DEBUG   HandlerThread:11564 [handler.py:handle_request():144] handle_request: poll_exit
2024-03-13 21:07:57,418 DEBUG   SenderThread:11564 [sender.py:send_request():407] send_request: poll_exit
2024-03-13 21:07:58,421 DEBUG   HandlerThread:11564 [handler.py:handle_request():144] handle_request: poll_exit
2024-03-13 21:07:58,421 DEBUG   HandlerThread:11564 [handler.py:handle_request():144] handle_request: status_report
2024-03-13 21:07:58,422 DEBUG   SenderThread:11564 [sender.py:send_request():407] send_request: poll_exit
2024-03-13 21:07:58,689 ERROR   wandb-upload_0:11564 [internal_api.py:upload_file():2556] upload_file exception https://storage.googleapis.com/wandb-production.appspot.com/princeporch/uncategorized/3oq1hjiv/wandb-metadata.json?Expires=1710421510&GoogleAccessId=gorilla-files-url-signer-man%40wandb-production.iam.gserviceaccount.com&Signature=eOp1F3K0OOM3nLDkP8XGnJ3vXn9pxmhpqBLHGF70JePq4N7T%2B4hDEXHcmhltlUQ4NQc9xeuf4L9NTUU%2BemKL1XjMPGZBND6%2FSrv8%2FeIjMQZGrjidNIcRFBDVeo8CmuxZxdJ8Gptyw1wtIbncOOpIPzc8V5H7JupruC5U8TClVinntCLXpAqXzilii5v6LTDWYxZOX6GKmUhaJ871cyuuHvd2XejOlPzybq50U7LJHzWK4pdv0BWmuuhQEqsLpnTIkJ8IIeqMvtDgkxzpt5Y%2Fctx%2BBpalC7l25wD67YQWlfLN78ndHS0nNNKhuSR2F6PrWYtKn5tRxqmu3wALLCLFJg%3D%3D: HTTPSConnectionPool(host='storage.googleapis.com', port=443): Max retries exceeded with url: /wandb-production.appspot.com/princeporch/uncategorized/3oq1hjiv/wandb-metadata.json?Expires=1710421510&GoogleAccessId=gorilla-files-url-signer-man%40wandb-production.iam.gserviceaccount.com&Signature=eOp1F3K0OOM3nLDkP8XGnJ3vXn9pxmhpqBLHGF70JePq4N7T%2B4hDEXHcmhltlUQ4NQc9xeuf4L9NTUU%2BemKL1XjMPGZBND6%2FSrv8%2FeIjMQZGrjidNIcRFBDVeo8CmuxZxdJ8Gptyw1wtIbncOOpIPzc8V5H7JupruC5U8TClVinntCLXpAqXzilii5v6LTDWYxZOX6GKmUhaJ871cyuuHvd2XejOlPzybq50U7LJHzWK4pdv0BWmuuhQEqsLpnTIkJ8IIeqMvtDgkxzpt5Y%2Fctx%2BBpalC7l25wD67YQWlfLN78ndHS0nNNKhuSR2F6PrWYtKn5tRxqmu3wALLCLFJg%3D%3D (Caused by NewConnectionError('<urllib3.connection.HTTPSConnection object at 0x000001E233A74B80>: Failed to establish a new connection: [WinError 10061] 由于目标计算机积极拒绝，无法连接。'))
2024-03-13 21:07:58,689 ERROR   wandb-upload_0:11564 [internal_api.py:upload_file():2558] upload_file request headers: {'User-Agent': 'python-requests/2.29.0', 'Accept-Encoding': 'gzip, deflate, br', 'Accept': '*/*', 'Connection': 'keep-alive', 'Content-Length': '1321'}
2024-03-13 21:07:58,689 ERROR   wandb-upload_0:11564 [internal_api.py:upload_file():2560] upload_file response body: 
2024-03-13 21:07:59,436 DEBUG   HandlerThread:11564 [handler.py:handle_request():144] handle_request: poll_exit
2024-03-13 21:07:59,436 DEBUG   SenderThread:11564 [sender.py:send_request():407] send_request: poll_exit
2024-03-13 21:08:00,438 DEBUG   HandlerThread:11564 [handler.py:handle_request():144] handle_request: poll_exit
2024-03-13 21:08:00,438 DEBUG   SenderThread:11564 [sender.py:send_request():407] send_request: poll_exit
2024-03-13 21:08:01,450 DEBUG   HandlerThread:11564 [handler.py:handle_request():144] handle_request: poll_exit
2024-03-13 21:08:01,451 DEBUG   SenderThread:11564 [sender.py:send_request():407] send_request: poll_exit
2024-03-13 21:08:02,464 DEBUG   HandlerThread:11564 [handler.py:handle_request():144] handle_request: poll_exit
2024-03-13 21:08:02,465 DEBUG   SenderThread:11564 [sender.py:send_request():407] send_request: poll_exit
2024-03-13 21:08:03,480 DEBUG   HandlerThread:11564 [handler.py:handle_request():144] handle_request: status_report
2024-03-13 21:08:03,480 DEBUG   HandlerThread:11564 [handler.py:handle_request():144] handle_request: poll_exit
2024-03-13 21:08:03,480 DEBUG   SenderThread:11564 [sender.py:send_request():407] send_request: poll_exit
2024-03-13 21:08:04,493 DEBUG   HandlerThread:11564 [handler.py:handle_request():144] handle_request: poll_exit
2024-03-13 21:08:04,494 DEBUG   SenderThread:11564 [sender.py:send_request():407] send_request: poll_exit
2024-03-13 21:08:05,500 DEBUG   HandlerThread:11564 [handler.py:handle_request():144] handle_request: poll_exit
2024-03-13 21:08:05,500 DEBUG   SenderThread:11564 [sender.py:send_request():407] send_request: poll_exit
2024-03-13 21:08:06,507 DEBUG   HandlerThread:11564 [handler.py:handle_request():144] handle_request: poll_exit
2024-03-13 21:08:06,507 DEBUG   SenderThread:11564 [sender.py:send_request():407] send_request: poll_exit
