2024-03-13 20:09:10,262 INFO    StreamThr :26388 [internal.py:wandb_internal():86] W&B internal server running at pid: 26388, started at: 2024-03-13 20:09:10.261690
2024-03-13 20:09:10,263 DEBUG   HandlerThread:26388 [handler.py:handle_request():144] handle_request: status
2024-03-13 20:09:10,269 INFO    WriterThread:26388 [datastore.py:open_for_write():85] open: E:\自动驾驶\车位检测\parking-space-Identification-in-different-weather-main\wandb\run-20240313_200910-4jawgydh\run-4jawgydh.wandb
2024-03-13 20:09:10,271 DEBUG   SenderThread:26388 [sender.py:send():380] send: header
2024-03-13 20:09:10,271 DEBUG   SenderThread:26388 [sender.py:send():380] send: run
2024-03-13 20:09:15,324 DEBUG   HandlerThread:26388 [handler.py:handle_request():144] handle_request: keepalive
2024-03-13 20:09:20,366 DEBUG   HandlerThread:26388 [handler.py:handle_request():144] handle_request: keepalive
2024-03-13 20:09:25,426 DEBUG   HandlerThread:26388 [handler.py:handle_request():144] handle_request: keepalive
2024-03-13 20:09:30,463 DEBUG   HandlerThread:26388 [handler.py:handle_request():144] handle_request: keepalive
2024-03-13 20:09:35,497 DEBUG   HandlerThread:26388 [handler.py:handle_request():144] handle_request: keepalive
2024-03-13 20:09:40,534 DEBUG   HandlerThread:26388 [handler.py:handle_request():144] handle_request: keepalive
2024-03-13 20:09:45,569 DEBUG   HandlerThread:26388 [handler.py:handle_request():144] handle_request: keepalive
2024-03-13 20:09:50,595 DEBUG   HandlerThread:26388 [handler.py:handle_request():144] handle_request: keepalive
2024-03-13 20:09:55,622 DEBUG   HandlerThread:26388 [handler.py:handle_request():144] handle_request: keepalive
2024-03-13 20:10:00,640 DEBUG   HandlerThread:26388 [handler.py:handle_request():144] handle_request: keepalive
2024-03-13 20:10:05,666 DEBUG   HandlerThread:26388 [handler.py:handle_request():144] handle_request: keepalive
2024-03-13 20:10:10,691 DEBUG   HandlerThread:26388 [handler.py:handle_request():144] handle_request: keepalive
2024-03-13 20:10:12,274 INFO    SenderThread:26388 [retry.py:__call__():172] Retry attempt failed:
Traceback (most recent call last):
  File "E:\anaconda\lib\site-packages\urllib3\connection.py", line 174, in _new_conn
    conn = connection.create_connection(
  File "E:\anaconda\lib\site-packages\urllib3\util\connection.py", line 95, in create_connection
    raise err
  File "E:\anaconda\lib\site-packages\urllib3\util\connection.py", line 85, in create_connection
    sock.connect(sa)
TimeoutError: timed out

During handling of the above exception, another exception occurred:

Traceback (most recent call last):
  File "E:\anaconda\lib\site-packages\urllib3\connectionpool.py", line 714, in urlopen
    httplib_response = self._make_request(
  File "E:\anaconda\lib\site-packages\urllib3\connectionpool.py", line 403, in _make_request
    self._validate_conn(conn)
  File "E:\anaconda\lib\site-packages\urllib3\connectionpool.py", line 1053, in _validate_conn
    conn.connect()
  File "E:\anaconda\lib\site-packages\urllib3\connection.py", line 363, in connect
    self.sock = conn = self._new_conn()
  File "E:\anaconda\lib\site-packages\urllib3\connection.py", line 179, in _new_conn
    raise ConnectTimeoutError(
urllib3.exceptions.ConnectTimeoutError: (<urllib3.connection.HTTPSConnection object at 0x00000224178E5210>, 'Connection to api.wandb.ai timed out. (connect timeout=20)')

During handling of the above exception, another exception occurred:

Traceback (most recent call last):
  File "E:\anaconda\lib\site-packages\requests\adapters.py", line 487, in send
    resp = conn.urlopen(
  File "E:\anaconda\lib\site-packages\urllib3\connectionpool.py", line 798, in urlopen
    retries = retries.increment(
  File "E:\anaconda\lib\site-packages\urllib3\util\retry.py", line 592, in increment
    raise MaxRetryError(_pool, url, error or ResponseError(cause))
urllib3.exceptions.MaxRetryError: HTTPSConnectionPool(host='api.wandb.ai', port=443): Max retries exceeded with url: /graphql (Caused by ConnectTimeoutError(<urllib3.connection.HTTPSConnection object at 0x00000224178E5210>, 'Connection to api.wandb.ai timed out. (connect timeout=20)'))

During handling of the above exception, another exception occurred:

Traceback (most recent call last):
  File "E:\anaconda\lib\site-packages\wandb\sdk\lib\retry.py", line 131, in __call__
    result = self._call_fn(*args, **kwargs)
  File "E:\anaconda\lib\site-packages\wandb\sdk\internal\internal_api.py", line 366, in execute
    return self.client.execute(*args, **kwargs)  # type: ignore
  File "E:\anaconda\lib\site-packages\wandb\vendor\gql-0.2.0\wandb_gql\client.py", line 52, in execute
    result = self._get_result(document, *args, **kwargs)
  File "E:\anaconda\lib\site-packages\wandb\vendor\gql-0.2.0\wandb_gql\client.py", line 60, in _get_result
    return self.transport.execute(document, *args, **kwargs)
  File "E:\anaconda\lib\site-packages\wandb\sdk\lib\gql_request.py", line 58, in execute
    request = self.session.post(self.url, **post_args)
  File "E:\anaconda\lib\site-packages\requests\sessions.py", line 635, in post
    return self.request("POST", url, data=data, json=json, **kwargs)
  File "E:\anaconda\lib\site-packages\requests\sessions.py", line 587, in request
    resp = self.send(prep, **send_kwargs)
  File "E:\anaconda\lib\site-packages\requests\sessions.py", line 701, in send
    r = adapter.send(request, **kwargs)
  File "E:\anaconda\lib\site-packages\requests\adapters.py", line 508, in send
    raise ConnectTimeout(e, request=request)
requests.exceptions.ConnectTimeout: HTTPSConnectionPool(host='api.wandb.ai', port=443): Max retries exceeded with url: /graphql (Caused by ConnectTimeoutError(<urllib3.connection.HTTPSConnection object at 0x00000224178E5210>, 'Connection to api.wandb.ai timed out. (connect timeout=20)'))
2024-03-13 20:10:15,717 DEBUG   HandlerThread:26388 [handler.py:handle_request():144] handle_request: keepalive
