2024-03-13 16:00:45,311 INFO    StreamThr :28704 [internal.py:wandb_internal():86] W&B internal server running at pid: 28704, started at: 2024-03-13 16:00:45.311103
2024-03-13 16:00:45,312 DEBUG   HandlerThread:28704 [handler.py:handle_request():144] handle_request: status
2024-03-13 16:00:45,317 INFO    WriterThread:28704 [datastore.py:open_for_write():85] open: E:\自动驾驶\车位检测\parking-space-Identification-in-different-weather-main\wandb\run-20240313_160045-nmntnj9e\run-nmntnj9e.wandb
2024-03-13 16:00:45,319 DEBUG   SenderThread:28704 [sender.py:send():380] send: header
2024-03-13 16:00:45,319 DEBUG   SenderThread:28704 [sender.py:send():380] send: run
2024-03-13 16:00:48,824 INFO    SenderThread:28704 [retry.py:__call__():172] Retry attempt failed:
Traceback (most recent call last):
  File "E:\anaconda\lib\site-packages\urllib3\connection.py", line 174, in _new_conn
    conn = connection.create_connection(
  File "E:\anaconda\lib\site-packages\urllib3\util\connection.py", line 72, in create_connection
    for res in socket.getaddrinfo(host, port, family, socket.SOCK_STREAM):
  File "E:\anaconda\lib\socket.py", line 955, in getaddrinfo
    for res in _socket.getaddrinfo(host, port, family, type, proto, flags):
socket.gaierror: [Errno 11001] getaddrinfo failed

During handling of the above exception, another exception occurred:

Traceback (most recent call last):
  File "E:\anaconda\lib\site-packages\urllib3\connectionpool.py", line 714, in urlopen
    httplib_response = self._make_request(
  File "E:\anaconda\lib\site-packages\urllib3\connectionpool.py", line 403, in _make_request
    self._validate_conn(conn)
  File "E:\anaconda\lib\site-packages\urllib3\connectionpool.py", line 1053, in _validate_conn
    conn.connect()
  File "E:\anaconda\lib\site-packages\urllib3\connection.py", line 363, in connect
    self.sock = conn = self._new_conn()
  File "E:\anaconda\lib\site-packages\urllib3\connection.py", line 186, in _new_conn
    raise NewConnectionError(
urllib3.exceptions.NewConnectionError: <urllib3.connection.HTTPSConnection object at 0x000001DBC1FAC3A0>: Failed to establish a new connection: [Errno 11001] getaddrinfo failed

During handling of the above exception, another exception occurred:

Traceback (most recent call last):
  File "E:\anaconda\lib\site-packages\requests\adapters.py", line 487, in send
    resp = conn.urlopen(
  File "E:\anaconda\lib\site-packages\urllib3\connectionpool.py", line 798, in urlopen
    retries = retries.increment(
  File "E:\anaconda\lib\site-packages\urllib3\util\retry.py", line 592, in increment
    raise MaxRetryError(_pool, url, error or ResponseError(cause))
urllib3.exceptions.MaxRetryError: HTTPSConnectionPool(host='api.wandb.ai', port=443): Max retries exceeded with url: /graphql (Caused by NewConnectionError('<urllib3.connection.HTTPSConnection object at 0x000001DBC1FAC3A0>: Failed to establish a new connection: [Errno 11001] getaddrinfo failed'))

During handling of the above exception, another exception occurred:

Traceback (most recent call last):
  File "E:\anaconda\lib\site-packages\wandb\sdk\lib\retry.py", line 131, in __call__
    result = self._call_fn(*args, **kwargs)
  File "E:\anaconda\lib\site-packages\wandb\sdk\internal\internal_api.py", line 366, in execute
    return self.client.execute(*args, **kwargs)  # type: ignore
  File "E:\anaconda\lib\site-packages\wandb\vendor\gql-0.2.0\wandb_gql\client.py", line 52, in execute
    result = self._get_result(document, *args, **kwargs)
  File "E:\anaconda\lib\site-packages\wandb\vendor\gql-0.2.0\wandb_gql\client.py", line 60, in _get_result
    return self.transport.execute(document, *args, **kwargs)
  File "E:\anaconda\lib\site-packages\wandb\sdk\lib\gql_request.py", line 58, in execute
    request = self.session.post(self.url, **post_args)
  File "E:\anaconda\lib\site-packages\requests\sessions.py", line 635, in post
    return self.request("POST", url, data=data, json=json, **kwargs)
  File "E:\anaconda\lib\site-packages\requests\sessions.py", line 587, in request
    resp = self.send(prep, **send_kwargs)
  File "E:\anaconda\lib\site-packages\requests\sessions.py", line 701, in send
    r = adapter.send(request, **kwargs)
  File "E:\anaconda\lib\site-packages\requests\adapters.py", line 520, in send
    raise ConnectionError(e, request=request)
requests.exceptions.ConnectionError: HTTPSConnectionPool(host='api.wandb.ai', port=443): Max retries exceeded with url: /graphql (Caused by NewConnectionError('<urllib3.connection.HTTPSConnection object at 0x000001DBC1FAC3A0>: Failed to establish a new connection: [Errno 11001] getaddrinfo failed'))
2024-03-13 16:00:50,343 DEBUG   HandlerThread:28704 [handler.py:handle_request():144] handle_request: keepalive
2024-03-13 16:00:55,372 DEBUG   HandlerThread:28704 [handler.py:handle_request():144] handle_request: keepalive
2024-03-13 16:01:00,404 DEBUG   HandlerThread:28704 [handler.py:handle_request():144] handle_request: keepalive
2024-03-13 16:01:05,429 DEBUG   HandlerThread:28704 [handler.py:handle_request():144] handle_request: keepalive
2024-03-13 16:01:09,461 DEBUG   HandlerThread:28704 [handler.py:handle_request():144] handle_request: shutdown
2024-03-13 16:01:09,461 INFO    HandlerThread:28704 [handler.py:finish():844] shutting down handler
