2024-03-04 10:16:41,117 INFO    StreamThr :14388 [internal.py:wandb_internal():86] W&B internal server running at pid: 14388, started at: 2024-03-04 10:16:41.116080
2024-03-04 10:16:41,118 DEBUG   HandlerThread:14388 [handler.py:handle_request():144] handle_request: status
2024-03-04 10:16:41,123 INFO    WriterThread:14388 [datastore.py:open_for_write():85] open: E:\自动驾驶\车位检测\parking-space-Identification-in-different-weather-main\wandb\run-20240304_101641-xshwy3sa\run-xshwy3sa.wandb
2024-03-04 10:16:41,125 DEBUG   SenderThread:14388 [sender.py:send():380] send: header
2024-03-04 10:16:41,125 DEBUG   SenderThread:14388 [sender.py:send():380] send: run
2024-03-04 10:16:46,150 DEBUG   HandlerThread:14388 [handler.py:handle_request():144] handle_request: keepalive
2024-03-04 10:16:51,198 DEBUG   HandlerThread:14388 [handler.py:handle_request():144] handle_request: keepalive
2024-03-04 10:16:56,235 DEBUG   HandlerThread:14388 [handler.py:handle_request():144] handle_request: keepalive
2024-03-04 10:17:01,261 DEBUG   HandlerThread:14388 [handler.py:handle_request():144] handle_request: keepalive
2024-03-04 10:17:06,281 DEBUG   HandlerThread:14388 [handler.py:handle_request():144] handle_request: keepalive
2024-03-04 10:17:11,338 DEBUG   HandlerThread:14388 [handler.py:handle_request():144] handle_request: keepalive
2024-03-04 10:17:16,382 DEBUG   HandlerThread:14388 [handler.py:handle_request():144] handle_request: keepalive
2024-03-04 10:17:21,430 DEBUG   HandlerThread:14388 [handler.py:handle_request():144] handle_request: keepalive
2024-03-04 10:17:26,478 DEBUG   HandlerThread:14388 [handler.py:handle_request():144] handle_request: keepalive
2024-03-04 10:17:31,524 DEBUG   HandlerThread:14388 [handler.py:handle_request():144] handle_request: keepalive
2024-03-04 10:17:36,551 DEBUG   HandlerThread:14388 [handler.py:handle_request():144] handle_request: keepalive
2024-03-04 10:17:41,574 DEBUG   HandlerThread:14388 [handler.py:handle_request():144] handle_request: keepalive
2024-03-04 10:17:46,623 DEBUG   HandlerThread:14388 [handler.py:handle_request():144] handle_request: keepalive
2024-03-04 10:17:51,683 DEBUG   HandlerThread:14388 [handler.py:handle_request():144] handle_request: keepalive
2024-03-04 10:17:56,725 DEBUG   HandlerThread:14388 [handler.py:handle_request():144] handle_request: keepalive
2024-03-04 10:18:01,765 DEBUG   HandlerThread:14388 [handler.py:handle_request():144] handle_request: keepalive
2024-03-04 10:18:03,544 INFO    SenderThread:14388 [retry.py:__call__():172] Retry attempt failed:
Traceback (most recent call last):
  File "E:\anaconda\lib\site-packages\urllib3\connectionpool.py", line 714, in urlopen
    httplib_response = self._make_request(
  File "E:\anaconda\lib\site-packages\urllib3\connectionpool.py", line 466, in _make_request
    six.raise_from(e, None)
  File "<string>", line 3, in raise_from
  File "E:\anaconda\lib\site-packages\urllib3\connectionpool.py", line 461, in _make_request
    httplib_response = conn.getresponse()
  File "E:\anaconda\lib\http\client.py", line 1374, in getresponse
    response.begin()
  File "E:\anaconda\lib\http\client.py", line 318, in begin
    version, status, reason = self._read_status()
  File "E:\anaconda\lib\http\client.py", line 287, in _read_status
    raise RemoteDisconnected("Remote end closed connection without"
http.client.RemoteDisconnected: Remote end closed connection without response

During handling of the above exception, another exception occurred:

Traceback (most recent call last):
  File "E:\anaconda\lib\site-packages\requests\adapters.py", line 487, in send
    resp = conn.urlopen(
  File "E:\anaconda\lib\site-packages\urllib3\connectionpool.py", line 798, in urlopen
    retries = retries.increment(
  File "E:\anaconda\lib\site-packages\urllib3\util\retry.py", line 550, in increment
    raise six.reraise(type(error), error, _stacktrace)
  File "E:\anaconda\lib\site-packages\urllib3\packages\six.py", line 769, in reraise
    raise value.with_traceback(tb)
  File "E:\anaconda\lib\site-packages\urllib3\connectionpool.py", line 714, in urlopen
    httplib_response = self._make_request(
  File "E:\anaconda\lib\site-packages\urllib3\connectionpool.py", line 466, in _make_request
    six.raise_from(e, None)
  File "<string>", line 3, in raise_from
  File "E:\anaconda\lib\site-packages\urllib3\connectionpool.py", line 461, in _make_request
    httplib_response = conn.getresponse()
  File "E:\anaconda\lib\http\client.py", line 1374, in getresponse
    response.begin()
  File "E:\anaconda\lib\http\client.py", line 318, in begin
    version, status, reason = self._read_status()
  File "E:\anaconda\lib\http\client.py", line 287, in _read_status
    raise RemoteDisconnected("Remote end closed connection without"
urllib3.exceptions.ProtocolError: ('Connection aborted.', RemoteDisconnected('Remote end closed connection without response'))

During handling of the above exception, another exception occurred:

Traceback (most recent call last):
  File "E:\anaconda\lib\site-packages\wandb\sdk\lib\retry.py", line 131, in __call__
    result = self._call_fn(*args, **kwargs)
  File "E:\anaconda\lib\site-packages\wandb\sdk\internal\internal_api.py", line 366, in execute
    return self.client.execute(*args, **kwargs)  # type: ignore
  File "E:\anaconda\lib\site-packages\wandb\vendor\gql-0.2.0\wandb_gql\client.py", line 52, in execute
    result = self._get_result(document, *args, **kwargs)
  File "E:\anaconda\lib\site-packages\wandb\vendor\gql-0.2.0\wandb_gql\client.py", line 60, in _get_result
    return self.transport.execute(document, *args, **kwargs)
  File "E:\anaconda\lib\site-packages\wandb\sdk\lib\gql_request.py", line 58, in execute
    request = self.session.post(self.url, **post_args)
  File "E:\anaconda\lib\site-packages\requests\sessions.py", line 635, in post
    return self.request("POST", url, data=data, json=json, **kwargs)
  File "E:\anaconda\lib\site-packages\requests\sessions.py", line 587, in request
    resp = self.send(prep, **send_kwargs)
  File "E:\anaconda\lib\site-packages\requests\sessions.py", line 701, in send
    r = adapter.send(request, **kwargs)
  File "E:\anaconda\lib\site-packages\requests\adapters.py", line 502, in send
    raise ConnectionError(err, request=request)
requests.exceptions.ConnectionError: ('Connection aborted.', RemoteDisconnected('Remote end closed connection without response'))
2024-03-04 10:18:06,820 DEBUG   HandlerThread:14388 [handler.py:handle_request():144] handle_request: keepalive
2024-03-04 10:18:11,847 DEBUG   HandlerThread:14388 [handler.py:handle_request():144] handle_request: cancel
2024-03-04 10:18:11,848 DEBUG   HandlerThread:14388 [handler.py:handle_request():144] handle_request: cancel
2024-03-04 10:18:13,877 DEBUG   HandlerThread:14388 [handler.py:handle_request():144] handle_request: shutdown
2024-03-04 10:18:13,877 INFO    HandlerThread:14388 [handler.py:finish():844] shutting down handler
2024-03-04 10:18:14,872 INFO    WriterThread:14388 [datastore.py:close():294] close: E:\自动驾驶\车位检测\parking-space-Identification-in-different-weather-main\wandb\run-20240304_101641-xshwy3sa\run-xshwy3sa.wandb
2024-03-04 10:18:27,435 DEBUG   SenderThread:14388 [sender.py:send():389] Record cancelled: run
2024-03-04 10:18:27,436 INFO    SenderThread:14388 [sender.py:finish():1534] shutting down sender
